ERROR:root:
INFO:root:You are logged in!
WARNING:googleapiclient.discovery_cache:file_cache is unavailable when using oauth2client >= 4.0.0 or google-auth
Traceback (most recent call last):
  File "C:\Users\79069\AppData\Local\Programs\Python\Python39\lib\site-packages\googleapiclient\discovery_cache\file_cache.py", line 33, in <module>
    from oauth2client.contrib.locked_file import LockedFile
ModuleNotFoundError: No module named 'oauth2client.contrib.locked_file'

During handling of the above exception, another exception occurred:

Traceback (most recent call last):
  File "C:\Users\79069\AppData\Local\Programs\Python\Python39\lib\site-packages\googleapiclient\discovery_cache\file_cache.py", line 37, in <module>
    from oauth2client.locked_file import LockedFile
ModuleNotFoundError: No module named 'oauth2client.locked_file'

During handling of the above exception, another exception occurred:

Traceback (most recent call last):
  File "C:\Users\79069\AppData\Local\Programs\Python\Python39\lib\site-packages\googleapiclient\discovery_cache\__init__.py", line 44, in autodetect
    from . import file_cache
  File "C:\Users\79069\AppData\Local\Programs\Python\Python39\lib\site-packages\googleapiclient\discovery_cache\file_cache.py", line 40, in <module>
    raise ImportError(
ImportError: file_cache is unavailable when using oauth2client >= 4.0.0 or google-auth
DEBUG:googleapiclient.discovery:URL being requested: GET https://www.googleapis.com/discovery/v1/apis/drive/v3/rest
INFO:oauth2client.transport:Attempting refresh to obtain initial access_token
DEBUG:oauth2client.crypt:[b'eyJ0eXAiOiJKV1QiLCJhbGciOiJSUzI1NiIsImtpZCI6IjZiYzEzYmFjOTE0ZGZkNzliN2ZhOWQyODYxMzk5YzljZmY4OWFjNjcifQ', b'eyJhdWQiOiJodHRwczovL29hdXRoMi5nb29nbGVhcGlzLmNvbS90b2tlbiIsInNjb3BlIjoiaHR0cHM6Ly93d3cuZ29vZ2xlYXBpcy5jb20vYXV0aC9kcml2ZSIsImlhdCI6MTYxMzY0NTYxOCwiZXhwIjoxNjEzNjQ5MjE4LCJpc3MiOiJqdXN0LWFjY291bnRAdGVzdGFwaWFuZHNoZWV0cy5pYW0uZ3NlcnZpY2VhY2NvdW50LmNvbSJ9', b'oyd_GwaLs7VIueVWiSaW-ExABBf3Nd66NmWg9F3ON0SrQ2c5DWWLwRqcJfeppEL8pFr4VmiVQVihoXCIjMsoKPVhTH0UeUKLXlEfxBPAOY29dXaEB-NQ7gcOPrzvrEJVwblMmllEgmxyW2uAD4fmkIZNP3VgLA2HVLEnRbVS5bLXx706oCp5980Mm10bYd8C75mVU5y-akBHGF2g_ZG38l34rS0wfsETn9K7ibfrprF9LmN6IywskLsAdIg5AsY2r_-rWQo1Z0n-2tm7Ly-d7nkblxDtXl7iSsasHetG5kj-aVnliIt7DJiJuWxrvd5Qci3CJpxDN2Cwl8A_3pqFNg']
INFO:oauth2client.client:Refreshing access_token
DEBUG:googleapiclient.discovery:URL being requested: GET https://www.googleapis.com/drive/v3/files/12xpxsV0IhJT0mPqxdO9dzsMjONwI7EcW?alt=media
WARNING:googleapiclient.discovery_cache:file_cache is unavailable when using oauth2client >= 4.0.0 or google-auth
Traceback (most recent call last):
  File "C:\Users\79069\AppData\Local\Programs\Python\Python39\lib\site-packages\googleapiclient\discovery_cache\file_cache.py", line 33, in <module>
    from oauth2client.contrib.locked_file import LockedFile
ModuleNotFoundError: No module named 'oauth2client.contrib.locked_file'

During handling of the above exception, another exception occurred:

Traceback (most recent call last):
  File "C:\Users\79069\AppData\Local\Programs\Python\Python39\lib\site-packages\googleapiclient\discovery_cache\file_cache.py", line 37, in <module>
    from oauth2client.locked_file import LockedFile
ModuleNotFoundError: No module named 'oauth2client.locked_file'

During handling of the above exception, another exception occurred:

Traceback (most recent call last):
  File "C:\Users\79069\AppData\Local\Programs\Python\Python39\lib\site-packages\googleapiclient\discovery_cache\__init__.py", line 44, in autodetect
    from . import file_cache
  File "C:\Users\79069\AppData\Local\Programs\Python\Python39\lib\site-packages\googleapiclient\discovery_cache\file_cache.py", line 40, in <module>
    raise ImportError(
ImportError: file_cache is unavailable when using oauth2client >= 4.0.0 or google-auth
DEBUG:googleapiclient.discovery:URL being requested: GET https://www.googleapis.com/discovery/v1/apis/drive/v3/rest
INFO:oauth2client.transport:Attempting refresh to obtain initial access_token
DEBUG:oauth2client.crypt:[b'eyJ0eXAiOiJKV1QiLCJhbGciOiJSUzI1NiIsImtpZCI6IjZiYzEzYmFjOTE0ZGZkNzliN2ZhOWQyODYxMzk5YzljZmY4OWFjNjcifQ', b'eyJhdWQiOiJodHRwczovL29hdXRoMi5nb29nbGVhcGlzLmNvbS90b2tlbiIsInNjb3BlIjoiaHR0cHM6Ly93d3cuZ29vZ2xlYXBpcy5jb20vYXV0aC9kcml2ZSIsImlhdCI6MTYxMzY0NTYyNywiZXhwIjoxNjEzNjQ5MjI3LCJpc3MiOiJqdXN0LWFjY291bnRAdGVzdGFwaWFuZHNoZWV0cy5pYW0uZ3NlcnZpY2VhY2NvdW50LmNvbSJ9', b'h1G90ZqO1CVqyj79Vi4wABsopFNSjzFndxq_O_UYgJmRECrfat4wbv7gGREkllJtWVPvUD-3tHCwx2r6QafepGfi2JmIiBkYdve4mfXUZc8uBMYtOn1H-ZSnZDTskX-oCG53a30ftOKmZKu1xZaDmv7GhJP_7H4K12itBZX2AN2PGrEhl1oYUvdr6pn-uso15sSbi1mA0frWSbi49usMCS8uCO5-7oQXdXLLt0OmSRLmbE1sk9bhtyq97I1X4bmRr22Eot9Js8SPl6ISFiHOuySXwZLf-Bi5_0mNx0j1LIGjXnGE73twDKircJkpdteq6AMVFwzet7ERtl0nRozgAw']
INFO:oauth2client.client:Refreshing access_token
DEBUG:googleapiclient.discovery:URL being requested: POST https://www.googleapis.com/upload/drive/v3/files?fields=id&alt=json&uploadType=multipart
INFO:root:You are logged in!
WARNING:googleapiclient.discovery_cache:file_cache is unavailable when using oauth2client >= 4.0.0 or google-auth
Traceback (most recent call last):
  File "C:\Users\79069\AppData\Local\Programs\Python\Python39\lib\site-packages\googleapiclient\discovery_cache\file_cache.py", line 33, in <module>
    from oauth2client.contrib.locked_file import LockedFile
ModuleNotFoundError: No module named 'oauth2client.contrib.locked_file'

During handling of the above exception, another exception occurred:

Traceback (most recent call last):
  File "C:\Users\79069\AppData\Local\Programs\Python\Python39\lib\site-packages\googleapiclient\discovery_cache\file_cache.py", line 37, in <module>
    from oauth2client.locked_file import LockedFile
ModuleNotFoundError: No module named 'oauth2client.locked_file'

During handling of the above exception, another exception occurred:

Traceback (most recent call last):
  File "C:\Users\79069\AppData\Local\Programs\Python\Python39\lib\site-packages\googleapiclient\discovery_cache\__init__.py", line 44, in autodetect
    from . import file_cache
  File "C:\Users\79069\AppData\Local\Programs\Python\Python39\lib\site-packages\googleapiclient\discovery_cache\file_cache.py", line 40, in <module>
    raise ImportError(
ImportError: file_cache is unavailable when using oauth2client >= 4.0.0 or google-auth
DEBUG:googleapiclient.discovery:URL being requested: GET https://www.googleapis.com/discovery/v1/apis/drive/v3/rest
INFO:oauth2client.transport:Attempting refresh to obtain initial access_token
DEBUG:oauth2client.crypt:[b'eyJ0eXAiOiJKV1QiLCJhbGciOiJSUzI1NiIsImtpZCI6IjZiYzEzYmFjOTE0ZGZkNzliN2ZhOWQyODYxMzk5YzljZmY4OWFjNjcifQ', b'eyJhdWQiOiJodHRwczovL29hdXRoMi5nb29nbGVhcGlzLmNvbS90b2tlbiIsInNjb3BlIjoiaHR0cHM6Ly93d3cuZ29vZ2xlYXBpcy5jb20vYXV0aC9kcml2ZSIsImlhdCI6MTYxMzY0NTc2MywiZXhwIjoxNjEzNjQ5MzYzLCJpc3MiOiJqdXN0LWFjY291bnRAdGVzdGFwaWFuZHNoZWV0cy5pYW0uZ3NlcnZpY2VhY2NvdW50LmNvbSJ9', b'CAMhvXD-Vk_YK0SE4F-z5Rg7xUjXPtjTnZlO6uEH6LrczezanfB0fJnxstSASv-6S_2ccfeX7Dd_liNRR7-DCZLP1sGmoDcylvv8ObpY51FJzF3zb-zYbA82UAfUYmrkHv9hptkPKmjkFY61_OWI8AeJJVg1MIKekI26PcBufQIQuB7Tp742BofdOOSfKU7pNfMu-CudW8jB1_bGLfvzAy6JhejLZC3UNEKde8Lg8YqNUq1vF-6CKfPFw1Rv5NTqMwc9b2YNPb5PmwFjY-sC5ENhh-HspRWbpzVagkxkkgsM-Bo-C1x0H0URm5P-hQMRewrOCxNdWrw7QaYiFeO_uw']
INFO:oauth2client.client:Refreshing access_token
DEBUG:googleapiclient.discovery:URL being requested: GET https://www.googleapis.com/drive/v3/files/12xpxsV0IhJT0mPqxdO9dzsMjONwI7EcW?alt=media
WARNING:googleapiclient.discovery_cache:file_cache is unavailable when using oauth2client >= 4.0.0 or google-auth
Traceback (most recent call last):
  File "C:\Users\79069\AppData\Local\Programs\Python\Python39\lib\site-packages\googleapiclient\discovery_cache\file_cache.py", line 33, in <module>
    from oauth2client.contrib.locked_file import LockedFile
ModuleNotFoundError: No module named 'oauth2client.contrib.locked_file'

During handling of the above exception, another exception occurred:

Traceback (most recent call last):
  File "C:\Users\79069\AppData\Local\Programs\Python\Python39\lib\site-packages\googleapiclient\discovery_cache\file_cache.py", line 37, in <module>
    from oauth2client.locked_file import LockedFile
ModuleNotFoundError: No module named 'oauth2client.locked_file'

During handling of the above exception, another exception occurred:

Traceback (most recent call last):
  File "C:\Users\79069\AppData\Local\Programs\Python\Python39\lib\site-packages\googleapiclient\discovery_cache\__init__.py", line 44, in autodetect
    from . import file_cache
  File "C:\Users\79069\AppData\Local\Programs\Python\Python39\lib\site-packages\googleapiclient\discovery_cache\file_cache.py", line 40, in <module>
    raise ImportError(
ImportError: file_cache is unavailable when using oauth2client >= 4.0.0 or google-auth
DEBUG:googleapiclient.discovery:URL being requested: GET https://www.googleapis.com/discovery/v1/apis/drive/v3/rest
INFO:oauth2client.transport:Attempting refresh to obtain initial access_token
DEBUG:oauth2client.crypt:[b'eyJ0eXAiOiJKV1QiLCJhbGciOiJSUzI1NiIsImtpZCI6IjZiYzEzYmFjOTE0ZGZkNzliN2ZhOWQyODYxMzk5YzljZmY4OWFjNjcifQ', b'eyJhdWQiOiJodHRwczovL29hdXRoMi5nb29nbGVhcGlzLmNvbS90b2tlbiIsInNjb3BlIjoiaHR0cHM6Ly93d3cuZ29vZ2xlYXBpcy5jb20vYXV0aC9kcml2ZSIsImlhdCI6MTYxMzY0NTc3MywiZXhwIjoxNjEzNjQ5MzczLCJpc3MiOiJqdXN0LWFjY291bnRAdGVzdGFwaWFuZHNoZWV0cy5pYW0uZ3NlcnZpY2VhY2NvdW50LmNvbSJ9', b'u5RdFA9ggTVJ-FqUp4JVs8SkBC9XW-5dD_hrfadAN1MYrAHKbJ_BZ79w5a3tkE9OYKAAbflGmTfCaC8WdLB0BNWK7J9ObxQke0lG1GD-JEEiIL5fa3LbD-kkD-iU8zk3Kmmv7lIfEJxlZthS2gBDL__9PV2gY89KzGh11LoNhTZhIIztGuI15984_GFM4dO7ZjrwAqtSOxBXY75rUwmcgRKOqLNLWgVZMMMxygejvYvgEWp9t5evjYN4MEfP3cPyLthRQZfH-ddxPI3K1GlNOaTXMWkhGjKIAY2a6HiZU21Y0prR3tAGWIYGdUorCKN48EeJ32aI5kga46HhGsNodg']
INFO:oauth2client.client:Refreshing access_token
DEBUG:googleapiclient.discovery:URL being requested: POST https://www.googleapis.com/upload/drive/v3/files?fields=id&alt=json&uploadType=multipart
INFO:root:You are logged in!
WARNING:googleapiclient.discovery_cache:file_cache is unavailable when using oauth2client >= 4.0.0 or google-auth
Traceback (most recent call last):
  File "C:\Users\79069\AppData\Local\Programs\Python\Python39\lib\site-packages\googleapiclient\discovery_cache\file_cache.py", line 33, in <module>
    from oauth2client.contrib.locked_file import LockedFile
ModuleNotFoundError: No module named 'oauth2client.contrib.locked_file'

During handling of the above exception, another exception occurred:

Traceback (most recent call last):
  File "C:\Users\79069\AppData\Local\Programs\Python\Python39\lib\site-packages\googleapiclient\discovery_cache\file_cache.py", line 37, in <module>
    from oauth2client.locked_file import LockedFile
ModuleNotFoundError: No module named 'oauth2client.locked_file'

During handling of the above exception, another exception occurred:

Traceback (most recent call last):
  File "C:\Users\79069\AppData\Local\Programs\Python\Python39\lib\site-packages\googleapiclient\discovery_cache\__init__.py", line 44, in autodetect
    from . import file_cache
  File "C:\Users\79069\AppData\Local\Programs\Python\Python39\lib\site-packages\googleapiclient\discovery_cache\file_cache.py", line 40, in <module>
    raise ImportError(
ImportError: file_cache is unavailable when using oauth2client >= 4.0.0 or google-auth
DEBUG:googleapiclient.discovery:URL being requested: GET https://www.googleapis.com/discovery/v1/apis/drive/v3/rest
INFO:oauth2client.transport:Attempting refresh to obtain initial access_token
DEBUG:oauth2client.crypt:[b'eyJ0eXAiOiJKV1QiLCJhbGciOiJSUzI1NiIsImtpZCI6IjZiYzEzYmFjOTE0ZGZkNzliN2ZhOWQyODYxMzk5YzljZmY4OWFjNjcifQ', b'eyJhdWQiOiJodHRwczovL29hdXRoMi5nb29nbGVhcGlzLmNvbS90b2tlbiIsInNjb3BlIjoiaHR0cHM6Ly93d3cuZ29vZ2xlYXBpcy5jb20vYXV0aC9kcml2ZSIsImlhdCI6MTYxMzY0NTgyNCwiZXhwIjoxNjEzNjQ5NDI0LCJpc3MiOiJqdXN0LWFjY291bnRAdGVzdGFwaWFuZHNoZWV0cy5pYW0uZ3NlcnZpY2VhY2NvdW50LmNvbSJ9', b'xZbYWCNIWEP86EmKN7ZD5lXeKUBJvIrcG8SzGaNgWqUdXIdoOy8VIL-1u-aw1c0BtbvEtq7MhsgoWdZ9KoJVyNtLKSPPb-xRVssUjSGHHSP8yqwHxGctB59hS4b3ZCtYMtaY_lPHl30GgPi5BWsdU4oid_ygqRKTOAsTsrxbKwY1wIDAPy3D2pjkkw7qpfV63rz4Qohm4Ie6OTEXumb_ZFT_kT9Nu-EmCD1cI-SSGdFTAS2FNKGEcqOh6XI79cpnqFOjaQQo330myVu7ZIRvJXVsS0TE6XQynmw0JdRkteV_sTUvHQqH3MxBhlLDLTFfVSWvj9Kb-EgP3LyxQPZR0w']
INFO:oauth2client.client:Refreshing access_token
DEBUG:googleapiclient.discovery:URL being requested: GET https://www.googleapis.com/drive/v3/files/12xpxsV0IhJT0mPqxdO9dzsMjONwI7EcW?alt=media
WARNING:googleapiclient.discovery_cache:file_cache is unavailable when using oauth2client >= 4.0.0 or google-auth
Traceback (most recent call last):
  File "C:\Users\79069\AppData\Local\Programs\Python\Python39\lib\site-packages\googleapiclient\discovery_cache\file_cache.py", line 33, in <module>
    from oauth2client.contrib.locked_file import LockedFile
ModuleNotFoundError: No module named 'oauth2client.contrib.locked_file'

During handling of the above exception, another exception occurred:

Traceback (most recent call last):
  File "C:\Users\79069\AppData\Local\Programs\Python\Python39\lib\site-packages\googleapiclient\discovery_cache\file_cache.py", line 37, in <module>
    from oauth2client.locked_file import LockedFile
ModuleNotFoundError: No module named 'oauth2client.locked_file'

During handling of the above exception, another exception occurred:

Traceback (most recent call last):
  File "C:\Users\79069\AppData\Local\Programs\Python\Python39\lib\site-packages\googleapiclient\discovery_cache\__init__.py", line 44, in autodetect
    from . import file_cache
  File "C:\Users\79069\AppData\Local\Programs\Python\Python39\lib\site-packages\googleapiclient\discovery_cache\file_cache.py", line 40, in <module>
    raise ImportError(
ImportError: file_cache is unavailable when using oauth2client >= 4.0.0 or google-auth
DEBUG:googleapiclient.discovery:URL being requested: GET https://www.googleapis.com/discovery/v1/apis/drive/v3/rest
INFO:oauth2client.transport:Attempting refresh to obtain initial access_token
DEBUG:oauth2client.crypt:[b'eyJ0eXAiOiJKV1QiLCJhbGciOiJSUzI1NiIsImtpZCI6IjZiYzEzYmFjOTE0ZGZkNzliN2ZhOWQyODYxMzk5YzljZmY4OWFjNjcifQ', b'eyJhdWQiOiJodHRwczovL29hdXRoMi5nb29nbGVhcGlzLmNvbS90b2tlbiIsInNjb3BlIjoiaHR0cHM6Ly93d3cuZ29vZ2xlYXBpcy5jb20vYXV0aC9kcml2ZSIsImlhdCI6MTYxMzY0NTgzMiwiZXhwIjoxNjEzNjQ5NDMyLCJpc3MiOiJqdXN0LWFjY291bnRAdGVzdGFwaWFuZHNoZWV0cy5pYW0uZ3NlcnZpY2VhY2NvdW50LmNvbSJ9', b'saJD2cY2WWFAZ-mL-7ghXyzw81LbSaTsnNEp334Cg0MNfLOmEaI5Fi8fHILOWD6WoK7kTbXcY6hCzdxq4-miI3UEURHZTE_ytXruEjBDjEr6RTNbT0nbnsrE2II-ApE8WJJ1Zw-iKv5nqnhZr3YiCHYzgl1F4ugYAmdFRuvE3CUk7zlxVO9qpCsidREbGKx8roMhjxvZXLUTMt2pc-X9sQPjx_6DJJvgKWEjiDd3WHzT8OXbUiA32qdjrcGpfWgxhR3udJ0SDdeMN0hwYPgFHLglH-MUu6Xp8gIP1Q-a7dAed0mCzZqoMaonOep2yzgrDKUPsUY7AZUkBaun2_tr0w']
INFO:oauth2client.client:Refreshing access_token
DEBUG:googleapiclient.discovery:URL being requested: POST https://www.googleapis.com/upload/drive/v3/files?fields=id&alt=json&uploadType=multipart
INFO:root:You are logged in!
WARNING:googleapiclient.discovery_cache:file_cache is unavailable when using oauth2client >= 4.0.0 or google-auth
Traceback (most recent call last):
  File "C:\Users\79069\AppData\Local\Programs\Python\Python39\lib\site-packages\googleapiclient\discovery_cache\file_cache.py", line 33, in <module>
    from oauth2client.contrib.locked_file import LockedFile
ModuleNotFoundError: No module named 'oauth2client.contrib.locked_file'

During handling of the above exception, another exception occurred:

Traceback (most recent call last):
  File "C:\Users\79069\AppData\Local\Programs\Python\Python39\lib\site-packages\googleapiclient\discovery_cache\file_cache.py", line 37, in <module>
    from oauth2client.locked_file import LockedFile
ModuleNotFoundError: No module named 'oauth2client.locked_file'

During handling of the above exception, another exception occurred:

Traceback (most recent call last):
  File "C:\Users\79069\AppData\Local\Programs\Python\Python39\lib\site-packages\googleapiclient\discovery_cache\__init__.py", line 44, in autodetect
    from . import file_cache
  File "C:\Users\79069\AppData\Local\Programs\Python\Python39\lib\site-packages\googleapiclient\discovery_cache\file_cache.py", line 40, in <module>
    raise ImportError(
ImportError: file_cache is unavailable when using oauth2client >= 4.0.0 or google-auth
DEBUG:googleapiclient.discovery:URL being requested: GET https://www.googleapis.com/discovery/v1/apis/drive/v3/rest
INFO:oauth2client.transport:Attempting refresh to obtain initial access_token
DEBUG:oauth2client.crypt:[b'eyJ0eXAiOiJKV1QiLCJhbGciOiJSUzI1NiIsImtpZCI6IjZiYzEzYmFjOTE0ZGZkNzliN2ZhOWQyODYxMzk5YzljZmY4OWFjNjcifQ', b'eyJhdWQiOiJodHRwczovL29hdXRoMi5nb29nbGVhcGlzLmNvbS90b2tlbiIsInNjb3BlIjoiaHR0cHM6Ly93d3cuZ29vZ2xlYXBpcy5jb20vYXV0aC9kcml2ZSIsImlhdCI6MTYxMzY0NTkwMCwiZXhwIjoxNjEzNjQ5NTAwLCJpc3MiOiJqdXN0LWFjY291bnRAdGVzdGFwaWFuZHNoZWV0cy5pYW0uZ3NlcnZpY2VhY2NvdW50LmNvbSJ9', b'YEG2cl6dj2nV_rpkHk5Fcm027TVmTZytlDUshoCiOseK2_gNteqY_4WPiwMTbJ8pGAfpa-Gkd9LcLtDexuxg5X0ZMZYURSHFEZb8vqci3mb-A9oWzX7wvwgWCRc4D141QKmjiaHnrg8iRuUcRhhRQxGy-XYngEgNN_bKXn1NvYY_vllTGxFAkTUE3a6a7iCApIRX7ef8FFssiAtccwUH7AxCDsI-KobclBsYozU9mw5_xbbtD8oDOM8WOJkNkgZr8eRE9xyNm_9_HenIBgCm7Wiy2S4nz3MXELofhJyxAy6eV9lx7brO690pYsoY8yCeDUtqd6yfwtP8Yw4LCYfHLg']
INFO:oauth2client.client:Refreshing access_token
DEBUG:googleapiclient.discovery:URL being requested: GET https://www.googleapis.com/drive/v3/files/12xpxsV0IhJT0mPqxdO9dzsMjONwI7EcW?alt=media
WARNING:googleapiclient.discovery_cache:file_cache is unavailable when using oauth2client >= 4.0.0 or google-auth
Traceback (most recent call last):
  File "C:\Users\79069\AppData\Local\Programs\Python\Python39\lib\site-packages\googleapiclient\discovery_cache\file_cache.py", line 33, in <module>
    from oauth2client.contrib.locked_file import LockedFile
ModuleNotFoundError: No module named 'oauth2client.contrib.locked_file'

During handling of the above exception, another exception occurred:

Traceback (most recent call last):
  File "C:\Users\79069\AppData\Local\Programs\Python\Python39\lib\site-packages\googleapiclient\discovery_cache\file_cache.py", line 37, in <module>
    from oauth2client.locked_file import LockedFile
ModuleNotFoundError: No module named 'oauth2client.locked_file'

During handling of the above exception, another exception occurred:

Traceback (most recent call last):
  File "C:\Users\79069\AppData\Local\Programs\Python\Python39\lib\site-packages\googleapiclient\discovery_cache\__init__.py", line 44, in autodetect
    from . import file_cache
  File "C:\Users\79069\AppData\Local\Programs\Python\Python39\lib\site-packages\googleapiclient\discovery_cache\file_cache.py", line 40, in <module>
    raise ImportError(
ImportError: file_cache is unavailable when using oauth2client >= 4.0.0 or google-auth
DEBUG:googleapiclient.discovery:URL being requested: GET https://www.googleapis.com/discovery/v1/apis/drive/v3/rest
INFO:oauth2client.transport:Attempting refresh to obtain initial access_token
DEBUG:oauth2client.crypt:[b'eyJ0eXAiOiJKV1QiLCJhbGciOiJSUzI1NiIsImtpZCI6IjZiYzEzYmFjOTE0ZGZkNzliN2ZhOWQyODYxMzk5YzljZmY4OWFjNjcifQ', b'eyJhdWQiOiJodHRwczovL29hdXRoMi5nb29nbGVhcGlzLmNvbS90b2tlbiIsInNjb3BlIjoiaHR0cHM6Ly93d3cuZ29vZ2xlYXBpcy5jb20vYXV0aC9kcml2ZSIsImlhdCI6MTYxMzY0NTkwNiwiZXhwIjoxNjEzNjQ5NTA2LCJpc3MiOiJqdXN0LWFjY291bnRAdGVzdGFwaWFuZHNoZWV0cy5pYW0uZ3NlcnZpY2VhY2NvdW50LmNvbSJ9', b'c6cAywrSy4WJV5aF7msInEouEexjDnVIJ5jb2vlvZFLfd1UycVKigZJYc_zb1-4FE0E9Poqi8YCui0bRm7dsqd4WCijpwREuKGzlZvl9XKNxflcM88R_KYq4vqWkL7UwZFSJfdFoRakYFPe8vQNxudWD8nlkqiC0ckVOxrruGYoS_2zplW57XW_PzJda1g1ZIXOlZusCXotIxYKOZowsav4M8cWqr8Zr4-90jmYsgWyErapKbEkAB726qNVS64VVL_VbaG8geoefDlaQwqT3HztKimD9B4Zt5LsJP8OBPX0J028UKrspet9UE2mYvwe7dUAxLpXff6QAK2HwsIuBUw']
INFO:oauth2client.client:Refreshing access_token
DEBUG:googleapiclient.discovery:URL being requested: POST https://www.googleapis.com/upload/drive/v3/files?fields=id&alt=json&uploadType=multipart
INFO:root:You are logged in!
WARNING:googleapiclient.discovery_cache:file_cache is unavailable when using oauth2client >= 4.0.0 or google-auth
Traceback (most recent call last):
  File "C:\Users\79069\AppData\Local\Programs\Python\Python39\lib\site-packages\googleapiclient\discovery_cache\file_cache.py", line 33, in <module>
    from oauth2client.contrib.locked_file import LockedFile
ModuleNotFoundError: No module named 'oauth2client.contrib.locked_file'

During handling of the above exception, another exception occurred:

Traceback (most recent call last):
  File "C:\Users\79069\AppData\Local\Programs\Python\Python39\lib\site-packages\googleapiclient\discovery_cache\file_cache.py", line 37, in <module>
    from oauth2client.locked_file import LockedFile
ModuleNotFoundError: No module named 'oauth2client.locked_file'

During handling of the above exception, another exception occurred:

Traceback (most recent call last):
  File "C:\Users\79069\AppData\Local\Programs\Python\Python39\lib\site-packages\googleapiclient\discovery_cache\__init__.py", line 44, in autodetect
    from . import file_cache
  File "C:\Users\79069\AppData\Local\Programs\Python\Python39\lib\site-packages\googleapiclient\discovery_cache\file_cache.py", line 40, in <module>
    raise ImportError(
ImportError: file_cache is unavailable when using oauth2client >= 4.0.0 or google-auth
DEBUG:googleapiclient.discovery:URL being requested: GET https://www.googleapis.com/discovery/v1/apis/drive/v3/rest
INFO:oauth2client.transport:Attempting refresh to obtain initial access_token
DEBUG:oauth2client.crypt:[b'eyJ0eXAiOiJKV1QiLCJhbGciOiJSUzI1NiIsImtpZCI6IjZiYzEzYmFjOTE0ZGZkNzliN2ZhOWQyODYxMzk5YzljZmY4OWFjNjcifQ', b'eyJhdWQiOiJodHRwczovL29hdXRoMi5nb29nbGVhcGlzLmNvbS90b2tlbiIsInNjb3BlIjoiaHR0cHM6Ly93d3cuZ29vZ2xlYXBpcy5jb20vYXV0aC9kcml2ZSIsImlhdCI6MTYxMzY0NjExNSwiZXhwIjoxNjEzNjQ5NzE1LCJpc3MiOiJqdXN0LWFjY291bnRAdGVzdGFwaWFuZHNoZWV0cy5pYW0uZ3NlcnZpY2VhY2NvdW50LmNvbSJ9', b'saNnfaMgA3ocJTs-mQny8N8qK_uO-CC5lmT1DfSHxD7OgCLEvjwjCmLWEbP3TSBDL7cCtD6pvAYb9TNe9zT7R2EASOIHRQYqocKbIGYtUyP-W50qZwAzE0g6RMcaQRIdNYFKjaiJR3fo6yUvVrgtix80g0hYYNc0COYiGtuPAoRP5dkjmacayTA42m4N8--g-qHwaSY2qIlaMdEqpLbSaxe_ZTihjIx2z8jALPAekrJrlbBR1QBxKrtvB_VoteV7Sq8AXOXYWrWBwJBK5_QT0ZPKOMFf0ybIPq6MVpjLdiJSPw6Ep9zuwDcaZqbf31C-H-uloYu2IpradaOA-kgIrQ']
INFO:oauth2client.client:Refreshing access_token
DEBUG:googleapiclient.discovery:URL being requested: GET https://www.googleapis.com/drive/v3/files/12xpxsV0IhJT0mPqxdO9dzsMjONwI7EcW?alt=media
WARNING:googleapiclient.discovery_cache:file_cache is unavailable when using oauth2client >= 4.0.0 or google-auth
Traceback (most recent call last):
  File "C:\Users\79069\AppData\Local\Programs\Python\Python39\lib\site-packages\googleapiclient\discovery_cache\file_cache.py", line 33, in <module>
    from oauth2client.contrib.locked_file import LockedFile
ModuleNotFoundError: No module named 'oauth2client.contrib.locked_file'

During handling of the above exception, another exception occurred:

Traceback (most recent call last):
  File "C:\Users\79069\AppData\Local\Programs\Python\Python39\lib\site-packages\googleapiclient\discovery_cache\file_cache.py", line 37, in <module>
    from oauth2client.locked_file import LockedFile
ModuleNotFoundError: No module named 'oauth2client.locked_file'

During handling of the above exception, another exception occurred:

Traceback (most recent call last):
  File "C:\Users\79069\AppData\Local\Programs\Python\Python39\lib\site-packages\googleapiclient\discovery_cache\__init__.py", line 44, in autodetect
    from . import file_cache
  File "C:\Users\79069\AppData\Local\Programs\Python\Python39\lib\site-packages\googleapiclient\discovery_cache\file_cache.py", line 40, in <module>
    raise ImportError(
ImportError: file_cache is unavailable when using oauth2client >= 4.0.0 or google-auth
DEBUG:googleapiclient.discovery:URL being requested: GET https://www.googleapis.com/discovery/v1/apis/drive/v3/rest
INFO:oauth2client.transport:Attempting refresh to obtain initial access_token
DEBUG:oauth2client.crypt:[b'eyJ0eXAiOiJKV1QiLCJhbGciOiJSUzI1NiIsImtpZCI6IjZiYzEzYmFjOTE0ZGZkNzliN2ZhOWQyODYxMzk5YzljZmY4OWFjNjcifQ', b'eyJhdWQiOiJodHRwczovL29hdXRoMi5nb29nbGVhcGlzLmNvbS90b2tlbiIsInNjb3BlIjoiaHR0cHM6Ly93d3cuZ29vZ2xlYXBpcy5jb20vYXV0aC9kcml2ZSIsImlhdCI6MTYxMzY0NjEyMiwiZXhwIjoxNjEzNjQ5NzIyLCJpc3MiOiJqdXN0LWFjY291bnRAdGVzdGFwaWFuZHNoZWV0cy5pYW0uZ3NlcnZpY2VhY2NvdW50LmNvbSJ9', b'jEmQqBOCCiFAouuv24VZyOLFsQZobnCry2I91moXVSCpt91XFj8YhgkOIddxnSkhL0pM7eulU4ED-QO7kjOpgdDWd3BL_UHetONuMAxcFwWhbHOfxdVXtQmMB-ws-eVtdXlZi9Lke31flIVbTtr4DHOvQyLUMQkTqEbvdOG87XW5iyVHxMwddNbXhRkCTbvrIooWjJRs33u1KPvs7mSiFcv2p_MZ0clLs44XAO7ZmMv-xKDEq6ctxDFCqfHa9TB0At4jJAFbLh786jNhWAV-IgUJFo97NK5ZB0B7C2FlhkPAhlsrWIetd4SVMogsHxta2AxYHshPSWNqrC_Q64l6CA']
INFO:oauth2client.client:Refreshing access_token
DEBUG:googleapiclient.discovery:URL being requested: POST https://www.googleapis.com/upload/drive/v3/files?fields=id&alt=json&uploadType=multipart
INFO:root:You are logged in!
WARNING:googleapiclient.discovery_cache:file_cache is unavailable when using oauth2client >= 4.0.0 or google-auth
Traceback (most recent call last):
  File "C:\Users\79069\AppData\Local\Programs\Python\Python39\lib\site-packages\googleapiclient\discovery_cache\file_cache.py", line 33, in <module>
    from oauth2client.contrib.locked_file import LockedFile
ModuleNotFoundError: No module named 'oauth2client.contrib.locked_file'

During handling of the above exception, another exception occurred:

Traceback (most recent call last):
  File "C:\Users\79069\AppData\Local\Programs\Python\Python39\lib\site-packages\googleapiclient\discovery_cache\file_cache.py", line 37, in <module>
    from oauth2client.locked_file import LockedFile
ModuleNotFoundError: No module named 'oauth2client.locked_file'

During handling of the above exception, another exception occurred:

Traceback (most recent call last):
  File "C:\Users\79069\AppData\Local\Programs\Python\Python39\lib\site-packages\googleapiclient\discovery_cache\__init__.py", line 44, in autodetect
    from . import file_cache
  File "C:\Users\79069\AppData\Local\Programs\Python\Python39\lib\site-packages\googleapiclient\discovery_cache\file_cache.py", line 40, in <module>
    raise ImportError(
ImportError: file_cache is unavailable when using oauth2client >= 4.0.0 or google-auth
DEBUG:googleapiclient.discovery:URL being requested: GET https://www.googleapis.com/discovery/v1/apis/drive/v3/rest
INFO:oauth2client.transport:Attempting refresh to obtain initial access_token
DEBUG:oauth2client.crypt:[b'eyJ0eXAiOiJKV1QiLCJhbGciOiJSUzI1NiIsImtpZCI6IjZiYzEzYmFjOTE0ZGZkNzliN2ZhOWQyODYxMzk5YzljZmY4OWFjNjcifQ', b'eyJhdWQiOiJodHRwczovL29hdXRoMi5nb29nbGVhcGlzLmNvbS90b2tlbiIsInNjb3BlIjoiaHR0cHM6Ly93d3cuZ29vZ2xlYXBpcy5jb20vYXV0aC9kcml2ZSIsImlhdCI6MTYxMzY0NjI2NSwiZXhwIjoxNjEzNjQ5ODY1LCJpc3MiOiJqdXN0LWFjY291bnRAdGVzdGFwaWFuZHNoZWV0cy5pYW0uZ3NlcnZpY2VhY2NvdW50LmNvbSJ9', b'QHfLQBtwoByNimWPj928s9NNd6m3SI7uW_F5qy9uxahzUKT-bUMFQVs5u3StyI_hHMfJ8QRyQL6PS3paB7fjmRDPcwmEZn_Mlktd2W7_9S7bHpZKlQOt9Z5pD5L0MLZch8iUGxhbWthKUguyzPTiRtYZdCsMPSo8at1WCUG2w0MNuZpxTRupjzTSJKkY-To2JQjntskVkUwED06W0ORNTsKYjZBsnMbLDQMDSh5R0ZomxIjbGc1USGJWn39fRBGQ_F_a_uxqwFD2OCFmQv4wqQ07wzEz-RdayTIT3a_jQPE7H2k7ngxa2cVjpzLN0VwptVu8Vi4YeUNH0T2oQm0g9Q']
INFO:oauth2client.client:Refreshing access_token
DEBUG:googleapiclient.discovery:URL being requested: GET https://www.googleapis.com/drive/v3/files/12xpxsV0IhJT0mPqxdO9dzsMjONwI7EcW?alt=media
WARNING:googleapiclient.discovery_cache:file_cache is unavailable when using oauth2client >= 4.0.0 or google-auth
Traceback (most recent call last):
  File "C:\Users\79069\AppData\Local\Programs\Python\Python39\lib\site-packages\googleapiclient\discovery_cache\file_cache.py", line 33, in <module>
    from oauth2client.contrib.locked_file import LockedFile
ModuleNotFoundError: No module named 'oauth2client.contrib.locked_file'

During handling of the above exception, another exception occurred:

Traceback (most recent call last):
  File "C:\Users\79069\AppData\Local\Programs\Python\Python39\lib\site-packages\googleapiclient\discovery_cache\file_cache.py", line 37, in <module>
    from oauth2client.locked_file import LockedFile
ModuleNotFoundError: No module named 'oauth2client.locked_file'

During handling of the above exception, another exception occurred:

Traceback (most recent call last):
  File "C:\Users\79069\AppData\Local\Programs\Python\Python39\lib\site-packages\googleapiclient\discovery_cache\__init__.py", line 44, in autodetect
    from . import file_cache
  File "C:\Users\79069\AppData\Local\Programs\Python\Python39\lib\site-packages\googleapiclient\discovery_cache\file_cache.py", line 40, in <module>
    raise ImportError(
ImportError: file_cache is unavailable when using oauth2client >= 4.0.0 or google-auth
DEBUG:googleapiclient.discovery:URL being requested: GET https://www.googleapis.com/discovery/v1/apis/drive/v3/rest
INFO:oauth2client.transport:Attempting refresh to obtain initial access_token
DEBUG:oauth2client.crypt:[b'eyJ0eXAiOiJKV1QiLCJhbGciOiJSUzI1NiIsImtpZCI6IjZiYzEzYmFjOTE0ZGZkNzliN2ZhOWQyODYxMzk5YzljZmY4OWFjNjcifQ', b'eyJhdWQiOiJodHRwczovL29hdXRoMi5nb29nbGVhcGlzLmNvbS90b2tlbiIsInNjb3BlIjoiaHR0cHM6Ly93d3cuZ29vZ2xlYXBpcy5jb20vYXV0aC9kcml2ZSIsImlhdCI6MTYxMzY0NjI3MiwiZXhwIjoxNjEzNjQ5ODcyLCJpc3MiOiJqdXN0LWFjY291bnRAdGVzdGFwaWFuZHNoZWV0cy5pYW0uZ3NlcnZpY2VhY2NvdW50LmNvbSJ9', b'j2tKumQzRFE-q3nJHTvAiR80yLkU6W_CxT2b8Tf9aTU_gujx-pUa39N4U2mMJEOjvPRkQZEZT01OsQnhRt7vMI2BpHaVhMheMwQLnnt21P4czaqUnqwbvuuBLRyyQLmMX8fllT3THHXrMibBN6PXMvbw2HupRgFtCssxBYP9bO0i_V8sM0FFJpstbyzASFDnq0Uz0ilc8uViFwvhZVLm5JvKM2gFGj5EJrbEAupRyS84GjAWjM0wsh7WQlg-pfALELJOkS7cqaReH_lRhZVxeofc8R4VEUY3Nfq97KyFUVrWtQFv6FkpfojCnB7zcOgywRw_lAB4CcEorPYd0KJYcg']
INFO:oauth2client.client:Refreshing access_token
DEBUG:googleapiclient.discovery:URL being requested: POST https://www.googleapis.com/upload/drive/v3/files?fields=id&alt=json&uploadType=multipart
INFO:root:You are logged in!
WARNING:googleapiclient.discovery_cache:file_cache is unavailable when using oauth2client >= 4.0.0 or google-auth
Traceback (most recent call last):
  File "C:\Users\79069\AppData\Local\Programs\Python\Python39\lib\site-packages\googleapiclient\discovery_cache\file_cache.py", line 33, in <module>
    from oauth2client.contrib.locked_file import LockedFile
ModuleNotFoundError: No module named 'oauth2client.contrib.locked_file'

During handling of the above exception, another exception occurred:

Traceback (most recent call last):
  File "C:\Users\79069\AppData\Local\Programs\Python\Python39\lib\site-packages\googleapiclient\discovery_cache\file_cache.py", line 37, in <module>
    from oauth2client.locked_file import LockedFile
ModuleNotFoundError: No module named 'oauth2client.locked_file'

During handling of the above exception, another exception occurred:

Traceback (most recent call last):
  File "C:\Users\79069\AppData\Local\Programs\Python\Python39\lib\site-packages\googleapiclient\discovery_cache\__init__.py", line 44, in autodetect
    from . import file_cache
  File "C:\Users\79069\AppData\Local\Programs\Python\Python39\lib\site-packages\googleapiclient\discovery_cache\file_cache.py", line 40, in <module>
    raise ImportError(
ImportError: file_cache is unavailable when using oauth2client >= 4.0.0 or google-auth
DEBUG:googleapiclient.discovery:URL being requested: GET https://www.googleapis.com/discovery/v1/apis/drive/v3/rest
INFO:oauth2client.transport:Attempting refresh to obtain initial access_token
DEBUG:oauth2client.crypt:[b'eyJ0eXAiOiJKV1QiLCJhbGciOiJSUzI1NiIsImtpZCI6IjZiYzEzYmFjOTE0ZGZkNzliN2ZhOWQyODYxMzk5YzljZmY4OWFjNjcifQ', b'eyJhdWQiOiJodHRwczovL29hdXRoMi5nb29nbGVhcGlzLmNvbS90b2tlbiIsInNjb3BlIjoiaHR0cHM6Ly93d3cuZ29vZ2xlYXBpcy5jb20vYXV0aC9kcml2ZSIsImlhdCI6MTYxMzY0NjM0OCwiZXhwIjoxNjEzNjQ5OTQ4LCJpc3MiOiJqdXN0LWFjY291bnRAdGVzdGFwaWFuZHNoZWV0cy5pYW0uZ3NlcnZpY2VhY2NvdW50LmNvbSJ9', b'bJVdrdNq-iaH6PdLRLnEqlju3jazo4JzXHN6JS74JbRpLQHgvXwd-pDDBZmBv8k59Dhm0CnwzSdH1G2MdVBFCVv7iRDaByAkc0_H60j8OEKdDhxOdKxOySfwJZ2FrHes52OU1QkcJ_yt5Foqs5g2qNT_pFGZZWyZgJaWQoBMN8F77E_d21vjdZoDAsSA7sjyfPSj8NL4V-jgjuSOqu_F1MEBQI5fR25NhYeywV2CQfmyRvOcTAxZhgJVnyOy88GXR3G_UO2JaG1LSoGpu1i76mxsBD_nF3rALjZD69Pu8UPT-a-x9TPOMm5Px49lLO58oZU3D0iiEzS1hITTAtmu4A']
INFO:oauth2client.client:Refreshing access_token
DEBUG:googleapiclient.discovery:URL being requested: POST https://www.googleapis.com/upload/drive/v3/files?fields=id&alt=json&uploadType=multipart
WARNING:googleapiclient.discovery_cache:file_cache is unavailable when using oauth2client >= 4.0.0 or google-auth
Traceback (most recent call last):
  File "C:\Users\79069\AppData\Local\Programs\Python\Python39\lib\site-packages\googleapiclient\discovery_cache\file_cache.py", line 33, in <module>
    from oauth2client.contrib.locked_file import LockedFile
ModuleNotFoundError: No module named 'oauth2client.contrib.locked_file'

During handling of the above exception, another exception occurred:

Traceback (most recent call last):
  File "C:\Users\79069\AppData\Local\Programs\Python\Python39\lib\site-packages\googleapiclient\discovery_cache\file_cache.py", line 37, in <module>
    from oauth2client.locked_file import LockedFile
ModuleNotFoundError: No module named 'oauth2client.locked_file'

During handling of the above exception, another exception occurred:

Traceback (most recent call last):
  File "C:\Users\79069\AppData\Local\Programs\Python\Python39\lib\site-packages\googleapiclient\discovery_cache\__init__.py", line 44, in autodetect
    from . import file_cache
  File "C:\Users\79069\AppData\Local\Programs\Python\Python39\lib\site-packages\googleapiclient\discovery_cache\file_cache.py", line 40, in <module>
    raise ImportError(
ImportError: file_cache is unavailable when using oauth2client >= 4.0.0 or google-auth
DEBUG:googleapiclient.discovery:URL being requested: GET https://www.googleapis.com/discovery/v1/apis/drive/v3/rest
INFO:oauth2client.transport:Attempting refresh to obtain initial access_token
DEBUG:oauth2client.crypt:[b'eyJ0eXAiOiJKV1QiLCJhbGciOiJSUzI1NiIsImtpZCI6IjZiYzEzYmFjOTE0ZGZkNzliN2ZhOWQyODYxMzk5YzljZmY4OWFjNjcifQ', b'eyJhdWQiOiJodHRwczovL29hdXRoMi5nb29nbGVhcGlzLmNvbS90b2tlbiIsInNjb3BlIjoiaHR0cHM6Ly93d3cuZ29vZ2xlYXBpcy5jb20vYXV0aC9kcml2ZSIsImlhdCI6MTYxMzY0OTk3OCwiZXhwIjoxNjEzNjUzNTc4LCJpc3MiOiJqdXN0LWFjY291bnRAdGVzdGFwaWFuZHNoZWV0cy5pYW0uZ3NlcnZpY2VhY2NvdW50LmNvbSJ9', b'e32FKsT8Su10Cl28C3TTDdLou9Q1Gw2YV7jILXXD1DE_CMQLZinNZR82tlGmKB1Xb5FmdeLLctb4ZAsvjoUmTPLMvFQIGSiJwLcj0jx_eOjezuVqP6AQ9CU3_eUbBf3ofMvF-Ievxnqm2fZCX6fdBVgv2zHkD_cim3pug-klWNkssRbDTJLWnlfCggpe4BiK__wkvmOAJRZwNdKkY2M7wmAt7WPH1MbfZ5B33aQp6vUBH7AywL5rnQ7Jqp3JM5srbVfR9-37qSyPS8bdzep7-U1a_PZC7fLWSEvby4boqzCw6i0depC57I2ZAn-nMulMKqPuC48ELV5-O_lBezSiKA']
INFO:oauth2client.client:Refreshing access_token
DEBUG:googleapiclient.discovery:URL being requested: GET https://www.googleapis.com/drive/v3/files/12xpxsV0IhJT0mPqxdO9dzsMjONwI7EcW?alt=media
WARNING:googleapiclient.discovery_cache:file_cache is unavailable when using oauth2client >= 4.0.0 or google-auth
Traceback (most recent call last):
  File "C:\Users\79069\AppData\Local\Programs\Python\Python39\lib\site-packages\googleapiclient\discovery_cache\file_cache.py", line 33, in <module>
    from oauth2client.contrib.locked_file import LockedFile
ModuleNotFoundError: No module named 'oauth2client.contrib.locked_file'

During handling of the above exception, another exception occurred:

Traceback (most recent call last):
  File "C:\Users\79069\AppData\Local\Programs\Python\Python39\lib\site-packages\googleapiclient\discovery_cache\file_cache.py", line 37, in <module>
    from oauth2client.locked_file import LockedFile
ModuleNotFoundError: No module named 'oauth2client.locked_file'

During handling of the above exception, another exception occurred:

Traceback (most recent call last):
  File "C:\Users\79069\AppData\Local\Programs\Python\Python39\lib\site-packages\googleapiclient\discovery_cache\__init__.py", line 44, in autodetect
    from . import file_cache
  File "C:\Users\79069\AppData\Local\Programs\Python\Python39\lib\site-packages\googleapiclient\discovery_cache\file_cache.py", line 40, in <module>
    raise ImportError(
ImportError: file_cache is unavailable when using oauth2client >= 4.0.0 or google-auth
DEBUG:googleapiclient.discovery:URL being requested: GET https://www.googleapis.com/discovery/v1/apis/drive/v3/rest
INFO:oauth2client.transport:Attempting refresh to obtain initial access_token
DEBUG:oauth2client.crypt:[b'eyJ0eXAiOiJKV1QiLCJhbGciOiJSUzI1NiIsImtpZCI6IjZiYzEzYmFjOTE0ZGZkNzliN2ZhOWQyODYxMzk5YzljZmY4OWFjNjcifQ', b'eyJhdWQiOiJodHRwczovL29hdXRoMi5nb29nbGVhcGlzLmNvbS90b2tlbiIsInNjb3BlIjoiaHR0cHM6Ly93d3cuZ29vZ2xlYXBpcy5jb20vYXV0aC9kcml2ZSIsImlhdCI6MTYxMzY0OTk4NiwiZXhwIjoxNjEzNjUzNTg2LCJpc3MiOiJqdXN0LWFjY291bnRAdGVzdGFwaWFuZHNoZWV0cy5pYW0uZ3NlcnZpY2VhY2NvdW50LmNvbSJ9', b'HBDzxsL25eR3AWMBpzFJX7po9HV9UYyuznVBFzSd-SSiF0sfkELarv-So3LgXDhnYG8dhEC1RrApk3_4zmkxPLiujg_ryMd3bxBlxu68wjQYemtzm14cWU3MYXfOPbw3D29F0KPNVHEMxCh6lr3u9aMJ243Ol-Thkt6gyJIIbYirYy_msg4HHeD6XaZtOzSHLMfMzqA1iy-3ke8B6foeC6eevGN85zBO5vvYDJAdpSaD_VP1O7PMd1Bo5H7Rm7h4kzUL_tFKNUYcXwMQXHpEI3rIGOwMtyxM3I40JDi7GixOycSz0SWC_ZABevDHCWtnLPTCmnEn3cxKuFHwBlFrKQ']
INFO:oauth2client.client:Refreshing access_token
DEBUG:googleapiclient.discovery:URL being requested: POST https://www.googleapis.com/upload/drive/v3/files?fields=id&alt=json&uploadType=multipart
WARNING:googleapiclient.discovery_cache:file_cache is unavailable when using oauth2client >= 4.0.0 or google-auth
Traceback (most recent call last):
  File "C:\Users\79069\AppData\Local\Programs\Python\Python39\lib\site-packages\googleapiclient\discovery_cache\file_cache.py", line 33, in <module>
    from oauth2client.contrib.locked_file import LockedFile
ModuleNotFoundError: No module named 'oauth2client.contrib.locked_file'

During handling of the above exception, another exception occurred:

Traceback (most recent call last):
  File "C:\Users\79069\AppData\Local\Programs\Python\Python39\lib\site-packages\googleapiclient\discovery_cache\file_cache.py", line 37, in <module>
    from oauth2client.locked_file import LockedFile
ModuleNotFoundError: No module named 'oauth2client.locked_file'

During handling of the above exception, another exception occurred:

Traceback (most recent call last):
  File "C:\Users\79069\AppData\Local\Programs\Python\Python39\lib\site-packages\googleapiclient\discovery_cache\__init__.py", line 44, in autodetect
    from . import file_cache
  File "C:\Users\79069\AppData\Local\Programs\Python\Python39\lib\site-packages\googleapiclient\discovery_cache\file_cache.py", line 40, in <module>
    raise ImportError(
ImportError: file_cache is unavailable when using oauth2client >= 4.0.0 or google-auth
DEBUG:googleapiclient.discovery:URL being requested: GET https://www.googleapis.com/discovery/v1/apis/drive/v3/rest
INFO:oauth2client.transport:Attempting refresh to obtain initial access_token
DEBUG:oauth2client.crypt:[b'eyJ0eXAiOiJKV1QiLCJhbGciOiJSUzI1NiIsImtpZCI6IjZiYzEzYmFjOTE0ZGZkNzliN2ZhOWQyODYxMzk5YzljZmY4OWFjNjcifQ', b'eyJhdWQiOiJodHRwczovL29hdXRoMi5nb29nbGVhcGlzLmNvbS90b2tlbiIsInNjb3BlIjoiaHR0cHM6Ly93d3cuZ29vZ2xlYXBpcy5jb20vYXV0aC9kcml2ZSIsImlhdCI6MTYxMzY1MDAyNCwiZXhwIjoxNjEzNjUzNjI0LCJpc3MiOiJqdXN0LWFjY291bnRAdGVzdGFwaWFuZHNoZWV0cy5pYW0uZ3NlcnZpY2VhY2NvdW50LmNvbSJ9', b'w49TBzcbewyNpIqIkWQO4P2Ugv3HZCBLMzbVb9e0erI55zuzOrdHGavbIRIgcQUaE6Ie4Xgz6ZlAk8N3ouHIQU64jcZpgukLO8bj69cZAwJ03fduSJnFK9HUwRoQCt6ff-3U36b5JgMyo4qPv8WwGPDqVuvATl1SbIJ9-k6eHAaK6eppMBswIP5UUj_0-1DMbCuz6-r7rbnc5jd46csraqnv8coENfjutQ-F_S7iu9MQiII4MgJWk2fKKp0SSs2BTvYwNBcUNdnO99_KkDBrbAnaR1kAWLecSYQa98RxF7Au6Z6Qe91HkTLuiYwTmZ_YRlc0OakfZTs-WoGUq4Ep8Q']
INFO:oauth2client.client:Refreshing access_token
DEBUG:googleapiclient.discovery:URL being requested: GET https://www.googleapis.com/drive/v3/files/12xpxsV0IhJT0mPqxdO9dzsMjONwI7EcW?alt=media
WARNING:googleapiclient.discovery_cache:file_cache is unavailable when using oauth2client >= 4.0.0 or google-auth
Traceback (most recent call last):
  File "C:\Users\79069\AppData\Local\Programs\Python\Python39\lib\site-packages\googleapiclient\discovery_cache\file_cache.py", line 33, in <module>
    from oauth2client.contrib.locked_file import LockedFile
ModuleNotFoundError: No module named 'oauth2client.contrib.locked_file'

During handling of the above exception, another exception occurred:

Traceback (most recent call last):
  File "C:\Users\79069\AppData\Local\Programs\Python\Python39\lib\site-packages\googleapiclient\discovery_cache\file_cache.py", line 37, in <module>
    from oauth2client.locked_file import LockedFile
ModuleNotFoundError: No module named 'oauth2client.locked_file'

During handling of the above exception, another exception occurred:

Traceback (most recent call last):
  File "C:\Users\79069\AppData\Local\Programs\Python\Python39\lib\site-packages\googleapiclient\discovery_cache\__init__.py", line 44, in autodetect
    from . import file_cache
  File "C:\Users\79069\AppData\Local\Programs\Python\Python39\lib\site-packages\googleapiclient\discovery_cache\file_cache.py", line 40, in <module>
    raise ImportError(
ImportError: file_cache is unavailable when using oauth2client >= 4.0.0 or google-auth
DEBUG:googleapiclient.discovery:URL being requested: GET https://www.googleapis.com/discovery/v1/apis/drive/v3/rest
INFO:oauth2client.transport:Attempting refresh to obtain initial access_token
DEBUG:oauth2client.crypt:[b'eyJ0eXAiOiJKV1QiLCJhbGciOiJSUzI1NiIsImtpZCI6IjZiYzEzYmFjOTE0ZGZkNzliN2ZhOWQyODYxMzk5YzljZmY4OWFjNjcifQ', b'eyJhdWQiOiJodHRwczovL29hdXRoMi5nb29nbGVhcGlzLmNvbS90b2tlbiIsInNjb3BlIjoiaHR0cHM6Ly93d3cuZ29vZ2xlYXBpcy5jb20vYXV0aC9kcml2ZSIsImlhdCI6MTYxMzY1MDAzMSwiZXhwIjoxNjEzNjUzNjMxLCJpc3MiOiJqdXN0LWFjY291bnRAdGVzdGFwaWFuZHNoZWV0cy5pYW0uZ3NlcnZpY2VhY2NvdW50LmNvbSJ9', b'V35b-Zaq3eGRJGIPH3GyGXxXoZAqW0jJnTxL0VNXNgzScQHQrTgFcV6YC01EED8sy3uxzULJutgOCpgOjHilMftCEANteke1Wcp_0xEes8g9FCinS8nn2itF_w2pYdJxAnf-3sMdrsQXYusmNZFJe9Gvcqjy_j9p97DqgdM4KQjt-HfPLAKxgG6lr92vTP868y9uqAfqapH3OS4jMWg0udZ_tiwt8w_XTQ2xGDBloNvc7KasIOvY_DfFvOEU6jAcv3ATMcN-RH1_K0GwTxif4ajFseYuayjfsLg7MCMrOXUa0VrucrL7eStnEh6cIY2prbtQKK2tP1gb6MSmv383oA']
INFO:oauth2client.client:Refreshing access_token
DEBUG:googleapiclient.discovery:URL being requested: POST https://www.googleapis.com/upload/drive/v3/files?fields=id&alt=json&uploadType=multipart
WARNING:googleapiclient.discovery_cache:file_cache is unavailable when using oauth2client >= 4.0.0 or google-auth
Traceback (most recent call last):
  File "C:\Users\79069\AppData\Local\Programs\Python\Python39\lib\site-packages\googleapiclient\discovery_cache\file_cache.py", line 33, in <module>
    from oauth2client.contrib.locked_file import LockedFile
ModuleNotFoundError: No module named 'oauth2client.contrib.locked_file'

During handling of the above exception, another exception occurred:

Traceback (most recent call last):
  File "C:\Users\79069\AppData\Local\Programs\Python\Python39\lib\site-packages\googleapiclient\discovery_cache\file_cache.py", line 37, in <module>
    from oauth2client.locked_file import LockedFile
ModuleNotFoundError: No module named 'oauth2client.locked_file'

During handling of the above exception, another exception occurred:

Traceback (most recent call last):
  File "C:\Users\79069\AppData\Local\Programs\Python\Python39\lib\site-packages\googleapiclient\discovery_cache\__init__.py", line 44, in autodetect
    from . import file_cache
  File "C:\Users\79069\AppData\Local\Programs\Python\Python39\lib\site-packages\googleapiclient\discovery_cache\file_cache.py", line 40, in <module>
    raise ImportError(
ImportError: file_cache is unavailable when using oauth2client >= 4.0.0 or google-auth
DEBUG:googleapiclient.discovery:URL being requested: GET https://www.googleapis.com/discovery/v1/apis/drive/v3/rest
INFO:oauth2client.transport:Attempting refresh to obtain initial access_token
DEBUG:oauth2client.crypt:[b'eyJ0eXAiOiJKV1QiLCJhbGciOiJSUzI1NiIsImtpZCI6IjZiYzEzYmFjOTE0ZGZkNzliN2ZhOWQyODYxMzk5YzljZmY4OWFjNjcifQ', b'eyJhdWQiOiJodHRwczovL29hdXRoMi5nb29nbGVhcGlzLmNvbS90b2tlbiIsInNjb3BlIjoiaHR0cHM6Ly93d3cuZ29vZ2xlYXBpcy5jb20vYXV0aC9kcml2ZSIsImlhdCI6MTYxMzY1MDI4NCwiZXhwIjoxNjEzNjUzODg0LCJpc3MiOiJqdXN0LWFjY291bnRAdGVzdGFwaWFuZHNoZWV0cy5pYW0uZ3NlcnZpY2VhY2NvdW50LmNvbSJ9', b'Ebt5U5aUWiOirNbHSJbz6JzPFq9F-8z9re_KRglfJyX97wjpgfkaqqt1Ta5m1Erh6Igu-aqpX_1mxuAbd7WAkDbwqjVaQbL7gRxahIdRlLea3sXRfEgU2hAw5BR3n-whZM90paR9skqEaZ3pMyw3y9pJvOtblHZE3P0h0DT_YeKWwZJS8R0X7DlT9OcvlIVQmjjDwuREMRqHvnryhfrqC1C12DBnOkTMzt5CP2l9BsbStUCE-uKKNKrYPh-UYdCfPeFX6txY8U5MxqxJFduBBz7y0K5wgZpOgfapo80B0F3JNP6_eqa0rBgZNomrQ5snXCoZNRNHDf8CiSICTCnuCQ']
INFO:oauth2client.client:Refreshing access_token
DEBUG:googleapiclient.discovery:URL being requested: GET https://www.googleapis.com/drive/v3/files/12xpxsV0IhJT0mPqxdO9dzsMjONwI7EcW?alt=media
WARNING:googleapiclient.discovery_cache:file_cache is unavailable when using oauth2client >= 4.0.0 or google-auth
Traceback (most recent call last):
  File "C:\Users\79069\AppData\Local\Programs\Python\Python39\lib\site-packages\googleapiclient\discovery_cache\file_cache.py", line 33, in <module>
    from oauth2client.contrib.locked_file import LockedFile
ModuleNotFoundError: No module named 'oauth2client.contrib.locked_file'

During handling of the above exception, another exception occurred:

Traceback (most recent call last):
  File "C:\Users\79069\AppData\Local\Programs\Python\Python39\lib\site-packages\googleapiclient\discovery_cache\file_cache.py", line 37, in <module>
    from oauth2client.locked_file import LockedFile
ModuleNotFoundError: No module named 'oauth2client.locked_file'

During handling of the above exception, another exception occurred:

Traceback (most recent call last):
  File "C:\Users\79069\AppData\Local\Programs\Python\Python39\lib\site-packages\googleapiclient\discovery_cache\__init__.py", line 44, in autodetect
    from . import file_cache
  File "C:\Users\79069\AppData\Local\Programs\Python\Python39\lib\site-packages\googleapiclient\discovery_cache\file_cache.py", line 40, in <module>
    raise ImportError(
ImportError: file_cache is unavailable when using oauth2client >= 4.0.0 or google-auth
DEBUG:googleapiclient.discovery:URL being requested: GET https://www.googleapis.com/discovery/v1/apis/drive/v3/rest
INFO:oauth2client.transport:Attempting refresh to obtain initial access_token
DEBUG:oauth2client.crypt:[b'eyJ0eXAiOiJKV1QiLCJhbGciOiJSUzI1NiIsImtpZCI6IjZiYzEzYmFjOTE0ZGZkNzliN2ZhOWQyODYxMzk5YzljZmY4OWFjNjcifQ', b'eyJhdWQiOiJodHRwczovL29hdXRoMi5nb29nbGVhcGlzLmNvbS90b2tlbiIsInNjb3BlIjoiaHR0cHM6Ly93d3cuZ29vZ2xlYXBpcy5jb20vYXV0aC9kcml2ZSIsImlhdCI6MTYxMzY1MDI5MCwiZXhwIjoxNjEzNjUzODkwLCJpc3MiOiJqdXN0LWFjY291bnRAdGVzdGFwaWFuZHNoZWV0cy5pYW0uZ3NlcnZpY2VhY2NvdW50LmNvbSJ9', b'7ROsTS_uzegMTvYLF2ENy1JGOV8FcI_qkKtcbkiBAKBCQinUfgVYg7MIxCqaZZSmzHqWSnF1n71g8BHekFkxnT3j08oAb96bJygkrJEC7jdz-xEUSVy8Q7rsPEJQ53jblChf8RxPML5HzLesNyLXPqmPBz40z6CzyRzTZ4f_-GMuxhGdM-3fpIydAFAxg9LMLLfmcJfWfQQuj_iRMjRnPie6wRvh1No2mVkIgFhO2HOF03sP9eUy0YIZHSjnrfs9A6fEGWa-1MRhxez-GL38F_z16MF5SiS8j9SIpUgkrTbGfEQpMgI1AJISIPZkzXywA15xtlqe4rrsG-t6OkLtUA']
INFO:oauth2client.client:Refreshing access_token
DEBUG:googleapiclient.discovery:URL being requested: POST https://www.googleapis.com/upload/drive/v3/files?fields=id&alt=json&uploadType=multipart
WARNING:googleapiclient.discovery_cache:file_cache is unavailable when using oauth2client >= 4.0.0 or google-auth
Traceback (most recent call last):
  File "C:\Users\79069\AppData\Local\Programs\Python\Python39\lib\site-packages\googleapiclient\discovery_cache\file_cache.py", line 33, in <module>
    from oauth2client.contrib.locked_file import LockedFile
ModuleNotFoundError: No module named 'oauth2client.contrib.locked_file'

During handling of the above exception, another exception occurred:

Traceback (most recent call last):
  File "C:\Users\79069\AppData\Local\Programs\Python\Python39\lib\site-packages\googleapiclient\discovery_cache\file_cache.py", line 37, in <module>
    from oauth2client.locked_file import LockedFile
ModuleNotFoundError: No module named 'oauth2client.locked_file'

During handling of the above exception, another exception occurred:

Traceback (most recent call last):
  File "C:\Users\79069\AppData\Local\Programs\Python\Python39\lib\site-packages\googleapiclient\discovery_cache\__init__.py", line 44, in autodetect
    from . import file_cache
  File "C:\Users\79069\AppData\Local\Programs\Python\Python39\lib\site-packages\googleapiclient\discovery_cache\file_cache.py", line 40, in <module>
    raise ImportError(
ImportError: file_cache is unavailable when using oauth2client >= 4.0.0 or google-auth
DEBUG:googleapiclient.discovery:URL being requested: GET https://www.googleapis.com/discovery/v1/apis/drive/v3/rest
INFO:oauth2client.transport:Attempting refresh to obtain initial access_token
DEBUG:oauth2client.crypt:[b'eyJ0eXAiOiJKV1QiLCJhbGciOiJSUzI1NiIsImtpZCI6IjZiYzEzYmFjOTE0ZGZkNzliN2ZhOWQyODYxMzk5YzljZmY4OWFjNjcifQ', b'eyJhdWQiOiJodHRwczovL29hdXRoMi5nb29nbGVhcGlzLmNvbS90b2tlbiIsInNjb3BlIjoiaHR0cHM6Ly93d3cuZ29vZ2xlYXBpcy5jb20vYXV0aC9kcml2ZSIsImlhdCI6MTYxMzY1MTAwNSwiZXhwIjoxNjEzNjU0NjA1LCJpc3MiOiJqdXN0LWFjY291bnRAdGVzdGFwaWFuZHNoZWV0cy5pYW0uZ3NlcnZpY2VhY2NvdW50LmNvbSJ9', b'DAfVlRuYoTFahVqygtlElKetMqYYGor3R6PX78Ojv-gU1RHi1eb1fr6ydvm7uHeUXw1KcllKbOfy_LP6qhVZQBYQZ3k3L8HJHFoPINbaaUtwFJnG8XhCQL0fip5uZniXiquQ0O-7-rYBzle57CO-bqBVTEmyQYJ9LGNOaMPz1z4DMcz1dZckm7788ooIKsT3b7ooxvTfs4-Zbe2nMcmrGpfPF7X6SIwJWE_gqsGIo7yFaNNsgZsf5cNKaGxWqaBCu9AUTo_qpiBS39XiNg3XTAQN6-JrUlyYZ5td_FUE0k_FLotFIIH39K7g7mHALBaP2ES5Ghb5GiV6dPEV5g9dNw']
INFO:oauth2client.client:Refreshing access_token
DEBUG:googleapiclient.discovery:URL being requested: GET https://www.googleapis.com/drive/v3/files/12xpxsV0IhJT0mPqxdO9dzsMjONwI7EcW?alt=media
WARNING:googleapiclient.discovery_cache:file_cache is unavailable when using oauth2client >= 4.0.0 or google-auth
Traceback (most recent call last):
  File "C:\Users\79069\AppData\Local\Programs\Python\Python39\lib\site-packages\googleapiclient\discovery_cache\file_cache.py", line 33, in <module>
    from oauth2client.contrib.locked_file import LockedFile
ModuleNotFoundError: No module named 'oauth2client.contrib.locked_file'

During handling of the above exception, another exception occurred:

Traceback (most recent call last):
  File "C:\Users\79069\AppData\Local\Programs\Python\Python39\lib\site-packages\googleapiclient\discovery_cache\file_cache.py", line 37, in <module>
    from oauth2client.locked_file import LockedFile
ModuleNotFoundError: No module named 'oauth2client.locked_file'

During handling of the above exception, another exception occurred:

Traceback (most recent call last):
  File "C:\Users\79069\AppData\Local\Programs\Python\Python39\lib\site-packages\googleapiclient\discovery_cache\__init__.py", line 44, in autodetect
    from . import file_cache
  File "C:\Users\79069\AppData\Local\Programs\Python\Python39\lib\site-packages\googleapiclient\discovery_cache\file_cache.py", line 40, in <module>
    raise ImportError(
ImportError: file_cache is unavailable when using oauth2client >= 4.0.0 or google-auth
DEBUG:googleapiclient.discovery:URL being requested: GET https://www.googleapis.com/discovery/v1/apis/drive/v3/rest
INFO:oauth2client.transport:Attempting refresh to obtain initial access_token
DEBUG:oauth2client.crypt:[b'eyJ0eXAiOiJKV1QiLCJhbGciOiJSUzI1NiIsImtpZCI6IjZiYzEzYmFjOTE0ZGZkNzliN2ZhOWQyODYxMzk5YzljZmY4OWFjNjcifQ', b'eyJhdWQiOiJodHRwczovL29hdXRoMi5nb29nbGVhcGlzLmNvbS90b2tlbiIsInNjb3BlIjoiaHR0cHM6Ly93d3cuZ29vZ2xlYXBpcy5jb20vYXV0aC9kcml2ZSIsImlhdCI6MTYxMzY1MTAxMywiZXhwIjoxNjEzNjU0NjEzLCJpc3MiOiJqdXN0LWFjY291bnRAdGVzdGFwaWFuZHNoZWV0cy5pYW0uZ3NlcnZpY2VhY2NvdW50LmNvbSJ9', b'IUA17-on7eBH5UMmQnPj2eaeCzkMEZcHQCG3A94mtQ8b1MDqQ536gEuLJJ5gT3EjmbSMQ53EQI3wunVUxuRsGrm7rqmwzjLSsBFBEQYa6rqT2IScZSJOxwdqt0G1v6w01zpKIe60limGSuvI1jur3eRzqJppdSzMMAkkAq5_IPGHs3_zlHTIcHDdxJzvfqlfKTk7sPxppOg4trd8spr9avy6gyInl-GzN-WfAb7eZllnqe_iTRpjqPDIJa5p74Pu0iZuLxlXbOgSQmbZvaOXNP1zxt4VxO3UZvGAKiqSMjTCndqcP4t454q8RBsopnLDodw_CL260JrBTY1Rir2BrA']
INFO:oauth2client.client:Refreshing access_token
DEBUG:googleapiclient.discovery:URL being requested: POST https://www.googleapis.com/upload/drive/v3/files?fields=id&alt=json&uploadType=multipart
WARNING:googleapiclient.discovery_cache:file_cache is unavailable when using oauth2client >= 4.0.0 or google-auth
Traceback (most recent call last):
  File "C:\Users\79069\AppData\Local\Programs\Python\Python39\lib\site-packages\googleapiclient\discovery_cache\file_cache.py", line 33, in <module>
    from oauth2client.contrib.locked_file import LockedFile
ModuleNotFoundError: No module named 'oauth2client.contrib.locked_file'

During handling of the above exception, another exception occurred:

Traceback (most recent call last):
  File "C:\Users\79069\AppData\Local\Programs\Python\Python39\lib\site-packages\googleapiclient\discovery_cache\file_cache.py", line 37, in <module>
    from oauth2client.locked_file import LockedFile
ModuleNotFoundError: No module named 'oauth2client.locked_file'

During handling of the above exception, another exception occurred:

Traceback (most recent call last):
  File "C:\Users\79069\AppData\Local\Programs\Python\Python39\lib\site-packages\googleapiclient\discovery_cache\__init__.py", line 44, in autodetect
    from . import file_cache
  File "C:\Users\79069\AppData\Local\Programs\Python\Python39\lib\site-packages\googleapiclient\discovery_cache\file_cache.py", line 40, in <module>
    raise ImportError(
ImportError: file_cache is unavailable when using oauth2client >= 4.0.0 or google-auth
DEBUG:googleapiclient.discovery:URL being requested: GET https://www.googleapis.com/discovery/v1/apis/drive/v3/rest
INFO:oauth2client.transport:Attempting refresh to obtain initial access_token
DEBUG:oauth2client.crypt:[b'eyJ0eXAiOiJKV1QiLCJhbGciOiJSUzI1NiIsImtpZCI6IjZiYzEzYmFjOTE0ZGZkNzliN2ZhOWQyODYxMzk5YzljZmY4OWFjNjcifQ', b'eyJhdWQiOiJodHRwczovL29hdXRoMi5nb29nbGVhcGlzLmNvbS90b2tlbiIsInNjb3BlIjoiaHR0cHM6Ly93d3cuZ29vZ2xlYXBpcy5jb20vYXV0aC9kcml2ZSIsImlhdCI6MTYxMzY1MTIyMywiZXhwIjoxNjEzNjU0ODIzLCJpc3MiOiJqdXN0LWFjY291bnRAdGVzdGFwaWFuZHNoZWV0cy5pYW0uZ3NlcnZpY2VhY2NvdW50LmNvbSJ9', b'OmjL4yHE6sBQFM-DhZJiseMJi5n029VlAfVr9FQddeEstgUaNU_jv3kZOC2uZChpH3cxjeH23fG6hjcVnkTsTfTIFH-oodu3F59BAkUIdEObliOFY-ZDva9BEf3pIRvlxo62YvucEfEyUAKw_q8IIIx_e9vdoEIXin12tEXCD1ExX6a4lMbXugNOLHiSB4aXNSHUFPGCiU2v8QDxlKCkz46QVsd6z3waTjX4kNyucNOsZNM6cE13Yfu70lMir8ZOwax4CYqnvdY3iuZsWeXKeLSUS566UMQaLpydj6uzKVI_VgCHNQyuTEclYsNU1TDVmCm6ZgkJt8HQrHyTsAuvLw']
INFO:oauth2client.client:Refreshing access_token
DEBUG:googleapiclient.discovery:URL being requested: GET https://www.googleapis.com/drive/v3/files/12xpxsV0IhJT0mPqxdO9dzsMjONwI7EcW?alt=media
WARNING:googleapiclient.discovery_cache:file_cache is unavailable when using oauth2client >= 4.0.0 or google-auth
Traceback (most recent call last):
  File "C:\Users\79069\AppData\Local\Programs\Python\Python39\lib\site-packages\googleapiclient\discovery_cache\file_cache.py", line 33, in <module>
    from oauth2client.contrib.locked_file import LockedFile
ModuleNotFoundError: No module named 'oauth2client.contrib.locked_file'

During handling of the above exception, another exception occurred:

Traceback (most recent call last):
  File "C:\Users\79069\AppData\Local\Programs\Python\Python39\lib\site-packages\googleapiclient\discovery_cache\file_cache.py", line 37, in <module>
    from oauth2client.locked_file import LockedFile
ModuleNotFoundError: No module named 'oauth2client.locked_file'

During handling of the above exception, another exception occurred:

Traceback (most recent call last):
  File "C:\Users\79069\AppData\Local\Programs\Python\Python39\lib\site-packages\googleapiclient\discovery_cache\__init__.py", line 44, in autodetect
    from . import file_cache
  File "C:\Users\79069\AppData\Local\Programs\Python\Python39\lib\site-packages\googleapiclient\discovery_cache\file_cache.py", line 40, in <module>
    raise ImportError(
ImportError: file_cache is unavailable when using oauth2client >= 4.0.0 or google-auth
DEBUG:googleapiclient.discovery:URL being requested: GET https://www.googleapis.com/discovery/v1/apis/drive/v3/rest
INFO:oauth2client.transport:Attempting refresh to obtain initial access_token
DEBUG:oauth2client.crypt:[b'eyJ0eXAiOiJKV1QiLCJhbGciOiJSUzI1NiIsImtpZCI6IjZiYzEzYmFjOTE0ZGZkNzliN2ZhOWQyODYxMzk5YzljZmY4OWFjNjcifQ', b'eyJhdWQiOiJodHRwczovL29hdXRoMi5nb29nbGVhcGlzLmNvbS90b2tlbiIsInNjb3BlIjoiaHR0cHM6Ly93d3cuZ29vZ2xlYXBpcy5jb20vYXV0aC9kcml2ZSIsImlhdCI6MTYxMzY1MTIzMSwiZXhwIjoxNjEzNjU0ODMxLCJpc3MiOiJqdXN0LWFjY291bnRAdGVzdGFwaWFuZHNoZWV0cy5pYW0uZ3NlcnZpY2VhY2NvdW50LmNvbSJ9', b'pAsx8mO_M8OhfjFWbyz1jFvQe0Fieqr5WEGu5W3nc2vGFBCM66jbhyFzZ76daeKBsPZbCccgsnOuozd8yCmlTcZAItGdIUipMeaWAaXtFahnDSlUN_tLCLQJzo1u1lZwH2eGKIsPpbrqgiR8egqSbHtwR-OdDzGEE9ua2_qXHaosajTPWjeZbQxLY7mVEfT1lCZ5gtc4aDG3ejYiMKn4cbSi34Gi2Sq1fv3i68WwjjvqAG-ap0I42auhTpfZmtsH08eYi7dLWjOwcvdJOkXDRxrO-Dm2crKAfrjm6a7GV7qBNtVOXs06L2fIPHRItHPnz6yhAHj-k8qF8xV9OPc9qw']
INFO:oauth2client.client:Refreshing access_token
DEBUG:googleapiclient.discovery:URL being requested: POST https://www.googleapis.com/upload/drive/v3/files?fields=id&alt=json&uploadType=multipart
WARNING:googleapiclient.discovery_cache:file_cache is unavailable when using oauth2client >= 4.0.0 or google-auth
Traceback (most recent call last):
  File "C:\Users\79069\AppData\Local\Programs\Python\Python39\lib\site-packages\googleapiclient\discovery_cache\file_cache.py", line 33, in <module>
    from oauth2client.contrib.locked_file import LockedFile
ModuleNotFoundError: No module named 'oauth2client.contrib.locked_file'

During handling of the above exception, another exception occurred:

Traceback (most recent call last):
  File "C:\Users\79069\AppData\Local\Programs\Python\Python39\lib\site-packages\googleapiclient\discovery_cache\file_cache.py", line 37, in <module>
    from oauth2client.locked_file import LockedFile
ModuleNotFoundError: No module named 'oauth2client.locked_file'

During handling of the above exception, another exception occurred:

Traceback (most recent call last):
  File "C:\Users\79069\AppData\Local\Programs\Python\Python39\lib\site-packages\googleapiclient\discovery_cache\__init__.py", line 44, in autodetect
    from . import file_cache
  File "C:\Users\79069\AppData\Local\Programs\Python\Python39\lib\site-packages\googleapiclient\discovery_cache\file_cache.py", line 40, in <module>
    raise ImportError(
ImportError: file_cache is unavailable when using oauth2client >= 4.0.0 or google-auth
DEBUG:googleapiclient.discovery:URL being requested: GET https://www.googleapis.com/discovery/v1/apis/drive/v3/rest
INFO:oauth2client.transport:Attempting refresh to obtain initial access_token
DEBUG:oauth2client.crypt:[b'eyJ0eXAiOiJKV1QiLCJhbGciOiJSUzI1NiIsImtpZCI6IjZiYzEzYmFjOTE0ZGZkNzliN2ZhOWQyODYxMzk5YzljZmY4OWFjNjcifQ', b'eyJhdWQiOiJodHRwczovL29hdXRoMi5nb29nbGVhcGlzLmNvbS90b2tlbiIsInNjb3BlIjoiaHR0cHM6Ly93d3cuZ29vZ2xlYXBpcy5jb20vYXV0aC9kcml2ZSIsImlhdCI6MTYxMzY1MTI1NSwiZXhwIjoxNjEzNjU0ODU1LCJpc3MiOiJqdXN0LWFjY291bnRAdGVzdGFwaWFuZHNoZWV0cy5pYW0uZ3NlcnZpY2VhY2NvdW50LmNvbSJ9', b'KkjzM4P4aplk4y_baWyI1Jg6wNrIm_H5Kk1pdpIBVWgw_XyI0IZ98HRUxj4ReDEdD_g9v2UheqqBK2MxYrLfWXbyVx7qPTJwcziDd2kaoZq_MX4W8NjkPXKsKgM3k050tuF2LE9CMtmR9MYa54aRFIGpn7xAWx-mng8-_FWKfivvKIXZkwMT0ak2de_RCrYvoiZST0fEMEf2PD6tS60dyOWFvrj5oPtPGhy5q1FZcTetrnrkDkTDcsH48WDP6jPu-7wUzR88o3nTJ7RzJmou_X6Tb1s4ZC5bNTecyn4SGb0Uj-MEI2507zv0XYNYlZZvIitaknnAPoQ3MBxMj8Mouw']
INFO:oauth2client.client:Refreshing access_token
DEBUG:googleapiclient.discovery:URL being requested: GET https://www.googleapis.com/drive/v3/files/12xpxsV0IhJT0mPqxdO9dzsMjONwI7EcW?alt=media
WARNING:googleapiclient.discovery_cache:file_cache is unavailable when using oauth2client >= 4.0.0 or google-auth
Traceback (most recent call last):
  File "C:\Users\79069\AppData\Local\Programs\Python\Python39\lib\site-packages\googleapiclient\discovery_cache\file_cache.py", line 33, in <module>
    from oauth2client.contrib.locked_file import LockedFile
ModuleNotFoundError: No module named 'oauth2client.contrib.locked_file'

During handling of the above exception, another exception occurred:

Traceback (most recent call last):
  File "C:\Users\79069\AppData\Local\Programs\Python\Python39\lib\site-packages\googleapiclient\discovery_cache\file_cache.py", line 37, in <module>
    from oauth2client.locked_file import LockedFile
ModuleNotFoundError: No module named 'oauth2client.locked_file'

During handling of the above exception, another exception occurred:

Traceback (most recent call last):
  File "C:\Users\79069\AppData\Local\Programs\Python\Python39\lib\site-packages\googleapiclient\discovery_cache\__init__.py", line 44, in autodetect
    from . import file_cache
  File "C:\Users\79069\AppData\Local\Programs\Python\Python39\lib\site-packages\googleapiclient\discovery_cache\file_cache.py", line 40, in <module>
    raise ImportError(
ImportError: file_cache is unavailable when using oauth2client >= 4.0.0 or google-auth
DEBUG:googleapiclient.discovery:URL being requested: GET https://www.googleapis.com/discovery/v1/apis/drive/v3/rest
INFO:oauth2client.transport:Attempting refresh to obtain initial access_token
DEBUG:oauth2client.crypt:[b'eyJ0eXAiOiJKV1QiLCJhbGciOiJSUzI1NiIsImtpZCI6IjZiYzEzYmFjOTE0ZGZkNzliN2ZhOWQyODYxMzk5YzljZmY4OWFjNjcifQ', b'eyJhdWQiOiJodHRwczovL29hdXRoMi5nb29nbGVhcGlzLmNvbS90b2tlbiIsInNjb3BlIjoiaHR0cHM6Ly93d3cuZ29vZ2xlYXBpcy5jb20vYXV0aC9kcml2ZSIsImlhdCI6MTYxMzY1MTI2MiwiZXhwIjoxNjEzNjU0ODYyLCJpc3MiOiJqdXN0LWFjY291bnRAdGVzdGFwaWFuZHNoZWV0cy5pYW0uZ3NlcnZpY2VhY2NvdW50LmNvbSJ9', b'dczPrw_C7uLBuKIpl7VorPTIp8ftgD51gHNorCu-oIlCHPh0c9jLOleORVq-AqF0fDPC2FUq1Hjc65No12DRdFd0AVY__5sZiKBOJ3dIuoT2GMHFrAtG7wEMn8o2PyF3vuYi_e9rmJeScUtqybMhCO0OtLD_RvtK7l1FUXWBq-d6zm_flTsRhnC5dzqdKfhdLDPivpXE-65MdI9JAaIT5spz1utbQph1pZt4aoHd8ApD4FCDfoYwDYRc_dG5fo10RFHD5XTwIhdfvDOM5ayYxEd5lBESjZPyc1iAwrSfVPPKpZzECfs3qIFI1j95d7Urqn5i0WRbG41MW__iFE_rzg']
INFO:oauth2client.client:Refreshing access_token
DEBUG:googleapiclient.discovery:URL being requested: POST https://www.googleapis.com/upload/drive/v3/files?fields=id&alt=json&uploadType=multipart
WARNING:googleapiclient.discovery_cache:file_cache is unavailable when using oauth2client >= 4.0.0 or google-auth
Traceback (most recent call last):
  File "C:\Users\79069\AppData\Local\Programs\Python\Python39\lib\site-packages\googleapiclient\discovery_cache\file_cache.py", line 33, in <module>
    from oauth2client.contrib.locked_file import LockedFile
ModuleNotFoundError: No module named 'oauth2client.contrib.locked_file'

During handling of the above exception, another exception occurred:

Traceback (most recent call last):
  File "C:\Users\79069\AppData\Local\Programs\Python\Python39\lib\site-packages\googleapiclient\discovery_cache\file_cache.py", line 37, in <module>
    from oauth2client.locked_file import LockedFile
ModuleNotFoundError: No module named 'oauth2client.locked_file'

During handling of the above exception, another exception occurred:

Traceback (most recent call last):
  File "C:\Users\79069\AppData\Local\Programs\Python\Python39\lib\site-packages\googleapiclient\discovery_cache\__init__.py", line 44, in autodetect
    from . import file_cache
  File "C:\Users\79069\AppData\Local\Programs\Python\Python39\lib\site-packages\googleapiclient\discovery_cache\file_cache.py", line 40, in <module>
    raise ImportError(
ImportError: file_cache is unavailable when using oauth2client >= 4.0.0 or google-auth
DEBUG:googleapiclient.discovery:URL being requested: GET https://www.googleapis.com/discovery/v1/apis/drive/v3/rest
INFO:oauth2client.transport:Attempting refresh to obtain initial access_token
DEBUG:oauth2client.crypt:[b'eyJ0eXAiOiJKV1QiLCJhbGciOiJSUzI1NiIsImtpZCI6IjZiYzEzYmFjOTE0ZGZkNzliN2ZhOWQyODYxMzk5YzljZmY4OWFjNjcifQ', b'eyJhdWQiOiJodHRwczovL29hdXRoMi5nb29nbGVhcGlzLmNvbS90b2tlbiIsInNjb3BlIjoiaHR0cHM6Ly93d3cuZ29vZ2xlYXBpcy5jb20vYXV0aC9kcml2ZSIsImlhdCI6MTYxMzY1MTMzNywiZXhwIjoxNjEzNjU0OTM3LCJpc3MiOiJqdXN0LWFjY291bnRAdGVzdGFwaWFuZHNoZWV0cy5pYW0uZ3NlcnZpY2VhY2NvdW50LmNvbSJ9', b'O4pRrllkglg9A1Ejxlo2J0pa0bVOqXmACc2vmB5uybHXYlrghauGNnUNKSqLxq9Xc2e4T1O9kjYQH7CxhVlGKDbSlwFHclxmtYSFZVnEHaLyf5lV50Kx9NxYPxfPVHo55kQSk3PARPmQeEwqNf1mXpqrrhQpoz5T763jOO2jbAOFKhLkX6bzkcea2QGZdgZ0VTwA2a0Nj386nfoxhRQqNYL5PfFFR09uNsc-BxN5dTR5iUw2zR3dm6o1Fwyom2K6UyX-qNyNyXxvNvsIjjBbz7K74Jklmz3zYh0JZl6lwFqmGlgWeUtdTq1cY_JPmd3ATYz9v2rjxhLFKasjrjWbgQ']
INFO:oauth2client.client:Refreshing access_token
DEBUG:googleapiclient.discovery:URL being requested: POST https://www.googleapis.com/upload/drive/v3/files?fields=id&alt=json&uploadType=multipart
WARNING:googleapiclient.discovery_cache:file_cache is unavailable when using oauth2client >= 4.0.0 or google-auth
Traceback (most recent call last):
  File "C:\Users\79069\AppData\Local\Programs\Python\Python39\lib\site-packages\googleapiclient\discovery_cache\file_cache.py", line 33, in <module>
    from oauth2client.contrib.locked_file import LockedFile
ModuleNotFoundError: No module named 'oauth2client.contrib.locked_file'

During handling of the above exception, another exception occurred:

Traceback (most recent call last):
  File "C:\Users\79069\AppData\Local\Programs\Python\Python39\lib\site-packages\googleapiclient\discovery_cache\file_cache.py", line 37, in <module>
    from oauth2client.locked_file import LockedFile
ModuleNotFoundError: No module named 'oauth2client.locked_file'

During handling of the above exception, another exception occurred:

Traceback (most recent call last):
  File "C:\Users\79069\AppData\Local\Programs\Python\Python39\lib\site-packages\googleapiclient\discovery_cache\__init__.py", line 44, in autodetect
    from . import file_cache
  File "C:\Users\79069\AppData\Local\Programs\Python\Python39\lib\site-packages\googleapiclient\discovery_cache\file_cache.py", line 40, in <module>
    raise ImportError(
ImportError: file_cache is unavailable when using oauth2client >= 4.0.0 or google-auth
DEBUG:googleapiclient.discovery:URL being requested: GET https://www.googleapis.com/discovery/v1/apis/drive/v3/rest
INFO:oauth2client.transport:Attempting refresh to obtain initial access_token
DEBUG:oauth2client.crypt:[b'eyJ0eXAiOiJKV1QiLCJhbGciOiJSUzI1NiIsImtpZCI6IjZiYzEzYmFjOTE0ZGZkNzliN2ZhOWQyODYxMzk5YzljZmY4OWFjNjcifQ', b'eyJhdWQiOiJodHRwczovL29hdXRoMi5nb29nbGVhcGlzLmNvbS90b2tlbiIsInNjb3BlIjoiaHR0cHM6Ly93d3cuZ29vZ2xlYXBpcy5jb20vYXV0aC9kcml2ZSIsImlhdCI6MTYxMzY1MTQzNCwiZXhwIjoxNjEzNjU1MDM0LCJpc3MiOiJqdXN0LWFjY291bnRAdGVzdGFwaWFuZHNoZWV0cy5pYW0uZ3NlcnZpY2VhY2NvdW50LmNvbSJ9', b'1JFnPcAXYBzks6rLW35EKob_3z43cSnu9L2hM2XSviYCFADNJokQGoqNXwUybhSGgY01IAhukET3Pe5v_zkTpiHm6M5L7SQJdlr5GWB9BPMnN1kWudZqDfPi5YTbBAtgPADmPFDi4XQo1WZf1tiV8STsPb1MX-aA6XJX5jbqWHuaehX59-yOvB_v5IXGs0uX7m1i9g0BbfXg0ghc30GhORNmUPa80chkuIa6jz062M2saEDZ9DuZvV3ojHgVAYXSKkuERi53GEnyNokXwLnXiP9rx38PEw3Ql32WhXU7xswU9libRwIowFCH81PduMvusVRAxV-3s8YYQLwt2--Uaw']
INFO:oauth2client.client:Refreshing access_token
DEBUG:googleapiclient.discovery:URL being requested: GET https://www.googleapis.com/drive/v3/files/12xpxsV0IhJT0mPqxdO9dzsMjONwI7EcW?alt=media
WARNING:googleapiclient.discovery_cache:file_cache is unavailable when using oauth2client >= 4.0.0 or google-auth
Traceback (most recent call last):
  File "C:\Users\79069\AppData\Local\Programs\Python\Python39\lib\site-packages\googleapiclient\discovery_cache\file_cache.py", line 33, in <module>
    from oauth2client.contrib.locked_file import LockedFile
ModuleNotFoundError: No module named 'oauth2client.contrib.locked_file'

During handling of the above exception, another exception occurred:

Traceback (most recent call last):
  File "C:\Users\79069\AppData\Local\Programs\Python\Python39\lib\site-packages\googleapiclient\discovery_cache\file_cache.py", line 37, in <module>
    from oauth2client.locked_file import LockedFile
ModuleNotFoundError: No module named 'oauth2client.locked_file'

During handling of the above exception, another exception occurred:

Traceback (most recent call last):
  File "C:\Users\79069\AppData\Local\Programs\Python\Python39\lib\site-packages\googleapiclient\discovery_cache\__init__.py", line 44, in autodetect
    from . import file_cache
  File "C:\Users\79069\AppData\Local\Programs\Python\Python39\lib\site-packages\googleapiclient\discovery_cache\file_cache.py", line 40, in <module>
    raise ImportError(
ImportError: file_cache is unavailable when using oauth2client >= 4.0.0 or google-auth
DEBUG:googleapiclient.discovery:URL being requested: GET https://www.googleapis.com/discovery/v1/apis/drive/v3/rest
INFO:oauth2client.transport:Attempting refresh to obtain initial access_token
DEBUG:oauth2client.crypt:[b'eyJ0eXAiOiJKV1QiLCJhbGciOiJSUzI1NiIsImtpZCI6IjZiYzEzYmFjOTE0ZGZkNzliN2ZhOWQyODYxMzk5YzljZmY4OWFjNjcifQ', b'eyJhdWQiOiJodHRwczovL29hdXRoMi5nb29nbGVhcGlzLmNvbS90b2tlbiIsInNjb3BlIjoiaHR0cHM6Ly93d3cuZ29vZ2xlYXBpcy5jb20vYXV0aC9kcml2ZSIsImlhdCI6MTYxMzY1MTQ0NSwiZXhwIjoxNjEzNjU1MDQ1LCJpc3MiOiJqdXN0LWFjY291bnRAdGVzdGFwaWFuZHNoZWV0cy5pYW0uZ3NlcnZpY2VhY2NvdW50LmNvbSJ9', b'JSbJG0YJaxHDyfP3pJjgUhSNAmDIPGT1rvV94vvCG-2q-PYnVpOMHmNbY3mxECA9EKOV0NZtxGjsB45DogDYslYqT3cO3tm9FnBt3hr2FBvLC1QsASrESbazVgMJM6g2is-nFxYP0GN8mQwXuU_qFp8JBmhMuKTNfu4nk9qfzVt-O2sLzDN6GsvHrrN7YIoz92OUCwvQrWZsmhxxOg-sUdscj-Fda-2oPYYhZ6J9WCyVMYTo2F2HguzDD7fnPYjwARqCrmc_fJ_Rf2QRiD63HWXLTa1MV5F6Kpt2Bp70yAIiwkhxWAi3xThxb9pRzfzfgYX7GjnFlBGKHomyy1_j3Q']
INFO:oauth2client.client:Refreshing access_token
DEBUG:googleapiclient.discovery:URL being requested: POST https://www.googleapis.com/upload/drive/v3/files?fields=id&alt=json&uploadType=multipart
WARNING:googleapiclient.discovery_cache:file_cache is unavailable when using oauth2client >= 4.0.0 or google-auth
Traceback (most recent call last):
  File "C:\Users\79069\AppData\Local\Programs\Python\Python39\lib\site-packages\googleapiclient\discovery_cache\file_cache.py", line 33, in <module>
    from oauth2client.contrib.locked_file import LockedFile
ModuleNotFoundError: No module named 'oauth2client.contrib.locked_file'

During handling of the above exception, another exception occurred:

Traceback (most recent call last):
  File "C:\Users\79069\AppData\Local\Programs\Python\Python39\lib\site-packages\googleapiclient\discovery_cache\file_cache.py", line 37, in <module>
    from oauth2client.locked_file import LockedFile
ModuleNotFoundError: No module named 'oauth2client.locked_file'

During handling of the above exception, another exception occurred:

Traceback (most recent call last):
  File "C:\Users\79069\AppData\Local\Programs\Python\Python39\lib\site-packages\googleapiclient\discovery_cache\__init__.py", line 44, in autodetect
    from . import file_cache
  File "C:\Users\79069\AppData\Local\Programs\Python\Python39\lib\site-packages\googleapiclient\discovery_cache\file_cache.py", line 40, in <module>
    raise ImportError(
ImportError: file_cache is unavailable when using oauth2client >= 4.0.0 or google-auth
DEBUG:googleapiclient.discovery:URL being requested: GET https://www.googleapis.com/discovery/v1/apis/drive/v3/rest
INFO:oauth2client.transport:Attempting refresh to obtain initial access_token
DEBUG:oauth2client.crypt:[b'eyJ0eXAiOiJKV1QiLCJhbGciOiJSUzI1NiIsImtpZCI6IjZiYzEzYmFjOTE0ZGZkNzliN2ZhOWQyODYxMzk5YzljZmY4OWFjNjcifQ', b'eyJhdWQiOiJodHRwczovL29hdXRoMi5nb29nbGVhcGlzLmNvbS90b2tlbiIsInNjb3BlIjoiaHR0cHM6Ly93d3cuZ29vZ2xlYXBpcy5jb20vYXV0aC9kcml2ZSIsImlhdCI6MTYxMzY1MTU4NSwiZXhwIjoxNjEzNjU1MTg1LCJpc3MiOiJqdXN0LWFjY291bnRAdGVzdGFwaWFuZHNoZWV0cy5pYW0uZ3NlcnZpY2VhY2NvdW50LmNvbSJ9', b'1qtMUPYmZQGs2n4i6J9uzsxMBANwQOaD2IKRF2ckKFYorx75FVLnwbuTf46aWgliDIzxe0o_ZKuxL0jwq2idaBrO9g7YDHT-Atz9NKxAlt1nefFSJFY5Xy-tJNvok9z_T0rpuzBnNMa3QX7nn4MzXMpXKtWguZng4dzRXHgvagSKKdxJfOiFDZ0Ft4_IboBmsM64lv1GaMjEe-zE7PeVIjpt0QFKubjBfU4N0_RNSrLNuCkYa-I88fLkHW9VW--Yft5Cvt5z4wQrXo7J2w1d0fWwbao6Z2iNgX85OHSQuXKAIeBvuZxp7sVsGWvtWw9y63TV73JmsJzgjWOF2V9YcQ']
INFO:oauth2client.client:Refreshing access_token
DEBUG:googleapiclient.discovery:URL being requested: GET https://www.googleapis.com/drive/v3/files/12xpxsV0IhJT0mPqxdO9dzsMjONwI7EcW?alt=media
WARNING:googleapiclient.discovery_cache:file_cache is unavailable when using oauth2client >= 4.0.0 or google-auth
Traceback (most recent call last):
  File "C:\Users\79069\AppData\Local\Programs\Python\Python39\lib\site-packages\googleapiclient\discovery_cache\file_cache.py", line 33, in <module>
    from oauth2client.contrib.locked_file import LockedFile
ModuleNotFoundError: No module named 'oauth2client.contrib.locked_file'

During handling of the above exception, another exception occurred:

Traceback (most recent call last):
  File "C:\Users\79069\AppData\Local\Programs\Python\Python39\lib\site-packages\googleapiclient\discovery_cache\file_cache.py", line 37, in <module>
    from oauth2client.locked_file import LockedFile
ModuleNotFoundError: No module named 'oauth2client.locked_file'

During handling of the above exception, another exception occurred:

Traceback (most recent call last):
  File "C:\Users\79069\AppData\Local\Programs\Python\Python39\lib\site-packages\googleapiclient\discovery_cache\__init__.py", line 44, in autodetect
    from . import file_cache
  File "C:\Users\79069\AppData\Local\Programs\Python\Python39\lib\site-packages\googleapiclient\discovery_cache\file_cache.py", line 40, in <module>
    raise ImportError(
ImportError: file_cache is unavailable when using oauth2client >= 4.0.0 or google-auth
DEBUG:googleapiclient.discovery:URL being requested: GET https://www.googleapis.com/discovery/v1/apis/drive/v3/rest
INFO:oauth2client.transport:Attempting refresh to obtain initial access_token
DEBUG:oauth2client.crypt:[b'eyJ0eXAiOiJKV1QiLCJhbGciOiJSUzI1NiIsImtpZCI6IjZiYzEzYmFjOTE0ZGZkNzliN2ZhOWQyODYxMzk5YzljZmY4OWFjNjcifQ', b'eyJhdWQiOiJodHRwczovL29hdXRoMi5nb29nbGVhcGlzLmNvbS90b2tlbiIsInNjb3BlIjoiaHR0cHM6Ly93d3cuZ29vZ2xlYXBpcy5jb20vYXV0aC9kcml2ZSIsImlhdCI6MTYxMzY1MTU5MywiZXhwIjoxNjEzNjU1MTkzLCJpc3MiOiJqdXN0LWFjY291bnRAdGVzdGFwaWFuZHNoZWV0cy5pYW0uZ3NlcnZpY2VhY2NvdW50LmNvbSJ9', b'EbNvdTZBPbQFWM6F2HEFZhl99FXDYuRoohkiOSKi7_it1ZQgVVS4eWVATKM7t7Hb5Dj02wrXQrxJUyTjrawFRaY5vf3A9qTmXKqfESHHzckFhM0F8cZSwNNlCLq0c3CDq2lKAqccSXYUb0zN3tfOzSzuZnDISKf9RgxCI5tA3RIYu8SgeU2h2kxB7VpJKZ9LWwDETWh3V9qzSIk2ega8glRcOOPdnENttU4_N3LYLz0jecSE95M-N52Da0BnmJw_vNBKJm58yAovUa7oysi6i-YtUql0ObN_9aekrkIk6CtQ_wbOGf5s1MIgH5cgZ8rkKLoyl5uB8P_fV-T9a75nBg']
INFO:oauth2client.client:Refreshing access_token
DEBUG:googleapiclient.discovery:URL being requested: POST https://www.googleapis.com/upload/drive/v3/files?fields=id&alt=json&uploadType=multipart
WARNING:googleapiclient.discovery_cache:file_cache is unavailable when using oauth2client >= 4.0.0 or google-auth
Traceback (most recent call last):
  File "C:\Users\79069\AppData\Local\Programs\Python\Python39\lib\site-packages\googleapiclient\discovery_cache\file_cache.py", line 33, in <module>
    from oauth2client.contrib.locked_file import LockedFile
ModuleNotFoundError: No module named 'oauth2client.contrib.locked_file'

During handling of the above exception, another exception occurred:

Traceback (most recent call last):
  File "C:\Users\79069\AppData\Local\Programs\Python\Python39\lib\site-packages\googleapiclient\discovery_cache\file_cache.py", line 37, in <module>
    from oauth2client.locked_file import LockedFile
ModuleNotFoundError: No module named 'oauth2client.locked_file'

During handling of the above exception, another exception occurred:

Traceback (most recent call last):
  File "C:\Users\79069\AppData\Local\Programs\Python\Python39\lib\site-packages\googleapiclient\discovery_cache\__init__.py", line 44, in autodetect
    from . import file_cache
  File "C:\Users\79069\AppData\Local\Programs\Python\Python39\lib\site-packages\googleapiclient\discovery_cache\file_cache.py", line 40, in <module>
    raise ImportError(
ImportError: file_cache is unavailable when using oauth2client >= 4.0.0 or google-auth
DEBUG:googleapiclient.discovery:URL being requested: GET https://www.googleapis.com/discovery/v1/apis/drive/v3/rest
INFO:oauth2client.transport:Attempting refresh to obtain initial access_token
DEBUG:oauth2client.crypt:[b'eyJ0eXAiOiJKV1QiLCJhbGciOiJSUzI1NiIsImtpZCI6IjZiYzEzYmFjOTE0ZGZkNzliN2ZhOWQyODYxMzk5YzljZmY4OWFjNjcifQ', b'eyJhdWQiOiJodHRwczovL29hdXRoMi5nb29nbGVhcGlzLmNvbS90b2tlbiIsInNjb3BlIjoiaHR0cHM6Ly93d3cuZ29vZ2xlYXBpcy5jb20vYXV0aC9kcml2ZSIsImlhdCI6MTYxMzY1MTcwMCwiZXhwIjoxNjEzNjU1MzAwLCJpc3MiOiJqdXN0LWFjY291bnRAdGVzdGFwaWFuZHNoZWV0cy5pYW0uZ3NlcnZpY2VhY2NvdW50LmNvbSJ9', b'7FdVxgh6wxlryhZh_q0TaB_J4xaccw85WcYLq5l8Q4EjL1M_v5b5RLDgiuaNNmDwCaYu295atIbJt1RReNKPsDUbc3pw4Y1FUK8yZLC6fsAbYBEn-3FAAiTwwUaq21OZG1zKg9JWDViPP_bOga_9BbEwMvL6gOjCREM7fiQq8sYdqX4ZIj1VdJE0Ef4r9oDdc53ctSQFcv7ZsJOVSMs3ngImSSxBXnsMQwvh7lj8Bn41BvgyaXkYiYfQoDxNiGCgQy9-R233LSHqcrVWMuALQoRBWssrrDVfI0rSo_Kj0OzmiVxxcIPoRYlfp1u7qeh7ley_NHmt-y96EGtvKg73bA']
INFO:oauth2client.client:Refreshing access_token
DEBUG:googleapiclient.discovery:URL being requested: GET https://www.googleapis.com/drive/v3/files/12xpxsV0IhJT0mPqxdO9dzsMjONwI7EcW?alt=media
WARNING:googleapiclient.discovery_cache:file_cache is unavailable when using oauth2client >= 4.0.0 or google-auth
Traceback (most recent call last):
  File "C:\Users\79069\AppData\Local\Programs\Python\Python39\lib\site-packages\googleapiclient\discovery_cache\file_cache.py", line 33, in <module>
    from oauth2client.contrib.locked_file import LockedFile
ModuleNotFoundError: No module named 'oauth2client.contrib.locked_file'

During handling of the above exception, another exception occurred:

Traceback (most recent call last):
  File "C:\Users\79069\AppData\Local\Programs\Python\Python39\lib\site-packages\googleapiclient\discovery_cache\file_cache.py", line 37, in <module>
    from oauth2client.locked_file import LockedFile
ModuleNotFoundError: No module named 'oauth2client.locked_file'

During handling of the above exception, another exception occurred:

Traceback (most recent call last):
  File "C:\Users\79069\AppData\Local\Programs\Python\Python39\lib\site-packages\googleapiclient\discovery_cache\__init__.py", line 44, in autodetect
    from . import file_cache
  File "C:\Users\79069\AppData\Local\Programs\Python\Python39\lib\site-packages\googleapiclient\discovery_cache\file_cache.py", line 40, in <module>
    raise ImportError(
ImportError: file_cache is unavailable when using oauth2client >= 4.0.0 or google-auth
DEBUG:googleapiclient.discovery:URL being requested: GET https://www.googleapis.com/discovery/v1/apis/drive/v3/rest
INFO:oauth2client.transport:Attempting refresh to obtain initial access_token
DEBUG:oauth2client.crypt:[b'eyJ0eXAiOiJKV1QiLCJhbGciOiJSUzI1NiIsImtpZCI6IjZiYzEzYmFjOTE0ZGZkNzliN2ZhOWQyODYxMzk5YzljZmY4OWFjNjcifQ', b'eyJhdWQiOiJodHRwczovL29hdXRoMi5nb29nbGVhcGlzLmNvbS90b2tlbiIsInNjb3BlIjoiaHR0cHM6Ly93d3cuZ29vZ2xlYXBpcy5jb20vYXV0aC9kcml2ZSIsImlhdCI6MTYxMzY1MTcxOSwiZXhwIjoxNjEzNjU1MzE5LCJpc3MiOiJqdXN0LWFjY291bnRAdGVzdGFwaWFuZHNoZWV0cy5pYW0uZ3NlcnZpY2VhY2NvdW50LmNvbSJ9', b'ljO-DDzxI09UbpPjqigbvP6TjxnwYEyqFNszzfOuZMmNwjGOyuk93P62IYE9gzRMEINPR2acTPb0uvtbCi4z1M8ddvXr3uy4z3Ae0lpsw1f0qvKL2Z6J0_tI8yxi--NvY4OzqlDOQLi0O4GAFxPjoF6WpaoHLlbfta6CISoq46Q82LifMTsLgpfbyTAw8DzJVEsjNldt-xXksb1H-_ym-gWIGHT0EOakTfHJpjaK4YVDWDyd9drRp0g5bWDdxe-TFqjmzK3If9JxhyufODV8Z1rj8cTg64ORXwMiTQn7UlfPRr5UoGYaccKD7_qNbV3cDNR_S805SRPrHEi_0ocQTw']
INFO:oauth2client.client:Refreshing access_token
DEBUG:googleapiclient.discovery:URL being requested: POST https://www.googleapis.com/upload/drive/v3/files?fields=id&alt=json&uploadType=multipart
WARNING:googleapiclient.discovery_cache:file_cache is unavailable when using oauth2client >= 4.0.0 or google-auth
Traceback (most recent call last):
  File "C:\Users\79069\AppData\Local\Programs\Python\Python39\lib\site-packages\googleapiclient\discovery_cache\file_cache.py", line 33, in <module>
    from oauth2client.contrib.locked_file import LockedFile
ModuleNotFoundError: No module named 'oauth2client.contrib.locked_file'

During handling of the above exception, another exception occurred:

Traceback (most recent call last):
  File "C:\Users\79069\AppData\Local\Programs\Python\Python39\lib\site-packages\googleapiclient\discovery_cache\file_cache.py", line 37, in <module>
    from oauth2client.locked_file import LockedFile
ModuleNotFoundError: No module named 'oauth2client.locked_file'

During handling of the above exception, another exception occurred:

Traceback (most recent call last):
  File "C:\Users\79069\AppData\Local\Programs\Python\Python39\lib\site-packages\googleapiclient\discovery_cache\__init__.py", line 44, in autodetect
    from . import file_cache
  File "C:\Users\79069\AppData\Local\Programs\Python\Python39\lib\site-packages\googleapiclient\discovery_cache\file_cache.py", line 40, in <module>
    raise ImportError(
ImportError: file_cache is unavailable when using oauth2client >= 4.0.0 or google-auth
DEBUG:googleapiclient.discovery:URL being requested: GET https://www.googleapis.com/discovery/v1/apis/drive/v3/rest
INFO:oauth2client.transport:Attempting refresh to obtain initial access_token
DEBUG:oauth2client.crypt:[b'eyJ0eXAiOiJKV1QiLCJhbGciOiJSUzI1NiIsImtpZCI6IjZiYzEzYmFjOTE0ZGZkNzliN2ZhOWQyODYxMzk5YzljZmY4OWFjNjcifQ', b'eyJhdWQiOiJodHRwczovL29hdXRoMi5nb29nbGVhcGlzLmNvbS90b2tlbiIsInNjb3BlIjoiaHR0cHM6Ly93d3cuZ29vZ2xlYXBpcy5jb20vYXV0aC9kcml2ZSIsImlhdCI6MTYxMzY1MTg5NywiZXhwIjoxNjEzNjU1NDk3LCJpc3MiOiJqdXN0LWFjY291bnRAdGVzdGFwaWFuZHNoZWV0cy5pYW0uZ3NlcnZpY2VhY2NvdW50LmNvbSJ9', b'CzEedHMyHBRex6ID53HipAg5w3fgnfFt4Tn9UZuU3goYxJHHnYoRfZZq8jXKjnI1mzyo-yXpTpIBD-nI3PcsJmVuJ2z0z8cDWjprtpTfVHDYoPO2uj1igSP5dsX0JUhEpwFpDjmWDyf-nKGAZr4X8l8d46RGtxybvl3RcnVEwrDc0hfb0ICBTIA-Nn7GNj6F1FzUHl5RnXvaeKDhKJkovUTan6bDiUk812ZQ7d9hVhcHhThjPta7DSlRMbkfVWn-bWSm_0lMs0NCIRYDr6CSFCmfwedZ2wIwG5F-l1vYnkVSi7OSZE1XYKnK0eCK8oSwz11KnryVgYXS_APvStdtSg']
INFO:oauth2client.client:Refreshing access_token
DEBUG:googleapiclient.discovery:URL being requested: GET https://www.googleapis.com/drive/v3/files/12xpxsV0IhJT0mPqxdO9dzsMjONwI7EcW?alt=media
WARNING:googleapiclient.discovery_cache:file_cache is unavailable when using oauth2client >= 4.0.0 or google-auth
Traceback (most recent call last):
  File "C:\Users\79069\AppData\Local\Programs\Python\Python39\lib\site-packages\googleapiclient\discovery_cache\file_cache.py", line 33, in <module>
    from oauth2client.contrib.locked_file import LockedFile
ModuleNotFoundError: No module named 'oauth2client.contrib.locked_file'

During handling of the above exception, another exception occurred:

Traceback (most recent call last):
  File "C:\Users\79069\AppData\Local\Programs\Python\Python39\lib\site-packages\googleapiclient\discovery_cache\file_cache.py", line 37, in <module>
    from oauth2client.locked_file import LockedFile
ModuleNotFoundError: No module named 'oauth2client.locked_file'

During handling of the above exception, another exception occurred:

Traceback (most recent call last):
  File "C:\Users\79069\AppData\Local\Programs\Python\Python39\lib\site-packages\googleapiclient\discovery_cache\__init__.py", line 44, in autodetect
    from . import file_cache
  File "C:\Users\79069\AppData\Local\Programs\Python\Python39\lib\site-packages\googleapiclient\discovery_cache\file_cache.py", line 40, in <module>
    raise ImportError(
ImportError: file_cache is unavailable when using oauth2client >= 4.0.0 or google-auth
DEBUG:googleapiclient.discovery:URL being requested: GET https://www.googleapis.com/discovery/v1/apis/drive/v3/rest
INFO:oauth2client.transport:Attempting refresh to obtain initial access_token
DEBUG:oauth2client.crypt:[b'eyJ0eXAiOiJKV1QiLCJhbGciOiJSUzI1NiIsImtpZCI6IjZiYzEzYmFjOTE0ZGZkNzliN2ZhOWQyODYxMzk5YzljZmY4OWFjNjcifQ', b'eyJhdWQiOiJodHRwczovL29hdXRoMi5nb29nbGVhcGlzLmNvbS90b2tlbiIsInNjb3BlIjoiaHR0cHM6Ly93d3cuZ29vZ2xlYXBpcy5jb20vYXV0aC9kcml2ZSIsImlhdCI6MTYxMzY1MjAxOSwiZXhwIjoxNjEzNjU1NjE5LCJpc3MiOiJqdXN0LWFjY291bnRAdGVzdGFwaWFuZHNoZWV0cy5pYW0uZ3NlcnZpY2VhY2NvdW50LmNvbSJ9', b'C7Zz1pbJz4tmGj6yG23A8O5Qnnd3ncaveaVYcwlsiUxvq0l-pIxvXaX9jVtp783Vsyt7oX25JZ4ZZ34oLh248RaEnwZ3Bqm9iWF3JlbM3KqpBoLRULkh10QP4wDK4r-hJWvaN8MYP3gA1OoL3wHGhjqYMwZT3bkLWN9ps7MVu42ThVrOdbj_wvC0pSOdW2a8QCL1YX7QU7MxinSBhqvRlMswoAvXKeFdGWp7htJqaamsVIp4nIS7JIwhmRGFUEr8PLveTG2AT1xFksdzczxfh_kxcpsWsv6VCxL5WcJ5y5AGUJGSiBWH3oJgCK6h83_2wAJwVyUWl-G_EnpBONd5gQ']
INFO:oauth2client.client:Refreshing access_token
DEBUG:googleapiclient.discovery:URL being requested: POST https://www.googleapis.com/upload/drive/v3/files?fields=id&alt=json&uploadType=multipart
WARNING:googleapiclient.discovery_cache:file_cache is unavailable when using oauth2client >= 4.0.0 or google-auth
Traceback (most recent call last):
  File "C:\Users\79069\AppData\Local\Programs\Python\Python39\lib\site-packages\googleapiclient\discovery_cache\file_cache.py", line 33, in <module>
    from oauth2client.contrib.locked_file import LockedFile
ModuleNotFoundError: No module named 'oauth2client.contrib.locked_file'

During handling of the above exception, another exception occurred:

Traceback (most recent call last):
  File "C:\Users\79069\AppData\Local\Programs\Python\Python39\lib\site-packages\googleapiclient\discovery_cache\file_cache.py", line 37, in <module>
    from oauth2client.locked_file import LockedFile
ModuleNotFoundError: No module named 'oauth2client.locked_file'

During handling of the above exception, another exception occurred:

Traceback (most recent call last):
  File "C:\Users\79069\AppData\Local\Programs\Python\Python39\lib\site-packages\googleapiclient\discovery_cache\__init__.py", line 44, in autodetect
    from . import file_cache
  File "C:\Users\79069\AppData\Local\Programs\Python\Python39\lib\site-packages\googleapiclient\discovery_cache\file_cache.py", line 40, in <module>
    raise ImportError(
ImportError: file_cache is unavailable when using oauth2client >= 4.0.0 or google-auth
DEBUG:googleapiclient.discovery:URL being requested: GET https://www.googleapis.com/discovery/v1/apis/drive/v3/rest
INFO:oauth2client.transport:Attempting refresh to obtain initial access_token
DEBUG:oauth2client.crypt:[b'eyJ0eXAiOiJKV1QiLCJhbGciOiJSUzI1NiIsImtpZCI6IjZiYzEzYmFjOTE0ZGZkNzliN2ZhOWQyODYxMzk5YzljZmY4OWFjNjcifQ', b'eyJhdWQiOiJodHRwczovL29hdXRoMi5nb29nbGVhcGlzLmNvbS90b2tlbiIsInNjb3BlIjoiaHR0cHM6Ly93d3cuZ29vZ2xlYXBpcy5jb20vYXV0aC9kcml2ZSIsImlhdCI6MTYxMzY1MjA5OCwiZXhwIjoxNjEzNjU1Njk4LCJpc3MiOiJqdXN0LWFjY291bnRAdGVzdGFwaWFuZHNoZWV0cy5pYW0uZ3NlcnZpY2VhY2NvdW50LmNvbSJ9', b'69kpTas1R-x-4m9NDpzvfRpCgXv87jseyY_k_uId7JXHtSHbNEyA5nfDErhlFx_ln3WPsOXv8IkOVYXL1OaXqh86EpSa1cwDl4yzgv9ZKHM9oQ6m1pBSygR1BpcNMgnvr0t1HlrIsTIJwaO8L6Ku30VDhugsxmmL9qhRxs23CUhOXIyHeeZBuZBtXedZVqNfaz0GclrlgoTaFwD4_4uBcz0fR58K8qXAQI0o2S0_9iotwGlOpUhS7k0nD-nQZqxwZR35svjQ006GL3d-Gx8-5FB4wXPmo1W18AYb7mJ-10DCER2Ox_DlwMvmK-D3iLNxTb7j9ne_zFndU22N9VQEIg']
INFO:oauth2client.client:Refreshing access_token
DEBUG:googleapiclient.discovery:URL being requested: GET https://www.googleapis.com/drive/v3/files/12xpxsV0IhJT0mPqxdO9dzsMjONwI7EcW?alt=media
WARNING:googleapiclient.discovery_cache:file_cache is unavailable when using oauth2client >= 4.0.0 or google-auth
Traceback (most recent call last):
  File "C:\Users\79069\AppData\Local\Programs\Python\Python39\lib\site-packages\googleapiclient\discovery_cache\file_cache.py", line 33, in <module>
    from oauth2client.contrib.locked_file import LockedFile
ModuleNotFoundError: No module named 'oauth2client.contrib.locked_file'

During handling of the above exception, another exception occurred:

Traceback (most recent call last):
  File "C:\Users\79069\AppData\Local\Programs\Python\Python39\lib\site-packages\googleapiclient\discovery_cache\file_cache.py", line 37, in <module>
    from oauth2client.locked_file import LockedFile
ModuleNotFoundError: No module named 'oauth2client.locked_file'

During handling of the above exception, another exception occurred:

Traceback (most recent call last):
  File "C:\Users\79069\AppData\Local\Programs\Python\Python39\lib\site-packages\googleapiclient\discovery_cache\__init__.py", line 44, in autodetect
    from . import file_cache
  File "C:\Users\79069\AppData\Local\Programs\Python\Python39\lib\site-packages\googleapiclient\discovery_cache\file_cache.py", line 40, in <module>
    raise ImportError(
ImportError: file_cache is unavailable when using oauth2client >= 4.0.0 or google-auth
DEBUG:googleapiclient.discovery:URL being requested: GET https://www.googleapis.com/discovery/v1/apis/drive/v3/rest
INFO:oauth2client.transport:Attempting refresh to obtain initial access_token
DEBUG:oauth2client.crypt:[b'eyJ0eXAiOiJKV1QiLCJhbGciOiJSUzI1NiIsImtpZCI6IjZiYzEzYmFjOTE0ZGZkNzliN2ZhOWQyODYxMzk5YzljZmY4OWFjNjcifQ', b'eyJhdWQiOiJodHRwczovL29hdXRoMi5nb29nbGVhcGlzLmNvbS90b2tlbiIsInNjb3BlIjoiaHR0cHM6Ly93d3cuZ29vZ2xlYXBpcy5jb20vYXV0aC9kcml2ZSIsImlhdCI6MTYxMzY1MjExMiwiZXhwIjoxNjEzNjU1NzEyLCJpc3MiOiJqdXN0LWFjY291bnRAdGVzdGFwaWFuZHNoZWV0cy5pYW0uZ3NlcnZpY2VhY2NvdW50LmNvbSJ9', b'7isCdqVdmlR-ARiJPrx81dRVW64MQ0ytETBRFTTI5C1TzzrVMAkKwA7iBEjjuE9V26wHGFiJeqDqzksZBLHzFVlU08LHw6apbr1GAo0iWUk2Cc2lJvhfF0DMNECWlvsbcyR58Q4hcGfN4QnqrAZ3NaCnRK6hqW5VBlmjiyBOrr7KgzstDzTNyN_c2hbjWbYjt_bMiTQPnOZoTsakCJljvYU8w9NoUSJC3ixiHMLZs_qvR9ob-Wv4ocdmQC_MY8JbKPFxethKLx7MkpREjYSeo9hGhlXsSSalEp3SDjhy6YjHZrFJ3J7dkEZfq72-Kmf9UVDjFGpjYZpYeBmYH2yifQ']
INFO:oauth2client.client:Refreshing access_token
DEBUG:googleapiclient.discovery:URL being requested: POST https://www.googleapis.com/upload/drive/v3/files?fields=id&alt=json&uploadType=multipart
WARNING:googleapiclient.discovery_cache:file_cache is unavailable when using oauth2client >= 4.0.0 or google-auth
Traceback (most recent call last):
  File "C:\Users\79069\AppData\Local\Programs\Python\Python39\lib\site-packages\googleapiclient\discovery_cache\file_cache.py", line 33, in <module>
    from oauth2client.contrib.locked_file import LockedFile
ModuleNotFoundError: No module named 'oauth2client.contrib.locked_file'

During handling of the above exception, another exception occurred:

Traceback (most recent call last):
  File "C:\Users\79069\AppData\Local\Programs\Python\Python39\lib\site-packages\googleapiclient\discovery_cache\file_cache.py", line 37, in <module>
    from oauth2client.locked_file import LockedFile
ModuleNotFoundError: No module named 'oauth2client.locked_file'

During handling of the above exception, another exception occurred:

Traceback (most recent call last):
  File "C:\Users\79069\AppData\Local\Programs\Python\Python39\lib\site-packages\googleapiclient\discovery_cache\__init__.py", line 44, in autodetect
    from . import file_cache
  File "C:\Users\79069\AppData\Local\Programs\Python\Python39\lib\site-packages\googleapiclient\discovery_cache\file_cache.py", line 40, in <module>
    raise ImportError(
ImportError: file_cache is unavailable when using oauth2client >= 4.0.0 or google-auth
DEBUG:googleapiclient.discovery:URL being requested: GET https://www.googleapis.com/discovery/v1/apis/drive/v3/rest
INFO:oauth2client.transport:Attempting refresh to obtain initial access_token
DEBUG:oauth2client.crypt:[b'eyJ0eXAiOiJKV1QiLCJhbGciOiJSUzI1NiIsImtpZCI6IjZiYzEzYmFjOTE0ZGZkNzliN2ZhOWQyODYxMzk5YzljZmY4OWFjNjcifQ', b'eyJhdWQiOiJodHRwczovL29hdXRoMi5nb29nbGVhcGlzLmNvbS90b2tlbiIsInNjb3BlIjoiaHR0cHM6Ly93d3cuZ29vZ2xlYXBpcy5jb20vYXV0aC9kcml2ZSIsImlhdCI6MTYxMzY1MjEzOCwiZXhwIjoxNjEzNjU1NzM4LCJpc3MiOiJqdXN0LWFjY291bnRAdGVzdGFwaWFuZHNoZWV0cy5pYW0uZ3NlcnZpY2VhY2NvdW50LmNvbSJ9', b'MYJs9CTBGjmsCBurk67VyF77uumrNS_HKqbKxFHkepwBJjmiVp7hr3eF56xdkFkYrULOorVifHEJ3JcJYQQWat8LsRIT1HpLdTp_4mQPcojUsZIs66BO1QpZogiTKP6qMR2lUaoC3pPosVRIejNYJjrPL9GLh8Q10xB6d-4jUu0ck5GhWBrbmzwdLtvAt6p7BO60PBwwXPehrdDiH0tqPZFO8JsNkwwICagAGP26vDS55lYbvUSPm85yuU9gcoPsCgbZb4VXVgl1BxUAvFvlMvKnZOBASy-cxqJLIw6a7KX5LecqX3quBQTxWz-NAWmkmFiQV6Z59gYnnpzIpRDI7w']
INFO:oauth2client.client:Refreshing access_token
DEBUG:googleapiclient.discovery:URL being requested: GET https://www.googleapis.com/drive/v3/files/12xpxsV0IhJT0mPqxdO9dzsMjONwI7EcW?alt=media
WARNING:googleapiclient.discovery_cache:file_cache is unavailable when using oauth2client >= 4.0.0 or google-auth
Traceback (most recent call last):
  File "C:\Users\79069\AppData\Local\Programs\Python\Python39\lib\site-packages\googleapiclient\discovery_cache\file_cache.py", line 33, in <module>
    from oauth2client.contrib.locked_file import LockedFile
ModuleNotFoundError: No module named 'oauth2client.contrib.locked_file'

During handling of the above exception, another exception occurred:

Traceback (most recent call last):
  File "C:\Users\79069\AppData\Local\Programs\Python\Python39\lib\site-packages\googleapiclient\discovery_cache\file_cache.py", line 37, in <module>
    from oauth2client.locked_file import LockedFile
ModuleNotFoundError: No module named 'oauth2client.locked_file'

During handling of the above exception, another exception occurred:

Traceback (most recent call last):
  File "C:\Users\79069\AppData\Local\Programs\Python\Python39\lib\site-packages\googleapiclient\discovery_cache\__init__.py", line 44, in autodetect
    from . import file_cache
  File "C:\Users\79069\AppData\Local\Programs\Python\Python39\lib\site-packages\googleapiclient\discovery_cache\file_cache.py", line 40, in <module>
    raise ImportError(
ImportError: file_cache is unavailable when using oauth2client >= 4.0.0 or google-auth
DEBUG:googleapiclient.discovery:URL being requested: GET https://www.googleapis.com/discovery/v1/apis/drive/v3/rest
INFO:oauth2client.transport:Attempting refresh to obtain initial access_token
DEBUG:oauth2client.crypt:[b'eyJ0eXAiOiJKV1QiLCJhbGciOiJSUzI1NiIsImtpZCI6IjZiYzEzYmFjOTE0ZGZkNzliN2ZhOWQyODYxMzk5YzljZmY4OWFjNjcifQ', b'eyJhdWQiOiJodHRwczovL29hdXRoMi5nb29nbGVhcGlzLmNvbS90b2tlbiIsInNjb3BlIjoiaHR0cHM6Ly93d3cuZ29vZ2xlYXBpcy5jb20vYXV0aC9kcml2ZSIsImlhdCI6MTYxMzY1MjE0NSwiZXhwIjoxNjEzNjU1NzQ1LCJpc3MiOiJqdXN0LWFjY291bnRAdGVzdGFwaWFuZHNoZWV0cy5pYW0uZ3NlcnZpY2VhY2NvdW50LmNvbSJ9', b'oBxV3V01PRGBSnRSlt9dYzUi9tq29UAMTbI-hEtl2F8m9hOwFP0NkM2DtxyY7_m-3qF1kkTW4-1XF86WuDlkxTMVYUHD546Ne9_qFUZ8ysjAtz1u3ioEfpEzyVx7BIaeElKMvwLz9FOiP5-opw_HJKHCvfvJvD7En2EEWwZm83PYQ1923aYaXCpxtDTn957-1ZElVwXwiOPgtp6q6B_U7c4CKlO6tgpJ0bYofhO_gesrRDci02LGNYjs0xp9NzWdOBu5YkmBHJy2KWLGLScrsr4jiVrnQNjICTOiHojF6iNIAOBVR4d2UVH5CG1evW3bOwI-dGxV5_QIgBboJKVcFw']
INFO:oauth2client.client:Refreshing access_token
DEBUG:googleapiclient.discovery:URL being requested: POST https://www.googleapis.com/upload/drive/v3/files?fields=id&alt=json&uploadType=multipart
