INFO:root:Connection to PostgreSQL DB successful
INFO:root:Query executed successfully
INFO:root:Query executed successfully
INFO:root:Query executed successfully
INFO:root:Query executed successfully
INFO:root:Connection to PostgreSQL DB successful
INFO:root:Query executed successfully
WARNING:googleapiclient.discovery_cache:file_cache is unavailable when using oauth2client >= 4.0.0 or google-auth
Traceback (most recent call last):
  File "C:\Users\79069\AppData\Local\Programs\Python\Python39\lib\site-packages\googleapiclient\discovery_cache\file_cache.py", line 33, in <module>
    from oauth2client.contrib.locked_file import LockedFile
ModuleNotFoundError: No module named 'oauth2client.contrib.locked_file'

During handling of the above exception, another exception occurred:

Traceback (most recent call last):
  File "C:\Users\79069\AppData\Local\Programs\Python\Python39\lib\site-packages\googleapiclient\discovery_cache\file_cache.py", line 37, in <module>
    from oauth2client.locked_file import LockedFile
ModuleNotFoundError: No module named 'oauth2client.locked_file'

During handling of the above exception, another exception occurred:

Traceback (most recent call last):
  File "C:\Users\79069\AppData\Local\Programs\Python\Python39\lib\site-packages\googleapiclient\discovery_cache\__init__.py", line 44, in autodetect
    from . import file_cache
  File "C:\Users\79069\AppData\Local\Programs\Python\Python39\lib\site-packages\googleapiclient\discovery_cache\file_cache.py", line 40, in <module>
    raise ImportError(
ImportError: file_cache is unavailable when using oauth2client >= 4.0.0 or google-auth
DEBUG:googleapiclient.discovery:URL being requested: GET https://www.googleapis.com/discovery/v1/apis/drive/v3/rest
INFO:oauth2client.transport:Attempting refresh to obtain initial access_token
DEBUG:oauth2client.crypt:[b'eyJ0eXAiOiJKV1QiLCJhbGciOiJSUzI1NiIsImtpZCI6IjZiYzEzYmFjOTE0ZGZkNzliN2ZhOWQyODYxMzk5YzljZmY4OWFjNjcifQ', b'eyJhdWQiOiJodHRwczovL29hdXRoMi5nb29nbGVhcGlzLmNvbS90b2tlbiIsInNjb3BlIjoiaHR0cHM6Ly93d3cuZ29vZ2xlYXBpcy5jb20vYXV0aC9kcml2ZSIsImlhdCI6MTYxNDY4MzIyMSwiZXhwIjoxNjE0Njg2ODIxLCJpc3MiOiJqdXN0LWFjY291bnRAdGVzdGFwaWFuZHNoZWV0cy5pYW0uZ3NlcnZpY2VhY2NvdW50LmNvbSJ9', b'rOcwrUHmoneBB-dNfp-Q00ouxc03rveRMxQXhAe82EzA2fXZrVMfDc5JpZC_S45qqzoQRfKWetaV4RuCs_OgOvcGzrs4_1lcSmus5wNfWpiDayQI_WdsecSsiMpSrrBj0sqU2iLHrZVoCgZ_InvXbtlZsEJlU1UKNezVyfDkJMUOAQmnSEXKAzZLYrz3z8JYJQS_mJTUOtG3_vFuCJc3jqmnU0AWLBYtIlFJ5eJjpEWgI1z6p6qV5iC8_YJKlCT8VOYEekJlHHYmEijHD9naexH3rQVpc7Ra4_TGZpU1YGTnelqSJWsNSi0miVi_ZxoMIBvAHfuBv4qyeJUqLbQDiA']
INFO:oauth2client.client:Refreshing access_token
DEBUG:googleapiclient.discovery:URL being requested: GET https://www.googleapis.com/drive/v3/files/1oPNfi7KITsFqbQPfKbcdO7QpZDlvVHzT?alt=media
WARNING:googleapiclient.discovery_cache:file_cache is unavailable when using oauth2client >= 4.0.0 or google-auth
Traceback (most recent call last):
  File "C:\Users\79069\AppData\Local\Programs\Python\Python39\lib\site-packages\googleapiclient\discovery_cache\file_cache.py", line 33, in <module>
    from oauth2client.contrib.locked_file import LockedFile
ModuleNotFoundError: No module named 'oauth2client.contrib.locked_file'

During handling of the above exception, another exception occurred:

Traceback (most recent call last):
  File "C:\Users\79069\AppData\Local\Programs\Python\Python39\lib\site-packages\googleapiclient\discovery_cache\file_cache.py", line 37, in <module>
    from oauth2client.locked_file import LockedFile
ModuleNotFoundError: No module named 'oauth2client.locked_file'

During handling of the above exception, another exception occurred:

Traceback (most recent call last):
  File "C:\Users\79069\AppData\Local\Programs\Python\Python39\lib\site-packages\googleapiclient\discovery_cache\__init__.py", line 44, in autodetect
    from . import file_cache
  File "C:\Users\79069\AppData\Local\Programs\Python\Python39\lib\site-packages\googleapiclient\discovery_cache\file_cache.py", line 40, in <module>
    raise ImportError(
ImportError: file_cache is unavailable when using oauth2client >= 4.0.0 or google-auth
DEBUG:googleapiclient.discovery:URL being requested: GET https://www.googleapis.com/discovery/v1/apis/drive/v3/rest
INFO:oauth2client.transport:Attempting refresh to obtain initial access_token
DEBUG:oauth2client.crypt:[b'eyJ0eXAiOiJKV1QiLCJhbGciOiJSUzI1NiIsImtpZCI6IjZiYzEzYmFjOTE0ZGZkNzliN2ZhOWQyODYxMzk5YzljZmY4OWFjNjcifQ', b'eyJhdWQiOiJodHRwczovL29hdXRoMi5nb29nbGVhcGlzLmNvbS90b2tlbiIsInNjb3BlIjoiaHR0cHM6Ly93d3cuZ29vZ2xlYXBpcy5jb20vYXV0aC9kcml2ZSIsImlhdCI6MTYxNDY4MzI3MSwiZXhwIjoxNjE0Njg2ODcxLCJpc3MiOiJqdXN0LWFjY291bnRAdGVzdGFwaWFuZHNoZWV0cy5pYW0uZ3NlcnZpY2VhY2NvdW50LmNvbSJ9', b'ATRvncGd4B3xiKp8q4V-FDBfcU_W_vtYWNr1B57A-yb62VPTT5nq8-JVqxnmqfh-cJW800PiG9d820KtWxz_VHSvQb7Z0Mw5_I0CacL-SiB5fjAstjIQyVeDsTwRDSBuANpkAhBAnbhrSWcpQ8ueKNLkj-wx6jXsiKVX9EPFqHGuTRZC6XO_aPS2oB8y2auKiFeoUrhoTD4Kzk4FuUW6nF8-5W9QqS0q6rA1dMipMumE1DKTHoxIm8czk8BFHS9T8hdmnHxITXo7FXB-nUrxuO0hmdc_iA_xgbaTc7ZX9naEO1JuX4g0F3VejQzPxDZkZ0Vm6fXERnZld-05FV0BQw']
INFO:oauth2client.client:Refreshing access_token
INFO:root:filetype: text/plain
DEBUG:googleapiclient.discovery:URL being requested: POST https://www.googleapis.com/upload/drive/v3/files?fields=id&alt=json&uploadType=multipart
INFO:root:File ID: 1x7h_IqDkIBFIfZlB3PXUqNM5pdxdUkW9
INFO:root:Connection to PostgreSQL DB successful
INFO:root:Query executed successfully
INFO:root:Connection to PostgreSQL DB successful
INFO:root:Query executed successfully
INFO:root:Connection to PostgreSQL DB successful
INFO:root:Query executed successfully
INFO:root:Query executed successfully
INFO:root:Query executed successfully
INFO:root:Query executed successfully
INFO:root:Connection to PostgreSQL DB successful
INFO:root:Query executed successfully
WARNING:googleapiclient.discovery_cache:file_cache is unavailable when using oauth2client >= 4.0.0 or google-auth
Traceback (most recent call last):
  File "C:\Users\79069\AppData\Local\Programs\Python\Python39\lib\site-packages\googleapiclient\discovery_cache\file_cache.py", line 33, in <module>
    from oauth2client.contrib.locked_file import LockedFile
ModuleNotFoundError: No module named 'oauth2client.contrib.locked_file'

During handling of the above exception, another exception occurred:

Traceback (most recent call last):
  File "C:\Users\79069\AppData\Local\Programs\Python\Python39\lib\site-packages\googleapiclient\discovery_cache\file_cache.py", line 37, in <module>
    from oauth2client.locked_file import LockedFile
ModuleNotFoundError: No module named 'oauth2client.locked_file'

During handling of the above exception, another exception occurred:

Traceback (most recent call last):
  File "C:\Users\79069\AppData\Local\Programs\Python\Python39\lib\site-packages\googleapiclient\discovery_cache\__init__.py", line 44, in autodetect
    from . import file_cache
  File "C:\Users\79069\AppData\Local\Programs\Python\Python39\lib\site-packages\googleapiclient\discovery_cache\file_cache.py", line 40, in <module>
    raise ImportError(
ImportError: file_cache is unavailable when using oauth2client >= 4.0.0 or google-auth
DEBUG:googleapiclient.discovery:URL being requested: GET https://www.googleapis.com/discovery/v1/apis/drive/v3/rest
INFO:oauth2client.transport:Attempting refresh to obtain initial access_token
DEBUG:oauth2client.crypt:[b'eyJ0eXAiOiJKV1QiLCJhbGciOiJSUzI1NiIsImtpZCI6IjZiYzEzYmFjOTE0ZGZkNzliN2ZhOWQyODYxMzk5YzljZmY4OWFjNjcifQ', b'eyJhdWQiOiJodHRwczovL29hdXRoMi5nb29nbGVhcGlzLmNvbS90b2tlbiIsInNjb3BlIjoiaHR0cHM6Ly93d3cuZ29vZ2xlYXBpcy5jb20vYXV0aC9kcml2ZSIsImlhdCI6MTYxNDY4MzI4NiwiZXhwIjoxNjE0Njg2ODg2LCJpc3MiOiJqdXN0LWFjY291bnRAdGVzdGFwaWFuZHNoZWV0cy5pYW0uZ3NlcnZpY2VhY2NvdW50LmNvbSJ9', b'zv7cz4Vo3Wun-kO1rSclaQq5qdJ7lng1LD_mzD9VcpqP3VrS3rodqblidaGTMvN0eLEEDeDadW6kIRTUOAulFaz1XOcCuVohnYMGzevWus5pvU3TapCofDQySN-8TH9ZZsekBO36RrpkKCqKy658aAW4MUiAlzPdl0ZaQLjHcMQWl0uwp_VmLt5OPie02AwAIzGGfd9rGvUr5RIW1bOTpHzQA9OnlmFBCt4aOV14U7Irkc80dz6-aAQkx2MiNFY8pgylBK8DWAJEnjrtE9Bhl_7H4ghO8SpGqWSl-npQ-5megcVMzRXafdikSXjZTwT4ZlkI1zFb0HdtBCYcpi51Mw']
INFO:oauth2client.client:Refreshing access_token
DEBUG:googleapiclient.discovery:URL being requested: GET https://www.googleapis.com/drive/v3/files/1oPNfi7KITsFqbQPfKbcdO7QpZDlvVHzT?alt=media
INFO:root:Connection to PostgreSQL DB successful
INFO:root:Query executed successfully
INFO:root:Query executed successfully
INFO:root:Query executed successfully
INFO:root:Query executed successfully
INFO:root:Connection to PostgreSQL DB successful
INFO:root:Query executed successfully
WARNING:googleapiclient.discovery_cache:file_cache is unavailable when using oauth2client >= 4.0.0 or google-auth
Traceback (most recent call last):
  File "C:\Users\79069\AppData\Local\Programs\Python\Python39\lib\site-packages\googleapiclient\discovery_cache\file_cache.py", line 33, in <module>
    from oauth2client.contrib.locked_file import LockedFile
ModuleNotFoundError: No module named 'oauth2client.contrib.locked_file'

During handling of the above exception, another exception occurred:

Traceback (most recent call last):
  File "C:\Users\79069\AppData\Local\Programs\Python\Python39\lib\site-packages\googleapiclient\discovery_cache\file_cache.py", line 37, in <module>
    from oauth2client.locked_file import LockedFile
ModuleNotFoundError: No module named 'oauth2client.locked_file'

During handling of the above exception, another exception occurred:

Traceback (most recent call last):
  File "C:\Users\79069\AppData\Local\Programs\Python\Python39\lib\site-packages\googleapiclient\discovery_cache\__init__.py", line 44, in autodetect
    from . import file_cache
  File "C:\Users\79069\AppData\Local\Programs\Python\Python39\lib\site-packages\googleapiclient\discovery_cache\file_cache.py", line 40, in <module>
    raise ImportError(
ImportError: file_cache is unavailable when using oauth2client >= 4.0.0 or google-auth
DEBUG:googleapiclient.discovery:URL being requested: GET https://www.googleapis.com/discovery/v1/apis/drive/v3/rest
INFO:oauth2client.transport:Attempting refresh to obtain initial access_token
DEBUG:oauth2client.crypt:[b'eyJ0eXAiOiJKV1QiLCJhbGciOiJSUzI1NiIsImtpZCI6IjZiYzEzYmFjOTE0ZGZkNzliN2ZhOWQyODYxMzk5YzljZmY4OWFjNjcifQ', b'eyJhdWQiOiJodHRwczovL29hdXRoMi5nb29nbGVhcGlzLmNvbS90b2tlbiIsInNjb3BlIjoiaHR0cHM6Ly93d3cuZ29vZ2xlYXBpcy5jb20vYXV0aC9kcml2ZSIsImlhdCI6MTYxNDY4MzQwNiwiZXhwIjoxNjE0Njg3MDA2LCJpc3MiOiJqdXN0LWFjY291bnRAdGVzdGFwaWFuZHNoZWV0cy5pYW0uZ3NlcnZpY2VhY2NvdW50LmNvbSJ9', b'lJJU2aWwaloXrBTcoG9-xKMpG6z72l_bC1EZt_-_cqgyNOInRIKsNta2uSY27V30c98daUiAjoPyV0xUl5cd5BTBI3po-GqOYZoHeW7hbVNsbDJjq246mXAK0CEHPqrV-1MnLAz2Nv_c1nV1xAk-zX33k183IyemDyZkt-jUxYa4bCQqdZXcwOrsz4vKasK33M-38u3lEJaxKh2OpESeiF6cD2Fzv1Mo3yAUErCTeY7Co1KmmlgiAScFPMwpdY3hmW2eiKi1l0jxaszU8U5m98qB_9Dyx-KBYRLD0TPJsBLzDJDOC6Vk_sQnIsNs10495mJ3qKjuWTcguVHasKb4BQ']
INFO:oauth2client.client:Refreshing access_token
DEBUG:googleapiclient.discovery:URL being requested: GET https://www.googleapis.com/drive/v3/files/1oPNfi7KITsFqbQPfKbcdO7QpZDlvVHzT?alt=media
WARNING:googleapiclient.discovery_cache:file_cache is unavailable when using oauth2client >= 4.0.0 or google-auth
Traceback (most recent call last):
  File "C:\Users\79069\AppData\Local\Programs\Python\Python39\lib\site-packages\googleapiclient\discovery_cache\file_cache.py", line 33, in <module>
    from oauth2client.contrib.locked_file import LockedFile
ModuleNotFoundError: No module named 'oauth2client.contrib.locked_file'

During handling of the above exception, another exception occurred:

Traceback (most recent call last):
  File "C:\Users\79069\AppData\Local\Programs\Python\Python39\lib\site-packages\googleapiclient\discovery_cache\file_cache.py", line 37, in <module>
    from oauth2client.locked_file import LockedFile
ModuleNotFoundError: No module named 'oauth2client.locked_file'

During handling of the above exception, another exception occurred:

Traceback (most recent call last):
  File "C:\Users\79069\AppData\Local\Programs\Python\Python39\lib\site-packages\googleapiclient\discovery_cache\__init__.py", line 44, in autodetect
    from . import file_cache
  File "C:\Users\79069\AppData\Local\Programs\Python\Python39\lib\site-packages\googleapiclient\discovery_cache\file_cache.py", line 40, in <module>
    raise ImportError(
ImportError: file_cache is unavailable when using oauth2client >= 4.0.0 or google-auth
DEBUG:googleapiclient.discovery:URL being requested: GET https://www.googleapis.com/discovery/v1/apis/drive/v3/rest
INFO:oauth2client.transport:Attempting refresh to obtain initial access_token
DEBUG:oauth2client.crypt:[b'eyJ0eXAiOiJKV1QiLCJhbGciOiJSUzI1NiIsImtpZCI6IjZiYzEzYmFjOTE0ZGZkNzliN2ZhOWQyODYxMzk5YzljZmY4OWFjNjcifQ', b'eyJhdWQiOiJodHRwczovL29hdXRoMi5nb29nbGVhcGlzLmNvbS90b2tlbiIsInNjb3BlIjoiaHR0cHM6Ly93d3cuZ29vZ2xlYXBpcy5jb20vYXV0aC9kcml2ZSIsImlhdCI6MTYxNDY4MzQwOCwiZXhwIjoxNjE0Njg3MDA4LCJpc3MiOiJqdXN0LWFjY291bnRAdGVzdGFwaWFuZHNoZWV0cy5pYW0uZ3NlcnZpY2VhY2NvdW50LmNvbSJ9', b'1AgcHlZYVLD470FNXsmEMtrKBVP-j3p9v1-z55UnBZkouxjvaYNTadgvF_4evwF6OAN5X8CUVdS6CLtM7DIQpV_lftOmFi__8tlMFX0keTCpqn4IXH5ZQixyg7BH8H1SR-w8H3V22W4o1IlddSreo1sOsjVzAPHD2ENNKOvNlcaw1ewrAJTWnjxa-_wmtI_Q3lRmXSVteDqOhJsFvER3n90Ma1fQ6WOWOVxS7Pc41RbmL_a5Yu1UwkWRp4ZyJz9KQgISzhh5zdUZV926pzk2CORL_qVSc0RNQi1c7DOBTlEY2fhD5fxY_Pc2W2R8278rE6Jo-Zy7FO9tFhSlhX-_EQ']
INFO:oauth2client.client:Refreshing access_token
DEBUG:googleapiclient.discovery:URL being requested: GET https://www.googleapis.com/drive/v3/files/1tdvwtNx2iQUEDPbpe7NsSl-djVe-_h9G?alt=media
INFO:root:Connection to PostgreSQL DB successful
INFO:root:Query executed successfully
WARNING:googleapiclient.discovery_cache:file_cache is unavailable when using oauth2client >= 4.0.0 or google-auth
Traceback (most recent call last):
  File "C:\Users\79069\AppData\Local\Programs\Python\Python39\lib\site-packages\googleapiclient\discovery_cache\file_cache.py", line 33, in <module>
    from oauth2client.contrib.locked_file import LockedFile
ModuleNotFoundError: No module named 'oauth2client.contrib.locked_file'

During handling of the above exception, another exception occurred:

Traceback (most recent call last):
  File "C:\Users\79069\AppData\Local\Programs\Python\Python39\lib\site-packages\googleapiclient\discovery_cache\file_cache.py", line 37, in <module>
    from oauth2client.locked_file import LockedFile
ModuleNotFoundError: No module named 'oauth2client.locked_file'

During handling of the above exception, another exception occurred:

Traceback (most recent call last):
  File "C:\Users\79069\AppData\Local\Programs\Python\Python39\lib\site-packages\googleapiclient\discovery_cache\__init__.py", line 44, in autodetect
    from . import file_cache
  File "C:\Users\79069\AppData\Local\Programs\Python\Python39\lib\site-packages\googleapiclient\discovery_cache\file_cache.py", line 40, in <module>
    raise ImportError(
ImportError: file_cache is unavailable when using oauth2client >= 4.0.0 or google-auth
DEBUG:googleapiclient.discovery:URL being requested: GET https://www.googleapis.com/discovery/v1/apis/drive/v3/rest
INFO:oauth2client.transport:Attempting refresh to obtain initial access_token
DEBUG:oauth2client.crypt:[b'eyJ0eXAiOiJKV1QiLCJhbGciOiJSUzI1NiIsImtpZCI6IjZiYzEzYmFjOTE0ZGZkNzliN2ZhOWQyODYxMzk5YzljZmY4OWFjNjcifQ', b'eyJhdWQiOiJodHRwczovL29hdXRoMi5nb29nbGVhcGlzLmNvbS90b2tlbiIsInNjb3BlIjoiaHR0cHM6Ly93d3cuZ29vZ2xlYXBpcy5jb20vYXV0aC9kcml2ZSIsImlhdCI6MTYxNDY4MzQxNywiZXhwIjoxNjE0Njg3MDE3LCJpc3MiOiJqdXN0LWFjY291bnRAdGVzdGFwaWFuZHNoZWV0cy5pYW0uZ3NlcnZpY2VhY2NvdW50LmNvbSJ9', b'r0IHWXUVZ3EM9TBlF-ExHaDPfTEAQMwvFsnCZ0wgPDsH8ycoD9vXcPMQiOPmcttZggooediqO_kPTz_zaRVw3QtuTxosc2BPgHlc6g7rK6JPzUWiNsq_LMCB1LtxsOXsfAX0CADET97yrJS98uUJWqmCNC67JKJhvxUMNiCx8lnsBQWiePtYv3KGgMEmpK40nVpGc3gMyrRnIIrsKGZKG2nAbPrFzHEMUCwOiLuxVNFjY-Qq-edXmzNVS2_0mGxoSxG2MKDMBCE49Ly2iKa2THytOgCJgdPlBZel_eKlreInDPMVSF8bbgrCRYtqOEKGb2mgQXRupHqOTVcHrQKXYg']
INFO:oauth2client.client:Refreshing access_token
DEBUG:googleapiclient.discovery:URL being requested: GET https://www.googleapis.com/drive/v3/files/14zy99yTm2Nq8l1nQ3WS189ITecl8dsWK?alt=media
WARNING:googleapiclient.discovery_cache:file_cache is unavailable when using oauth2client >= 4.0.0 or google-auth
Traceback (most recent call last):
  File "C:\Users\79069\AppData\Local\Programs\Python\Python39\lib\site-packages\googleapiclient\discovery_cache\file_cache.py", line 33, in <module>
    from oauth2client.contrib.locked_file import LockedFile
ModuleNotFoundError: No module named 'oauth2client.contrib.locked_file'

During handling of the above exception, another exception occurred:

Traceback (most recent call last):
  File "C:\Users\79069\AppData\Local\Programs\Python\Python39\lib\site-packages\googleapiclient\discovery_cache\file_cache.py", line 37, in <module>
    from oauth2client.locked_file import LockedFile
ModuleNotFoundError: No module named 'oauth2client.locked_file'

During handling of the above exception, another exception occurred:

Traceback (most recent call last):
  File "C:\Users\79069\AppData\Local\Programs\Python\Python39\lib\site-packages\googleapiclient\discovery_cache\__init__.py", line 44, in autodetect
    from . import file_cache
  File "C:\Users\79069\AppData\Local\Programs\Python\Python39\lib\site-packages\googleapiclient\discovery_cache\file_cache.py", line 40, in <module>
    raise ImportError(
ImportError: file_cache is unavailable when using oauth2client >= 4.0.0 or google-auth
DEBUG:googleapiclient.discovery:URL being requested: GET https://www.googleapis.com/discovery/v1/apis/drive/v3/rest
INFO:oauth2client.transport:Attempting refresh to obtain initial access_token
DEBUG:oauth2client.crypt:[b'eyJ0eXAiOiJKV1QiLCJhbGciOiJSUzI1NiIsImtpZCI6IjZiYzEzYmFjOTE0ZGZkNzliN2ZhOWQyODYxMzk5YzljZmY4OWFjNjcifQ', b'eyJhdWQiOiJodHRwczovL29hdXRoMi5nb29nbGVhcGlzLmNvbS90b2tlbiIsInNjb3BlIjoiaHR0cHM6Ly93d3cuZ29vZ2xlYXBpcy5jb20vYXV0aC9kcml2ZSIsImlhdCI6MTYxNDY4MzQyNSwiZXhwIjoxNjE0Njg3MDI1LCJpc3MiOiJqdXN0LWFjY291bnRAdGVzdGFwaWFuZHNoZWV0cy5pYW0uZ3NlcnZpY2VhY2NvdW50LmNvbSJ9', b'jzfNuz6XcBI0SriMGQ2tRGKt2VXpNSfS9OKbTqeJTCGdBrI8d7_Z7ghsvSyETG2W8bPUAKwWerW7yNIDsa-FnSM6mFQUKja8XXfHutVYVChFvg6h5OCVqQ_WW7jj4mRpsu5EByC8DtDAgUfVNi3BdM2-X9I9YFLOnmumpX1m5FTaCUnvYoZ8cCoiL56LalP9lkDcZETFMLwtXEfvc3E9vDht8zNW7GVeDYcalqzAEyt3Uc1PZdCR0MO294XGea0qMeZ-pIEAzsV45VoN1ozpzhJmfRrI4ihSHD2z0nOzccbxDYDV3TxyRPln290otEcC7SL4DgK4J7XUgBFFguvqSw']
INFO:oauth2client.client:Refreshing access_token
INFO:root:filetype: text/plain
DEBUG:googleapiclient.discovery:URL being requested: POST https://www.googleapis.com/upload/drive/v3/files?fields=id&alt=json&uploadType=multipart
INFO:root:File ID: 1RIYRlcaRKOhNEfBxobWgzjpTbyDoEb37
INFO:root:Connection to PostgreSQL DB successful
INFO:root:Query executed successfully
INFO:root:Connection to PostgreSQL DB successful
INFO:root:Query executed successfully
INFO:root:Connection to PostgreSQL DB successful
INFO:root:Query executed successfully
INFO:root:Query executed successfully
INFO:root:You are logged in!
INFO:root:Connection to PostgreSQL DB successful
INFO:root:Query executed successfully
WARNING:googleapiclient.discovery_cache:file_cache is unavailable when using oauth2client >= 4.0.0 or google-auth
Traceback (most recent call last):
  File "C:\Users\79069\AppData\Local\Programs\Python\Python39\lib\site-packages\googleapiclient\discovery_cache\file_cache.py", line 33, in <module>
    from oauth2client.contrib.locked_file import LockedFile
ModuleNotFoundError: No module named 'oauth2client.contrib.locked_file'

During handling of the above exception, another exception occurred:

Traceback (most recent call last):
  File "C:\Users\79069\AppData\Local\Programs\Python\Python39\lib\site-packages\googleapiclient\discovery_cache\file_cache.py", line 37, in <module>
    from oauth2client.locked_file import LockedFile
ModuleNotFoundError: No module named 'oauth2client.locked_file'

During handling of the above exception, another exception occurred:

Traceback (most recent call last):
  File "C:\Users\79069\AppData\Local\Programs\Python\Python39\lib\site-packages\googleapiclient\discovery_cache\__init__.py", line 44, in autodetect
    from . import file_cache
  File "C:\Users\79069\AppData\Local\Programs\Python\Python39\lib\site-packages\googleapiclient\discovery_cache\file_cache.py", line 40, in <module>
    raise ImportError(
ImportError: file_cache is unavailable when using oauth2client >= 4.0.0 or google-auth
DEBUG:googleapiclient.discovery:URL being requested: GET https://www.googleapis.com/discovery/v1/apis/drive/v3/rest
INFO:oauth2client.transport:Attempting refresh to obtain initial access_token
DEBUG:oauth2client.crypt:[b'eyJ0eXAiOiJKV1QiLCJhbGciOiJSUzI1NiIsImtpZCI6IjZiYzEzYmFjOTE0ZGZkNzliN2ZhOWQyODYxMzk5YzljZmY4OWFjNjcifQ', b'eyJhdWQiOiJodHRwczovL29hdXRoMi5nb29nbGVhcGlzLmNvbS90b2tlbiIsInNjb3BlIjoiaHR0cHM6Ly93d3cuZ29vZ2xlYXBpcy5jb20vYXV0aC9kcml2ZSIsImlhdCI6MTYxNDY4MzU2MywiZXhwIjoxNjE0Njg3MTYzLCJpc3MiOiJqdXN0LWFjY291bnRAdGVzdGFwaWFuZHNoZWV0cy5pYW0uZ3NlcnZpY2VhY2NvdW50LmNvbSJ9', b'FrQ0_6PgyQg4FB2CdflXjlMNGSTqxhRr6VmjVmLvi7RtJBpDNsBlplpuG5Y0p4K1mUWkEGjlq4R2HN2TwgvcTrKgQxOVkpLb3uT3OxePwEQa2mDMjjxRwCYKOAKxfNsMeF7dpG8C9C0rSlWnqNgq16fyhuLQw-QygVZfG7rwnb_tgfbBgeJKgVTDGcTI4s4PYE1VvtLEVseRvZM9z4XVUxhiqFjUPuGJJUdur2_VTpjKyUENK6bXcz29RwlWx51x95MFGtdToTRvpm6Pp7RRhWdErA8D-XxbdKz2FyUCLOiJfCL57U5Bts9a4p0ik7riRrKzvhJtW_Pyb1NKnt24jQ']
INFO:oauth2client.client:Refreshing access_token
DEBUG:googleapiclient.discovery:URL being requested: GET https://www.googleapis.com/drive/v3/files/1jgRj4273tHow-e8JJ8btM4jl6rG20t1U?alt=media
INFO:root:Connection to PostgreSQL DB successful
INFO:root:Query executed successfully
INFO:root:Connection to PostgreSQL DB successful
INFO:root:Query executed successfully
INFO:root:Connection to PostgreSQL DB successful
INFO:root:Query executed successfully
INFO:root:Connection to PostgreSQL DB successful
INFO:root:Query executed successfully
INFO:root:Connection to PostgreSQL DB successful
INFO:root:Connection to PostgreSQL DB successful
INFO:root:Query executed successfully
INFO:root:Connection to PostgreSQL DB successful
INFO:root:Query executed successfully
INFO:root:Connection to PostgreSQL DB successful
INFO:root:Query executed successfully
INFO:root:Connection to PostgreSQL DB successful
INFO:root:Query executed successfully
INFO:root:Connection to PostgreSQL DB successful
INFO:root:Query executed successfully
INFO:root:Connection to PostgreSQL DB successful
INFO:root:Connection to PostgreSQL DB successful
INFO:root:Query executed successfully
INFO:root:Connection to PostgreSQL DB successful
INFO:root:Query executed successfully
INFO:root:Connection to PostgreSQL DB successful
INFO:root:Query executed successfully
INFO:root:Connection to PostgreSQL DB successful
INFO:root:Query executed successfully
INFO:root:Connection to PostgreSQL DB successful
INFO:root:Query executed successfully
INFO:root:Query executed successfully
INFO:root:You are logged in!
INFO:root:Connection to PostgreSQL DB successful
INFO:root:Query executed successfully
INFO:root:Connection to PostgreSQL DB successful
INFO:root:Query executed successfully
INFO:root:Connection to PostgreSQL DB successful
INFO:root:Query executed successfully
INFO:root:Query executed successfully
INFO:root:Query executed successfully
INFO:root:Query executed successfully
INFO:root:Connection to PostgreSQL DB successful
INFO:root:Query executed successfully
WARNING:googleapiclient.discovery_cache:file_cache is unavailable when using oauth2client >= 4.0.0 or google-auth
Traceback (most recent call last):
  File "C:\Users\79069\AppData\Local\Programs\Python\Python39\lib\site-packages\googleapiclient\discovery_cache\file_cache.py", line 33, in <module>
    from oauth2client.contrib.locked_file import LockedFile
ModuleNotFoundError: No module named 'oauth2client.contrib.locked_file'

During handling of the above exception, another exception occurred:

Traceback (most recent call last):
  File "C:\Users\79069\AppData\Local\Programs\Python\Python39\lib\site-packages\googleapiclient\discovery_cache\file_cache.py", line 37, in <module>
    from oauth2client.locked_file import LockedFile
ModuleNotFoundError: No module named 'oauth2client.locked_file'

During handling of the above exception, another exception occurred:

Traceback (most recent call last):
  File "C:\Users\79069\AppData\Local\Programs\Python\Python39\lib\site-packages\googleapiclient\discovery_cache\__init__.py", line 44, in autodetect
    from . import file_cache
  File "C:\Users\79069\AppData\Local\Programs\Python\Python39\lib\site-packages\googleapiclient\discovery_cache\file_cache.py", line 40, in <module>
    raise ImportError(
ImportError: file_cache is unavailable when using oauth2client >= 4.0.0 or google-auth
DEBUG:googleapiclient.discovery:URL being requested: GET https://www.googleapis.com/discovery/v1/apis/drive/v3/rest
INFO:oauth2client.transport:Attempting refresh to obtain initial access_token
DEBUG:oauth2client.crypt:[b'eyJ0eXAiOiJKV1QiLCJhbGciOiJSUzI1NiIsImtpZCI6IjZiYzEzYmFjOTE0ZGZkNzliN2ZhOWQyODYxMzk5YzljZmY4OWFjNjcifQ', b'eyJhdWQiOiJodHRwczovL29hdXRoMi5nb29nbGVhcGlzLmNvbS90b2tlbiIsInNjb3BlIjoiaHR0cHM6Ly93d3cuZ29vZ2xlYXBpcy5jb20vYXV0aC9kcml2ZSIsImlhdCI6MTYxNDY4MzgxNCwiZXhwIjoxNjE0Njg3NDE0LCJpc3MiOiJqdXN0LWFjY291bnRAdGVzdGFwaWFuZHNoZWV0cy5pYW0uZ3NlcnZpY2VhY2NvdW50LmNvbSJ9', b'lml1y4MYZHw9i_Y5t0mVp6ZplDxzVMiQFuwYzDx8XnqKHDd83TdegvjRfd504olTyMt6CDMvd89RKegyt4dwGq9zlvuwpUUrkeXRP-4r3Bf6gBLsjvspXN7nFjJWr8o3T5o94ho4K2vjVozCcWNGLUpzyGLNXA0ItCMiolbZ_D0k6XcLp-zoXNWxOAAUJ-7SHqgjnbnYnxtREO8h-JrX3SXzuaBRD7U0aCrFzOt7IjZEY9mzoQGTOrz8cUmeNrIqq-Y7tZ5_ExHoGtDezljznMc1inUYEi3h1FpgtkJ1VyFpwdP4EJ5YyFY16CSK8wQyBSC2J9FXzoyl0fwSO0yYfA']
INFO:oauth2client.client:Refreshing access_token
DEBUG:googleapiclient.discovery:URL being requested: GET https://www.googleapis.com/drive/v3/files/Test1.txt?alt=media
ERROR:root:<HttpError 404 when requesting https://www.googleapis.com/drive/v3/files/Test1.txt?alt=media returned "File not found: Test1.txt.". Details: "File not found: Test1.txt.">
INFO:root:Connection to PostgreSQL DB successful
INFO:root:Query executed successfully
INFO:root:Connection to PostgreSQL DB successful
INFO:root:Query executed successfully
INFO:root:Connection to PostgreSQL DB successful
INFO:root:Query executed successfully
INFO:root:Query executed successfully
INFO:root:Query executed successfully
INFO:root:Query executed successfully
INFO:root:Connection to PostgreSQL DB successful
INFO:root:Query executed successfully
WARNING:googleapiclient.discovery_cache:file_cache is unavailable when using oauth2client >= 4.0.0 or google-auth
Traceback (most recent call last):
  File "C:\Users\79069\AppData\Local\Programs\Python\Python39\lib\site-packages\googleapiclient\discovery_cache\file_cache.py", line 33, in <module>
    from oauth2client.contrib.locked_file import LockedFile
ModuleNotFoundError: No module named 'oauth2client.contrib.locked_file'

During handling of the above exception, another exception occurred:

Traceback (most recent call last):
  File "C:\Users\79069\AppData\Local\Programs\Python\Python39\lib\site-packages\googleapiclient\discovery_cache\file_cache.py", line 37, in <module>
    from oauth2client.locked_file import LockedFile
ModuleNotFoundError: No module named 'oauth2client.locked_file'

During handling of the above exception, another exception occurred:

Traceback (most recent call last):
  File "C:\Users\79069\AppData\Local\Programs\Python\Python39\lib\site-packages\googleapiclient\discovery_cache\__init__.py", line 44, in autodetect
    from . import file_cache
  File "C:\Users\79069\AppData\Local\Programs\Python\Python39\lib\site-packages\googleapiclient\discovery_cache\file_cache.py", line 40, in <module>
    raise ImportError(
ImportError: file_cache is unavailable when using oauth2client >= 4.0.0 or google-auth
DEBUG:googleapiclient.discovery:URL being requested: GET https://www.googleapis.com/discovery/v1/apis/drive/v3/rest
INFO:oauth2client.transport:Attempting refresh to obtain initial access_token
DEBUG:oauth2client.crypt:[b'eyJ0eXAiOiJKV1QiLCJhbGciOiJSUzI1NiIsImtpZCI6IjZiYzEzYmFjOTE0ZGZkNzliN2ZhOWQyODYxMzk5YzljZmY4OWFjNjcifQ', b'eyJhdWQiOiJodHRwczovL29hdXRoMi5nb29nbGVhcGlzLmNvbS90b2tlbiIsInNjb3BlIjoiaHR0cHM6Ly93d3cuZ29vZ2xlYXBpcy5jb20vYXV0aC9kcml2ZSIsImlhdCI6MTYxNDY4Mzg2NiwiZXhwIjoxNjE0Njg3NDY2LCJpc3MiOiJqdXN0LWFjY291bnRAdGVzdGFwaWFuZHNoZWV0cy5pYW0uZ3NlcnZpY2VhY2NvdW50LmNvbSJ9', b'1VceQHruAPjNbc-FnmfAk6T5kt6XBqNMJxH3UPm5T8_R5NopbowGy6wjsm_Dj6TKx68azQd5F2MZ4JKr8Sa9qP4dh6qw6WfQuNyJ3x2E_QvmH9IXZrkYDJ6FO5_dedKwAl0UBvnxZ93PCTLomdSedECz3li4PgmlNMMxSl1SOKRbJYZBUJIxxe_sL8eP7Yoliff880aSrwuvNQcqv9_herXAD2Oe7MAjTPD-LBqqTsNHayDnJ_emSsYyLciei2dGyDmUxCBnVe5jNBODmVez6bEebTUsQlj-gPo0L3QhFRHbb_hzhjZC4zh5M8Fu_e7IDJNZMPufEBOIxe0cDPysdQ']
INFO:oauth2client.client:Refreshing access_token
DEBUG:googleapiclient.discovery:URL being requested: GET https://www.googleapis.com/drive/v3/files/Test1.txt?alt=media
INFO:root:Connection to PostgreSQL DB successful
INFO:root:Query executed successfully
INFO:root:Query executed successfully
INFO:root:You are logged in!
INFO:root:Connection to PostgreSQL DB successful
INFO:root:Query executed successfully
INFO:root:Connection to PostgreSQL DB successful
INFO:root:Query executed successfully
INFO:root:Connection to PostgreSQL DB successful
INFO:root:Query executed successfully
INFO:root:Query executed successfully
INFO:root:Query executed successfully
INFO:root:Query executed successfully
INFO:root:Connection to PostgreSQL DB successful
INFO:root:Query executed successfully
WARNING:googleapiclient.discovery_cache:file_cache is unavailable when using oauth2client >= 4.0.0 or google-auth
Traceback (most recent call last):
  File "C:\Users\79069\AppData\Local\Programs\Python\Python39\lib\site-packages\googleapiclient\discovery_cache\file_cache.py", line 33, in <module>
    from oauth2client.contrib.locked_file import LockedFile
ModuleNotFoundError: No module named 'oauth2client.contrib.locked_file'

During handling of the above exception, another exception occurred:

Traceback (most recent call last):
  File "C:\Users\79069\AppData\Local\Programs\Python\Python39\lib\site-packages\googleapiclient\discovery_cache\file_cache.py", line 37, in <module>
    from oauth2client.locked_file import LockedFile
ModuleNotFoundError: No module named 'oauth2client.locked_file'

During handling of the above exception, another exception occurred:

Traceback (most recent call last):
  File "C:\Users\79069\AppData\Local\Programs\Python\Python39\lib\site-packages\googleapiclient\discovery_cache\__init__.py", line 44, in autodetect
    from . import file_cache
  File "C:\Users\79069\AppData\Local\Programs\Python\Python39\lib\site-packages\googleapiclient\discovery_cache\file_cache.py", line 40, in <module>
    raise ImportError(
ImportError: file_cache is unavailable when using oauth2client >= 4.0.0 or google-auth
DEBUG:googleapiclient.discovery:URL being requested: GET https://www.googleapis.com/discovery/v1/apis/drive/v3/rest
INFO:oauth2client.transport:Attempting refresh to obtain initial access_token
DEBUG:oauth2client.crypt:[b'eyJ0eXAiOiJKV1QiLCJhbGciOiJSUzI1NiIsImtpZCI6IjZiYzEzYmFjOTE0ZGZkNzliN2ZhOWQyODYxMzk5YzljZmY4OWFjNjcifQ', b'eyJhdWQiOiJodHRwczovL29hdXRoMi5nb29nbGVhcGlzLmNvbS90b2tlbiIsInNjb3BlIjoiaHR0cHM6Ly93d3cuZ29vZ2xlYXBpcy5jb20vYXV0aC9kcml2ZSIsImlhdCI6MTYxNDY4Mzk5NiwiZXhwIjoxNjE0Njg3NTk2LCJpc3MiOiJqdXN0LWFjY291bnRAdGVzdGFwaWFuZHNoZWV0cy5pYW0uZ3NlcnZpY2VhY2NvdW50LmNvbSJ9', b'P1dyMkgNgAIYCudsfe3HtHp_8kAzNndeGIpFIr75Od6-JaARA3Cr8P0qEU_Mc_zjp9eBVQA0qmefO5TUhWjzcggeDbFM6ZRwZkKn8bq-DR4xaJvvGcVyLL7xWnE88D7ZNCSUt2rkvVAX0r5IpvUK2ItEy1G5YM92G6AgWxXlcQF_NkjnZxEhTRzT-ExUqF501BSTSsNU2SYd0HU3T5lqLNUkJ7rjxLY3uXlwspoCZRjEN9NXmBadBqMRj-WEfaExwq0qFIIlEz99ymhjYBoR-kCYFoW4K0XZin7vvaSWfNYHo31aF2lWmy_W6ijJx4iMJfEvYKu_xEpdrweU-MzzJA']
INFO:oauth2client.client:Refreshing access_token
DEBUG:googleapiclient.discovery:URL being requested: GET https://www.googleapis.com/drive/v3/files/1oPNfi7KITsFqbQPfKbcdO7QpZDlvVHzT?alt=media
WARNING:googleapiclient.discovery_cache:file_cache is unavailable when using oauth2client >= 4.0.0 or google-auth
Traceback (most recent call last):
  File "C:\Users\79069\AppData\Local\Programs\Python\Python39\lib\site-packages\googleapiclient\discovery_cache\file_cache.py", line 33, in <module>
    from oauth2client.contrib.locked_file import LockedFile
ModuleNotFoundError: No module named 'oauth2client.contrib.locked_file'

During handling of the above exception, another exception occurred:

Traceback (most recent call last):
  File "C:\Users\79069\AppData\Local\Programs\Python\Python39\lib\site-packages\googleapiclient\discovery_cache\file_cache.py", line 37, in <module>
    from oauth2client.locked_file import LockedFile
ModuleNotFoundError: No module named 'oauth2client.locked_file'

During handling of the above exception, another exception occurred:

Traceback (most recent call last):
  File "C:\Users\79069\AppData\Local\Programs\Python\Python39\lib\site-packages\googleapiclient\discovery_cache\__init__.py", line 44, in autodetect
    from . import file_cache
  File "C:\Users\79069\AppData\Local\Programs\Python\Python39\lib\site-packages\googleapiclient\discovery_cache\file_cache.py", line 40, in <module>
    raise ImportError(
ImportError: file_cache is unavailable when using oauth2client >= 4.0.0 or google-auth
DEBUG:googleapiclient.discovery:URL being requested: GET https://www.googleapis.com/discovery/v1/apis/drive/v3/rest
INFO:oauth2client.transport:Attempting refresh to obtain initial access_token
DEBUG:oauth2client.crypt:[b'eyJ0eXAiOiJKV1QiLCJhbGciOiJSUzI1NiIsImtpZCI6IjZiYzEzYmFjOTE0ZGZkNzliN2ZhOWQyODYxMzk5YzljZmY4OWFjNjcifQ', b'eyJhdWQiOiJodHRwczovL29hdXRoMi5nb29nbGVhcGlzLmNvbS90b2tlbiIsInNjb3BlIjoiaHR0cHM6Ly93d3cuZ29vZ2xlYXBpcy5jb20vYXV0aC9kcml2ZSIsImlhdCI6MTYxNDY4NDAwNSwiZXhwIjoxNjE0Njg3NjA1LCJpc3MiOiJqdXN0LWFjY291bnRAdGVzdGFwaWFuZHNoZWV0cy5pYW0uZ3NlcnZpY2VhY2NvdW50LmNvbSJ9', b'387vK0E-0n1xFlIzJbHSB5jpr5eAOWsppPTIskTemG7KRXMvukiWcFsWw_41BxayDJ05PjLbpxCLeDCyuznquMKa0aCj8gVbOh6vPqkzCfcTYsGp61I3Ea2hUivXjNXd5BmKxHG4Q1Qs6wvRJpKTLzWQgZ8wtH3WFahc63SmjOXRcs428orC8-_OFJgfyv-mKRYjZgO8lXpGZ8vmjIOPf6-vCU17g47P6Uve8-RKOr_XAOBmKrgN41xHl7AJ1FcLba-7Dbmj9L9LYdno-XaAjRoLQV_DIPl8rucwSzsCrsJArX9RPZhimoinNq4cHCsi5O-vBR3xneiOQxe929FMDg']
INFO:oauth2client.client:Refreshing access_token
INFO:root:filetype: text/plain
DEBUG:googleapiclient.discovery:URL being requested: POST https://www.googleapis.com/upload/drive/v3/files?fields=id&alt=json&uploadType=multipart
INFO:root:File ID: 16ijZzAFUr2HQqQbKhaXSSTE6aGtqj9wt
INFO:root:Connection to PostgreSQL DB successful
INFO:root:Query executed successfully
INFO:root:Connection to PostgreSQL DB successful
INFO:root:Query executed successfully
INFO:root:Connection to PostgreSQL DB successful
INFO:root:Query executed successfully
INFO:root:Query executed successfully
INFO:root:Query executed successfully
INFO:root:Connection to PostgreSQL DB successful
INFO:root:Query executed successfully
INFO:root:Connection to PostgreSQL DB successful
INFO:root:Query executed successfully
INFO:root:Connection to PostgreSQL DB successful
INFO:root:Connection to PostgreSQL DB successful
INFO:root:Query executed successfully
INFO:root:Connection to PostgreSQL DB successful
INFO:root:Query executed successfully
INFO:root:Connection to PostgreSQL DB successful
INFO:root:Query executed successfully
INFO:root:Connection to PostgreSQL DB successful
INFO:root:Query executed successfully
INFO:root:Connection to PostgreSQL DB successful
INFO:root:Query executed successfully
INFO:root:Connection to PostgreSQL DB successful
INFO:root:Query executed successfully
INFO:root:Connection to PostgreSQL DB successful
INFO:root:Query executed successfully
INFO:root:Connection to PostgreSQL DB successful
INFO:root:Query executed successfully
