WARNING:googleapiclient.discovery_cache:file_cache is unavailable when using oauth2client >= 4.0.0 or google-auth
Traceback (most recent call last):
  File "C:\Users\79069\AppData\Local\Programs\Python\Python39\lib\site-packages\googleapiclient\discovery_cache\file_cache.py", line 33, in <module>
    from oauth2client.contrib.locked_file import LockedFile
ModuleNotFoundError: No module named 'oauth2client.contrib.locked_file'

During handling of the above exception, another exception occurred:

Traceback (most recent call last):
  File "C:\Users\79069\AppData\Local\Programs\Python\Python39\lib\site-packages\googleapiclient\discovery_cache\file_cache.py", line 37, in <module>
    from oauth2client.locked_file import LockedFile
ModuleNotFoundError: No module named 'oauth2client.locked_file'

During handling of the above exception, another exception occurred:

Traceback (most recent call last):
  File "C:\Users\79069\AppData\Local\Programs\Python\Python39\lib\site-packages\googleapiclient\discovery_cache\__init__.py", line 44, in autodetect
    from . import file_cache
  File "C:\Users\79069\AppData\Local\Programs\Python\Python39\lib\site-packages\googleapiclient\discovery_cache\file_cache.py", line 40, in <module>
    raise ImportError(
ImportError: file_cache is unavailable when using oauth2client >= 4.0.0 or google-auth
DEBUG:googleapiclient.discovery:URL being requested: GET https://www.googleapis.com/discovery/v1/apis/drive/v3/rest
INFO:oauth2client.transport:Attempting refresh to obtain initial access_token
DEBUG:oauth2client.crypt:[b'eyJ0eXAiOiJKV1QiLCJhbGciOiJSUzI1NiIsImtpZCI6IjZiYzEzYmFjOTE0ZGZkNzliN2ZhOWQyODYxMzk5YzljZmY4OWFjNjcifQ', b'eyJhdWQiOiJodHRwczovL29hdXRoMi5nb29nbGVhcGlzLmNvbS90b2tlbiIsInNjb3BlIjoiaHR0cHM6Ly93d3cuZ29vZ2xlYXBpcy5jb20vYXV0aC9kcml2ZSIsImlhdCI6MTYxNDE2OTUyMSwiZXhwIjoxNjE0MTczMTIxLCJpc3MiOiJqdXN0LWFjY291bnRAdGVzdGFwaWFuZHNoZWV0cy5pYW0uZ3NlcnZpY2VhY2NvdW50LmNvbSJ9', b'AeZPFvvcGK-SKfacCbtIppmZD89v5QNylinD1jt3VUWCqmqQw3XNAXqOyAqy9cJJGfaKcJdP1GsciyIfMhm1UY9Kw3W0qM_jJ102IGbQ3H-LHK2lwBm2kukGjmzI3JISTzWfjZxRYTJX8aNEFkuV7SiiEIClMJ40q39Eu4evkz__v7hqoO5JxIuqzb-16RzVfJXtZH_csb2OfYWnZ7j_t4VqWACVbqC7GPER_SDgfvDGmYHKH31zZhI_rn1T1KGG1PDqoC2cKvsNHr-lGt3S7fWzOR75ZfsLn2vHIv49WMMBA_vg_pub_CsUxJ0xOYM3j46EjMIYpbEK8-2sB4fyMQ']
INFO:oauth2client.client:Refreshing access_token
DEBUG:googleapiclient.discovery:URL being requested: GET https://www.googleapis.com/drive/v3/files/12xpxsV0IhJT0mPqxdO9dzsMjONwI7EcW?alt=media
WARNING:googleapiclient.discovery_cache:file_cache is unavailable when using oauth2client >= 4.0.0 or google-auth
Traceback (most recent call last):
  File "C:\Users\79069\AppData\Local\Programs\Python\Python39\lib\site-packages\googleapiclient\discovery_cache\file_cache.py", line 33, in <module>
    from oauth2client.contrib.locked_file import LockedFile
ModuleNotFoundError: No module named 'oauth2client.contrib.locked_file'

During handling of the above exception, another exception occurred:

Traceback (most recent call last):
  File "C:\Users\79069\AppData\Local\Programs\Python\Python39\lib\site-packages\googleapiclient\discovery_cache\file_cache.py", line 37, in <module>
    from oauth2client.locked_file import LockedFile
ModuleNotFoundError: No module named 'oauth2client.locked_file'

During handling of the above exception, another exception occurred:

Traceback (most recent call last):
  File "C:\Users\79069\AppData\Local\Programs\Python\Python39\lib\site-packages\googleapiclient\discovery_cache\__init__.py", line 44, in autodetect
    from . import file_cache
  File "C:\Users\79069\AppData\Local\Programs\Python\Python39\lib\site-packages\googleapiclient\discovery_cache\file_cache.py", line 40, in <module>
    raise ImportError(
ImportError: file_cache is unavailable when using oauth2client >= 4.0.0 or google-auth
DEBUG:googleapiclient.discovery:URL being requested: GET https://www.googleapis.com/discovery/v1/apis/drive/v3/rest
INFO:oauth2client.transport:Attempting refresh to obtain initial access_token
DEBUG:oauth2client.crypt:[b'eyJ0eXAiOiJKV1QiLCJhbGciOiJSUzI1NiIsImtpZCI6IjZiYzEzYmFjOTE0ZGZkNzliN2ZhOWQyODYxMzk5YzljZmY4OWFjNjcifQ', b'eyJhdWQiOiJodHRwczovL29hdXRoMi5nb29nbGVhcGlzLmNvbS90b2tlbiIsInNjb3BlIjoiaHR0cHM6Ly93d3cuZ29vZ2xlYXBpcy5jb20vYXV0aC9kcml2ZSIsImlhdCI6MTYxNDE2OTUyOCwiZXhwIjoxNjE0MTczMTI4LCJpc3MiOiJqdXN0LWFjY291bnRAdGVzdGFwaWFuZHNoZWV0cy5pYW0uZ3NlcnZpY2VhY2NvdW50LmNvbSJ9', b'sy1JrXiSxnws59fTbIzzUFYCuBNDyU7R1R24h_S75Xw81tnvM-j5MssM3mKV55oPUfYj_zlFjJUyjq1mwNqVrdQFWzQLGPONA6X7-53V-NHme3ea_AY-kqFsm0VQQ_XJpXCzfr_8_dt3hPSx5w5uPnevLlE_oXqwL3EJgpcMUdFULLZk055SCQIeOZRqMgy5qEoFsI1Obxt7cu2cCUAseQVDQFVC_Wqn1bbNMtzHXdTcC9qC64v2BNRZiLyInOd7ckwTjoyG6N9qLwUiq7u6S5M2uJI8dy0W8KpvNa_Vp1mGZm9ZTKJkXzrtbbSz0daWnGE_wGHS4Eup3MuF1Gfg2w']
INFO:oauth2client.client:Refreshing access_token
DEBUG:googleapiclient.discovery:URL being requested: POST https://www.googleapis.com/upload/drive/v3/files?fields=id&alt=json&uploadType=multipart
WARNING:googleapiclient.discovery_cache:file_cache is unavailable when using oauth2client >= 4.0.0 or google-auth
Traceback (most recent call last):
  File "C:\Users\79069\AppData\Local\Programs\Python\Python39\lib\site-packages\googleapiclient\discovery_cache\file_cache.py", line 33, in <module>
    from oauth2client.contrib.locked_file import LockedFile
ModuleNotFoundError: No module named 'oauth2client.contrib.locked_file'

During handling of the above exception, another exception occurred:

Traceback (most recent call last):
  File "C:\Users\79069\AppData\Local\Programs\Python\Python39\lib\site-packages\googleapiclient\discovery_cache\file_cache.py", line 37, in <module>
    from oauth2client.locked_file import LockedFile
ModuleNotFoundError: No module named 'oauth2client.locked_file'

During handling of the above exception, another exception occurred:

Traceback (most recent call last):
  File "C:\Users\79069\AppData\Local\Programs\Python\Python39\lib\site-packages\googleapiclient\discovery_cache\__init__.py", line 44, in autodetect
    from . import file_cache
  File "C:\Users\79069\AppData\Local\Programs\Python\Python39\lib\site-packages\googleapiclient\discovery_cache\file_cache.py", line 40, in <module>
    raise ImportError(
ImportError: file_cache is unavailable when using oauth2client >= 4.0.0 or google-auth
DEBUG:googleapiclient.discovery:URL being requested: GET https://www.googleapis.com/discovery/v1/apis/drive/v3/rest
INFO:oauth2client.transport:Attempting refresh to obtain initial access_token
DEBUG:oauth2client.crypt:[b'eyJ0eXAiOiJKV1QiLCJhbGciOiJSUzI1NiIsImtpZCI6IjZiYzEzYmFjOTE0ZGZkNzliN2ZhOWQyODYxMzk5YzljZmY4OWFjNjcifQ', b'eyJhdWQiOiJodHRwczovL29hdXRoMi5nb29nbGVhcGlzLmNvbS90b2tlbiIsInNjb3BlIjoiaHR0cHM6Ly93d3cuZ29vZ2xlYXBpcy5jb20vYXV0aC9kcml2ZSIsImlhdCI6MTYxNDE2OTU2OCwiZXhwIjoxNjE0MTczMTY4LCJpc3MiOiJqdXN0LWFjY291bnRAdGVzdGFwaWFuZHNoZWV0cy5pYW0uZ3NlcnZpY2VhY2NvdW50LmNvbSJ9', b'wx3JAjiM1yiNolvpj-YzcUig6tEi63DDOSeZixqnhvpGulnUqpmyN3iieuZZ2s7KKUy2ENzcziUDkR3KcJZHVWMuLOVpnWOIgoR4digVxUOsh-twLUTA7oLrlaOVEvd_PIOM5K7SsBXaS9IUEeGf1rO9gvmTqoHeHe8Yo8X3vzu-9dvpcaofdxHXCL-ZK1rthYRAVX9AF478zv-udkWmIn47BvaNJ1L3z1rZM23nHVQzEfYs6RF1Z37uJXZ2F1yEjCahAtcUIOI1PyIIEr2V5bkWmCdEelONzvwzQ6H3Fw-C_acrvpZXOCZJqdlq4po8jeu0Dc6-r4usgpSGTL6fDg']
INFO:oauth2client.client:Refreshing access_token
DEBUG:googleapiclient.discovery:URL being requested: GET https://www.googleapis.com/drive/v3/files/1-GLrj8pJ11Y72fqamsqbb1I3X7t680Wb?alt=media
WARNING:googleapiclient.discovery_cache:file_cache is unavailable when using oauth2client >= 4.0.0 or google-auth
Traceback (most recent call last):
  File "C:\Users\79069\AppData\Local\Programs\Python\Python39\lib\site-packages\googleapiclient\discovery_cache\file_cache.py", line 33, in <module>
    from oauth2client.contrib.locked_file import LockedFile
ModuleNotFoundError: No module named 'oauth2client.contrib.locked_file'

During handling of the above exception, another exception occurred:

Traceback (most recent call last):
  File "C:\Users\79069\AppData\Local\Programs\Python\Python39\lib\site-packages\googleapiclient\discovery_cache\file_cache.py", line 37, in <module>
    from oauth2client.locked_file import LockedFile
ModuleNotFoundError: No module named 'oauth2client.locked_file'

During handling of the above exception, another exception occurred:

Traceback (most recent call last):
  File "C:\Users\79069\AppData\Local\Programs\Python\Python39\lib\site-packages\googleapiclient\discovery_cache\__init__.py", line 44, in autodetect
    from . import file_cache
  File "C:\Users\79069\AppData\Local\Programs\Python\Python39\lib\site-packages\googleapiclient\discovery_cache\file_cache.py", line 40, in <module>
    raise ImportError(
ImportError: file_cache is unavailable when using oauth2client >= 4.0.0 or google-auth
DEBUG:googleapiclient.discovery:URL being requested: GET https://www.googleapis.com/discovery/v1/apis/drive/v3/rest
INFO:oauth2client.transport:Attempting refresh to obtain initial access_token
DEBUG:oauth2client.crypt:[b'eyJ0eXAiOiJKV1QiLCJhbGciOiJSUzI1NiIsImtpZCI6IjZiYzEzYmFjOTE0ZGZkNzliN2ZhOWQyODYxMzk5YzljZmY4OWFjNjcifQ', b'eyJhdWQiOiJodHRwczovL29hdXRoMi5nb29nbGVhcGlzLmNvbS90b2tlbiIsInNjb3BlIjoiaHR0cHM6Ly93d3cuZ29vZ2xlYXBpcy5jb20vYXV0aC9kcml2ZSIsImlhdCI6MTYxNDE2OTY3NywiZXhwIjoxNjE0MTczMjc3LCJpc3MiOiJqdXN0LWFjY291bnRAdGVzdGFwaWFuZHNoZWV0cy5pYW0uZ3NlcnZpY2VhY2NvdW50LmNvbSJ9', b'fLk9S06tufwcndX3XK29P_KhYY_qR1IccM52z6_4YvLTaQizkrW1Hxjiwu-g-XaUmPVsmk_oYlcnNQo5Cvr-EJA7DA-B8m7hSDB65KAxVEdHdnGT9HxVFuLEQt1BsoknEjOXYC0rMZxkvQNeG6rz9fnP6LkpsMKOIugHUtAJjq8_5eFYNF26Wkk8FiO2jWyXXTDy6f0D5dUUe3kfrPKdwA3I4ZJub85CxJaw74ac-7Ee5Kpc58HILdFdbbhZZ-w_vw4huOHq4e0l2Nkx0PGsw9JUUNPChrFgrxg_Zz8s73ATGifE69Y2uLxternU9H8wmoBr--KYKQRIakmdiaD-oA']
INFO:oauth2client.client:Refreshing access_token
DEBUG:googleapiclient.discovery:URL being requested: POST https://www.googleapis.com/upload/drive/v3/files?fields=id&alt=json&uploadType=multipart
WARNING:googleapiclient.discovery_cache:file_cache is unavailable when using oauth2client >= 4.0.0 or google-auth
Traceback (most recent call last):
  File "C:\Users\79069\AppData\Local\Programs\Python\Python39\lib\site-packages\googleapiclient\discovery_cache\file_cache.py", line 33, in <module>
    from oauth2client.contrib.locked_file import LockedFile
ModuleNotFoundError: No module named 'oauth2client.contrib.locked_file'

During handling of the above exception, another exception occurred:

Traceback (most recent call last):
  File "C:\Users\79069\AppData\Local\Programs\Python\Python39\lib\site-packages\googleapiclient\discovery_cache\file_cache.py", line 37, in <module>
    from oauth2client.locked_file import LockedFile
ModuleNotFoundError: No module named 'oauth2client.locked_file'

During handling of the above exception, another exception occurred:

Traceback (most recent call last):
  File "C:\Users\79069\AppData\Local\Programs\Python\Python39\lib\site-packages\googleapiclient\discovery_cache\__init__.py", line 44, in autodetect
    from . import file_cache
  File "C:\Users\79069\AppData\Local\Programs\Python\Python39\lib\site-packages\googleapiclient\discovery_cache\file_cache.py", line 40, in <module>
    raise ImportError(
ImportError: file_cache is unavailable when using oauth2client >= 4.0.0 or google-auth
DEBUG:googleapiclient.discovery:URL being requested: GET https://www.googleapis.com/discovery/v1/apis/drive/v3/rest
INFO:oauth2client.transport:Attempting refresh to obtain initial access_token
DEBUG:oauth2client.crypt:[b'eyJ0eXAiOiJKV1QiLCJhbGciOiJSUzI1NiIsImtpZCI6IjZiYzEzYmFjOTE0ZGZkNzliN2ZhOWQyODYxMzk5YzljZmY4OWFjNjcifQ', b'eyJhdWQiOiJodHRwczovL29hdXRoMi5nb29nbGVhcGlzLmNvbS90b2tlbiIsInNjb3BlIjoiaHR0cHM6Ly93d3cuZ29vZ2xlYXBpcy5jb20vYXV0aC9kcml2ZSIsImlhdCI6MTYxNDE2OTc5MCwiZXhwIjoxNjE0MTczMzkwLCJpc3MiOiJqdXN0LWFjY291bnRAdGVzdGFwaWFuZHNoZWV0cy5pYW0uZ3NlcnZpY2VhY2NvdW50LmNvbSJ9', b'JspKdCjNWXzQNO5_aezVuw2k9JWNCQ84YeOpRSvxEfn1z-M92UN7Dxt-UoG1ddGdBtifCJxou2tZnP8nYJIpoi0P67sMh0y3q7WCgi96VbtGRl0hlSzRYeief77_H5SIe6m67JKM53N-0g-ii0TeFmwvVpXP1LW13TTqmOSCkDXufecvyUZHk0AouyRowlXgwm7pD30Fjf02ScEcufzaKxR15Bg4Tzt1ekmtPVcLAK5akkU5WAFQJk-z8AW-IsFg_2bh-tqSYiVJEgUeT4vmmC9wH2rZbSkMG8G2A5zDismojhQf_aUNy_iuG2wjpmeQqzh2O94MEIfITMQ_wZn2fg']
INFO:oauth2client.client:Refreshing access_token
DEBUG:googleapiclient.discovery:URL being requested: GET https://www.googleapis.com/drive/v3/files/1-GLrj8pJ11Y72fqamsqbb1I3X7t680Wb?alt=media
WARNING:googleapiclient.discovery_cache:file_cache is unavailable when using oauth2client >= 4.0.0 or google-auth
Traceback (most recent call last):
  File "C:\Users\79069\AppData\Local\Programs\Python\Python39\lib\site-packages\googleapiclient\discovery_cache\file_cache.py", line 33, in <module>
    from oauth2client.contrib.locked_file import LockedFile
ModuleNotFoundError: No module named 'oauth2client.contrib.locked_file'

During handling of the above exception, another exception occurred:

Traceback (most recent call last):
  File "C:\Users\79069\AppData\Local\Programs\Python\Python39\lib\site-packages\googleapiclient\discovery_cache\file_cache.py", line 37, in <module>
    from oauth2client.locked_file import LockedFile
ModuleNotFoundError: No module named 'oauth2client.locked_file'

During handling of the above exception, another exception occurred:

Traceback (most recent call last):
  File "C:\Users\79069\AppData\Local\Programs\Python\Python39\lib\site-packages\googleapiclient\discovery_cache\__init__.py", line 44, in autodetect
    from . import file_cache
  File "C:\Users\79069\AppData\Local\Programs\Python\Python39\lib\site-packages\googleapiclient\discovery_cache\file_cache.py", line 40, in <module>
    raise ImportError(
ImportError: file_cache is unavailable when using oauth2client >= 4.0.0 or google-auth
DEBUG:googleapiclient.discovery:URL being requested: GET https://www.googleapis.com/discovery/v1/apis/drive/v3/rest
INFO:oauth2client.transport:Attempting refresh to obtain initial access_token
DEBUG:oauth2client.crypt:[b'eyJ0eXAiOiJKV1QiLCJhbGciOiJSUzI1NiIsImtpZCI6IjZiYzEzYmFjOTE0ZGZkNzliN2ZhOWQyODYxMzk5YzljZmY4OWFjNjcifQ', b'eyJhdWQiOiJodHRwczovL29hdXRoMi5nb29nbGVhcGlzLmNvbS90b2tlbiIsInNjb3BlIjoiaHR0cHM6Ly93d3cuZ29vZ2xlYXBpcy5jb20vYXV0aC9kcml2ZSIsImlhdCI6MTYxNDE2OTc5NiwiZXhwIjoxNjE0MTczMzk2LCJpc3MiOiJqdXN0LWFjY291bnRAdGVzdGFwaWFuZHNoZWV0cy5pYW0uZ3NlcnZpY2VhY2NvdW50LmNvbSJ9', b'I4KChhXsIYiPCncMF1z3Mjs-B_WQ7ISPUxbfZOVUrP9_avizTBmL3A_OAuq5DjTj6i8xkONul8AKQCENIEnGKHhbD4ayClNaMNZ2HEpKQh-DLpZj9WmkVIGWgh9KEjy6YHvUF9oKPZJEAzr8nfSBvrVPSVLQt0qfwJ0iVGYZjthD1iqzVVMNMWGlw9s8aq4cu5H5mcuC4KEdAQ-202I2_GwoX9bZV-VH7d3l6udcEadkaMt3H1KHMNg4j2EkLFT7r0uTogJeUiJ4_99rOfhEAFIOuZn5DD0Uq9GtaD2w4Z_jI7hmWUsJiO0b8zPFT7AGlMEBVVSSwj45wvQoT1oADg']
INFO:oauth2client.client:Refreshing access_token
DEBUG:googleapiclient.discovery:URL being requested: POST https://www.googleapis.com/upload/drive/v3/files?fields=id&alt=json&uploadType=multipart
WARNING:googleapiclient.discovery_cache:file_cache is unavailable when using oauth2client >= 4.0.0 or google-auth
Traceback (most recent call last):
  File "C:\Users\79069\AppData\Local\Programs\Python\Python39\lib\site-packages\googleapiclient\discovery_cache\file_cache.py", line 33, in <module>
    from oauth2client.contrib.locked_file import LockedFile
ModuleNotFoundError: No module named 'oauth2client.contrib.locked_file'

During handling of the above exception, another exception occurred:

Traceback (most recent call last):
  File "C:\Users\79069\AppData\Local\Programs\Python\Python39\lib\site-packages\googleapiclient\discovery_cache\file_cache.py", line 37, in <module>
    from oauth2client.locked_file import LockedFile
ModuleNotFoundError: No module named 'oauth2client.locked_file'

During handling of the above exception, another exception occurred:

Traceback (most recent call last):
  File "C:\Users\79069\AppData\Local\Programs\Python\Python39\lib\site-packages\googleapiclient\discovery_cache\__init__.py", line 44, in autodetect
    from . import file_cache
  File "C:\Users\79069\AppData\Local\Programs\Python\Python39\lib\site-packages\googleapiclient\discovery_cache\file_cache.py", line 40, in <module>
    raise ImportError(
ImportError: file_cache is unavailable when using oauth2client >= 4.0.0 or google-auth
DEBUG:googleapiclient.discovery:URL being requested: GET https://www.googleapis.com/discovery/v1/apis/drive/v3/rest
INFO:oauth2client.transport:Attempting refresh to obtain initial access_token
DEBUG:oauth2client.crypt:[b'eyJ0eXAiOiJKV1QiLCJhbGciOiJSUzI1NiIsImtpZCI6IjZiYzEzYmFjOTE0ZGZkNzliN2ZhOWQyODYxMzk5YzljZmY4OWFjNjcifQ', b'eyJhdWQiOiJodHRwczovL29hdXRoMi5nb29nbGVhcGlzLmNvbS90b2tlbiIsInNjb3BlIjoiaHR0cHM6Ly93d3cuZ29vZ2xlYXBpcy5jb20vYXV0aC9kcml2ZSIsImlhdCI6MTYxNDE2OTgxOSwiZXhwIjoxNjE0MTczNDE5LCJpc3MiOiJqdXN0LWFjY291bnRAdGVzdGFwaWFuZHNoZWV0cy5pYW0uZ3NlcnZpY2VhY2NvdW50LmNvbSJ9', b'2Id3S0hpMg8X84WlQdqC82U_5r2zWMKF5hCGbGa2xCvTQHEDSYJyeeWHxAncku3B50J-UeF8mdS_cUkM4leMSfofTo9ZC0iJSxs6FJFHM2HrqCZowjPz1O-mgWoTVNwCpy0fk0lfcsrAXakyqGHSen3ywDtuSxePQ09Wb9UCOHCXpSwP0nD4N2INSqZweD5Xd__mzgyf99hMOu5lBjaW_MBjy2ww2_PC45VHIW2xYYYsmvHW_5JB19nZnFgX-NIJeydzYqpLyCw7vDTptvPYhUkiOqqn4a315VoyYe31l-SF2GyWCLPb3SmuMLMRH85_4LAAtQpDx2_jFGslnarTnA']
INFO:oauth2client.client:Refreshing access_token
DEBUG:googleapiclient.discovery:URL being requested: GET https://www.googleapis.com/drive/v3/files/1-GLrj8pJ11Y72fqamsqbb1I3X7t680Wb?alt=media
WARNING:googleapiclient.discovery_cache:file_cache is unavailable when using oauth2client >= 4.0.0 or google-auth
Traceback (most recent call last):
  File "C:\Users\79069\AppData\Local\Programs\Python\Python39\lib\site-packages\googleapiclient\discovery_cache\file_cache.py", line 33, in <module>
    from oauth2client.contrib.locked_file import LockedFile
ModuleNotFoundError: No module named 'oauth2client.contrib.locked_file'

During handling of the above exception, another exception occurred:

Traceback (most recent call last):
  File "C:\Users\79069\AppData\Local\Programs\Python\Python39\lib\site-packages\googleapiclient\discovery_cache\file_cache.py", line 37, in <module>
    from oauth2client.locked_file import LockedFile
ModuleNotFoundError: No module named 'oauth2client.locked_file'

During handling of the above exception, another exception occurred:

Traceback (most recent call last):
  File "C:\Users\79069\AppData\Local\Programs\Python\Python39\lib\site-packages\googleapiclient\discovery_cache\__init__.py", line 44, in autodetect
    from . import file_cache
  File "C:\Users\79069\AppData\Local\Programs\Python\Python39\lib\site-packages\googleapiclient\discovery_cache\file_cache.py", line 40, in <module>
    raise ImportError(
ImportError: file_cache is unavailable when using oauth2client >= 4.0.0 or google-auth
DEBUG:googleapiclient.discovery:URL being requested: GET https://www.googleapis.com/discovery/v1/apis/drive/v3/rest
INFO:oauth2client.transport:Attempting refresh to obtain initial access_token
DEBUG:oauth2client.crypt:[b'eyJ0eXAiOiJKV1QiLCJhbGciOiJSUzI1NiIsImtpZCI6IjZiYzEzYmFjOTE0ZGZkNzliN2ZhOWQyODYxMzk5YzljZmY4OWFjNjcifQ', b'eyJhdWQiOiJodHRwczovL29hdXRoMi5nb29nbGVhcGlzLmNvbS90b2tlbiIsInNjb3BlIjoiaHR0cHM6Ly93d3cuZ29vZ2xlYXBpcy5jb20vYXV0aC9kcml2ZSIsImlhdCI6MTYxNDE2OTgyNiwiZXhwIjoxNjE0MTczNDI2LCJpc3MiOiJqdXN0LWFjY291bnRAdGVzdGFwaWFuZHNoZWV0cy5pYW0uZ3NlcnZpY2VhY2NvdW50LmNvbSJ9', b'eN056WNJYRS33_n4SNHnpvjawKANx2wkx1cNyHXYbmfZCCZ1zdJ786cBcfg4SlcQkhedUPUYAeF1icqlmemh1_GjLcSC6liUBXX99GchC7bN1EwUIF-ZlIVrcyPtX4hpFskQzrunFIamys5L8REApr-AEkxCFBST7rrcAvG1fB_j5ifw_QOWkU-it3bjPLZYBxVZdBlku-pAwcIKhDAc787m4M0cor-oEW-0Dc67pEsoXWzSOB81iFOdGoatE0mEBeF_KpzDijGHbVmloZ61lAq5iGqompj1UmA2iMRT2yhXkHOwUuvhp3NGqAhI5sGmHRa22flikD9m2Vg07qwqQQ']
INFO:oauth2client.client:Refreshing access_token
DEBUG:googleapiclient.discovery:URL being requested: POST https://www.googleapis.com/upload/drive/v3/files?fields=id&alt=json&uploadType=multipart
WARNING:googleapiclient.discovery_cache:file_cache is unavailable when using oauth2client >= 4.0.0 or google-auth
Traceback (most recent call last):
  File "C:\Users\79069\AppData\Local\Programs\Python\Python39\lib\site-packages\googleapiclient\discovery_cache\file_cache.py", line 33, in <module>
    from oauth2client.contrib.locked_file import LockedFile
ModuleNotFoundError: No module named 'oauth2client.contrib.locked_file'

During handling of the above exception, another exception occurred:

Traceback (most recent call last):
  File "C:\Users\79069\AppData\Local\Programs\Python\Python39\lib\site-packages\googleapiclient\discovery_cache\file_cache.py", line 37, in <module>
    from oauth2client.locked_file import LockedFile
ModuleNotFoundError: No module named 'oauth2client.locked_file'

During handling of the above exception, another exception occurred:

Traceback (most recent call last):
  File "C:\Users\79069\AppData\Local\Programs\Python\Python39\lib\site-packages\googleapiclient\discovery_cache\__init__.py", line 44, in autodetect
    from . import file_cache
  File "C:\Users\79069\AppData\Local\Programs\Python\Python39\lib\site-packages\googleapiclient\discovery_cache\file_cache.py", line 40, in <module>
    raise ImportError(
ImportError: file_cache is unavailable when using oauth2client >= 4.0.0 or google-auth
DEBUG:googleapiclient.discovery:URL being requested: GET https://www.googleapis.com/discovery/v1/apis/drive/v3/rest
INFO:oauth2client.transport:Attempting refresh to obtain initial access_token
DEBUG:oauth2client.crypt:[b'eyJ0eXAiOiJKV1QiLCJhbGciOiJSUzI1NiIsImtpZCI6IjZiYzEzYmFjOTE0ZGZkNzliN2ZhOWQyODYxMzk5YzljZmY4OWFjNjcifQ', b'eyJhdWQiOiJodHRwczovL29hdXRoMi5nb29nbGVhcGlzLmNvbS90b2tlbiIsInNjb3BlIjoiaHR0cHM6Ly93d3cuZ29vZ2xlYXBpcy5jb20vYXV0aC9kcml2ZSIsImlhdCI6MTYxNDE2OTk2MiwiZXhwIjoxNjE0MTczNTYyLCJpc3MiOiJqdXN0LWFjY291bnRAdGVzdGFwaWFuZHNoZWV0cy5pYW0uZ3NlcnZpY2VhY2NvdW50LmNvbSJ9', b'O0hrX_rl10TMj8nvd0fCykcByOcBQfXPOSib4t4b-wDK45I71cb97S9lnPqt3dAxq4YWTh7uc0thbLf8dIuxigIIjTxLlL_cHMQdiOQvYcPsp8fzZcX5rdbb2GgXH0tVLKiSVktqZ7iRbxHYSj1CIHGhaq-1id0NJw559UsQdPQ7zz04FtvvV-wIL3AFshgARdUxyr24vhIVKGoP4ZNuVjS62t24TzF_r4iWgDRI9GNkx3KjY8Obji22IKaD1p92E0S4MJk6MYGjd6hbV6ninWCfXypFh7BLVq2dtcFwIl0728F5CsztFITaGPIAmyopV4lMOA9-OQN3WrRqis1N4Q']
INFO:oauth2client.client:Refreshing access_token
DEBUG:googleapiclient.discovery:URL being requested: GET https://www.googleapis.com/drive/v3/files/1-GLrj8pJ11Y72fqamsqbb1I3X7t680Wb?alt=media
WARNING:googleapiclient.discovery_cache:file_cache is unavailable when using oauth2client >= 4.0.0 or google-auth
Traceback (most recent call last):
  File "C:\Users\79069\AppData\Local\Programs\Python\Python39\lib\site-packages\googleapiclient\discovery_cache\file_cache.py", line 33, in <module>
    from oauth2client.contrib.locked_file import LockedFile
ModuleNotFoundError: No module named 'oauth2client.contrib.locked_file'

During handling of the above exception, another exception occurred:

Traceback (most recent call last):
  File "C:\Users\79069\AppData\Local\Programs\Python\Python39\lib\site-packages\googleapiclient\discovery_cache\file_cache.py", line 37, in <module>
    from oauth2client.locked_file import LockedFile
ModuleNotFoundError: No module named 'oauth2client.locked_file'

During handling of the above exception, another exception occurred:

Traceback (most recent call last):
  File "C:\Users\79069\AppData\Local\Programs\Python\Python39\lib\site-packages\googleapiclient\discovery_cache\__init__.py", line 44, in autodetect
    from . import file_cache
  File "C:\Users\79069\AppData\Local\Programs\Python\Python39\lib\site-packages\googleapiclient\discovery_cache\file_cache.py", line 40, in <module>
    raise ImportError(
ImportError: file_cache is unavailable when using oauth2client >= 4.0.0 or google-auth
DEBUG:googleapiclient.discovery:URL being requested: GET https://www.googleapis.com/discovery/v1/apis/drive/v3/rest
INFO:oauth2client.transport:Attempting refresh to obtain initial access_token
DEBUG:oauth2client.crypt:[b'eyJ0eXAiOiJKV1QiLCJhbGciOiJSUzI1NiIsImtpZCI6IjZiYzEzYmFjOTE0ZGZkNzliN2ZhOWQyODYxMzk5YzljZmY4OWFjNjcifQ', b'eyJhdWQiOiJodHRwczovL29hdXRoMi5nb29nbGVhcGlzLmNvbS90b2tlbiIsInNjb3BlIjoiaHR0cHM6Ly93d3cuZ29vZ2xlYXBpcy5jb20vYXV0aC9kcml2ZSIsImlhdCI6MTYxNDE2OTk2OCwiZXhwIjoxNjE0MTczNTY4LCJpc3MiOiJqdXN0LWFjY291bnRAdGVzdGFwaWFuZHNoZWV0cy5pYW0uZ3NlcnZpY2VhY2NvdW50LmNvbSJ9', b'GS9JHKPOiMZyMba06dM9rHNfMs32zD4HDr43Tf40T43xWXl-6Aj3W1Xe4LMMJyrAj8V1Q94sAo61YasZRGqTkVBcTfnhSt7H0xgBe1bJ6ml5cNsw6cw84OKYLi4FIcW3yf90hysn4dBBTiy3_LMJwg4cst9db1QQB2Az7jazefRYpajR7oxaFDdmEZ0jGOGCYwfHRhVs46eRY5SdupCX33XCngHqVkL3vHeJfL6miWVG1XXS0R6GMsIqpWygSA4DUYPKvgtY26JhNMKuS76qfrNalZ1J_WWKWssKVFq2-7z2KRqQ38NDYvbYWU-x6f0nKwovS5z-anxWF9uCAJvHCw']
INFO:oauth2client.client:Refreshing access_token
DEBUG:googleapiclient.discovery:URL being requested: POST https://www.googleapis.com/upload/drive/v3/files?fields=id&alt=json&uploadType=multipart
WARNING:googleapiclient.discovery_cache:file_cache is unavailable when using oauth2client >= 4.0.0 or google-auth
Traceback (most recent call last):
  File "C:\Users\79069\AppData\Local\Programs\Python\Python39\lib\site-packages\googleapiclient\discovery_cache\file_cache.py", line 33, in <module>
    from oauth2client.contrib.locked_file import LockedFile
ModuleNotFoundError: No module named 'oauth2client.contrib.locked_file'

During handling of the above exception, another exception occurred:

Traceback (most recent call last):
  File "C:\Users\79069\AppData\Local\Programs\Python\Python39\lib\site-packages\googleapiclient\discovery_cache\file_cache.py", line 37, in <module>
    from oauth2client.locked_file import LockedFile
ModuleNotFoundError: No module named 'oauth2client.locked_file'

During handling of the above exception, another exception occurred:

Traceback (most recent call last):
  File "C:\Users\79069\AppData\Local\Programs\Python\Python39\lib\site-packages\googleapiclient\discovery_cache\__init__.py", line 44, in autodetect
    from . import file_cache
  File "C:\Users\79069\AppData\Local\Programs\Python\Python39\lib\site-packages\googleapiclient\discovery_cache\file_cache.py", line 40, in <module>
    raise ImportError(
ImportError: file_cache is unavailable when using oauth2client >= 4.0.0 or google-auth
DEBUG:googleapiclient.discovery:URL being requested: GET https://www.googleapis.com/discovery/v1/apis/drive/v3/rest
INFO:oauth2client.transport:Attempting refresh to obtain initial access_token
DEBUG:oauth2client.crypt:[b'eyJ0eXAiOiJKV1QiLCJhbGciOiJSUzI1NiIsImtpZCI6IjZiYzEzYmFjOTE0ZGZkNzliN2ZhOWQyODYxMzk5YzljZmY4OWFjNjcifQ', b'eyJhdWQiOiJodHRwczovL29hdXRoMi5nb29nbGVhcGlzLmNvbS90b2tlbiIsInNjb3BlIjoiaHR0cHM6Ly93d3cuZ29vZ2xlYXBpcy5jb20vYXV0aC9kcml2ZSIsImlhdCI6MTYxNDE3MDA0OSwiZXhwIjoxNjE0MTczNjQ5LCJpc3MiOiJqdXN0LWFjY291bnRAdGVzdGFwaWFuZHNoZWV0cy5pYW0uZ3NlcnZpY2VhY2NvdW50LmNvbSJ9', b'5FlxlhQVKRP3tjDAoxpI7SgaETEwKtICJON8oCvAbui3YhTX9morz4HIgxulBjUiL-lrC72GhZWmXxo_wPx0zq3pcAZ-8Mq2bY6f6HixMXcZYbIf0Tj1je6LTfeMWxOmGVy5gcEaCF3l4SFgTGpg-bGZdenPvhCpWg81yNKjWuj1glnJg0bW7J6hOorUWHf-yuigGg-gyPJ-EhRfdO3Q7DAvSn4YEVxmQTuh6T5D1oiu14SzWCNNsq0P-V6CpDpZwZvmbMlEHqT_0WOl3tr9pR4IHLSDGdamyaDtqX3WUu_uX15dtr7QC5DoeyM4hi31bPH89cYe02hmXez4EZLmVg']
INFO:oauth2client.client:Refreshing access_token
DEBUG:googleapiclient.discovery:URL being requested: GET https://www.googleapis.com/drive/v3/files/12xpxsV0IhJT0mPqxdO9dzsMjONwI7EcW?alt=media
WARNING:googleapiclient.discovery_cache:file_cache is unavailable when using oauth2client >= 4.0.0 or google-auth
Traceback (most recent call last):
  File "C:\Users\79069\AppData\Local\Programs\Python\Python39\lib\site-packages\googleapiclient\discovery_cache\file_cache.py", line 33, in <module>
    from oauth2client.contrib.locked_file import LockedFile
ModuleNotFoundError: No module named 'oauth2client.contrib.locked_file'

During handling of the above exception, another exception occurred:

Traceback (most recent call last):
  File "C:\Users\79069\AppData\Local\Programs\Python\Python39\lib\site-packages\googleapiclient\discovery_cache\file_cache.py", line 37, in <module>
    from oauth2client.locked_file import LockedFile
ModuleNotFoundError: No module named 'oauth2client.locked_file'

During handling of the above exception, another exception occurred:

Traceback (most recent call last):
  File "C:\Users\79069\AppData\Local\Programs\Python\Python39\lib\site-packages\googleapiclient\discovery_cache\__init__.py", line 44, in autodetect
    from . import file_cache
  File "C:\Users\79069\AppData\Local\Programs\Python\Python39\lib\site-packages\googleapiclient\discovery_cache\file_cache.py", line 40, in <module>
    raise ImportError(
ImportError: file_cache is unavailable when using oauth2client >= 4.0.0 or google-auth
DEBUG:googleapiclient.discovery:URL being requested: GET https://www.googleapis.com/discovery/v1/apis/drive/v3/rest
INFO:oauth2client.transport:Attempting refresh to obtain initial access_token
DEBUG:oauth2client.crypt:[b'eyJ0eXAiOiJKV1QiLCJhbGciOiJSUzI1NiIsImtpZCI6IjZiYzEzYmFjOTE0ZGZkNzliN2ZhOWQyODYxMzk5YzljZmY4OWFjNjcifQ', b'eyJhdWQiOiJodHRwczovL29hdXRoMi5nb29nbGVhcGlzLmNvbS90b2tlbiIsInNjb3BlIjoiaHR0cHM6Ly93d3cuZ29vZ2xlYXBpcy5jb20vYXV0aC9kcml2ZSIsImlhdCI6MTYxNDE3MDA1NywiZXhwIjoxNjE0MTczNjU3LCJpc3MiOiJqdXN0LWFjY291bnRAdGVzdGFwaWFuZHNoZWV0cy5pYW0uZ3NlcnZpY2VhY2NvdW50LmNvbSJ9', b'NJaiBNzT3URVvKpoOUlptshrMLAb6mmTyDaLeLO9x6bHFVgpV_zo_Wzh9dU_UTjZ5d6nGj_MUiwcm90E_A5Kt234Uf0lr-09T7AWe5KDexWKFovn2CeD-dWgrxyt2TSTjgROhBe3i74y51z6GI7VLjBEpN-uC-s-DDB2Cw9ZUN6a49TvIkMiRlmcf7SBQygChATDX4IhQjb00ITgKFSwlG8qPA_gcAAQuggv2dXzSy3An2gwSyX2Usx2ZKtS6uAMG1hAwJEnpoL27GXfxYHvqPoMU6LTiVnG4m4jU4GJqlSR1VLZ-YvQSZz1CaDy3JOYUB51ypugYMBBuNXL0jsmIQ']
INFO:oauth2client.client:Refreshing access_token
DEBUG:googleapiclient.discovery:URL being requested: POST https://www.googleapis.com/upload/drive/v3/files?fields=id&alt=json&uploadType=multipart
WARNING:googleapiclient.discovery_cache:file_cache is unavailable when using oauth2client >= 4.0.0 or google-auth
Traceback (most recent call last):
  File "C:\Users\79069\AppData\Local\Programs\Python\Python39\lib\site-packages\googleapiclient\discovery_cache\file_cache.py", line 33, in <module>
    from oauth2client.contrib.locked_file import LockedFile
ModuleNotFoundError: No module named 'oauth2client.contrib.locked_file'

During handling of the above exception, another exception occurred:

Traceback (most recent call last):
  File "C:\Users\79069\AppData\Local\Programs\Python\Python39\lib\site-packages\googleapiclient\discovery_cache\file_cache.py", line 37, in <module>
    from oauth2client.locked_file import LockedFile
ModuleNotFoundError: No module named 'oauth2client.locked_file'

During handling of the above exception, another exception occurred:

Traceback (most recent call last):
  File "C:\Users\79069\AppData\Local\Programs\Python\Python39\lib\site-packages\googleapiclient\discovery_cache\__init__.py", line 44, in autodetect
    from . import file_cache
  File "C:\Users\79069\AppData\Local\Programs\Python\Python39\lib\site-packages\googleapiclient\discovery_cache\file_cache.py", line 40, in <module>
    raise ImportError(
ImportError: file_cache is unavailable when using oauth2client >= 4.0.0 or google-auth
DEBUG:googleapiclient.discovery:URL being requested: GET https://www.googleapis.com/discovery/v1/apis/drive/v3/rest
INFO:oauth2client.transport:Attempting refresh to obtain initial access_token
DEBUG:oauth2client.crypt:[b'eyJ0eXAiOiJKV1QiLCJhbGciOiJSUzI1NiIsImtpZCI6IjZiYzEzYmFjOTE0ZGZkNzliN2ZhOWQyODYxMzk5YzljZmY4OWFjNjcifQ', b'eyJhdWQiOiJodHRwczovL29hdXRoMi5nb29nbGVhcGlzLmNvbS90b2tlbiIsInNjb3BlIjoiaHR0cHM6Ly93d3cuZ29vZ2xlYXBpcy5jb20vYXV0aC9kcml2ZSIsImlhdCI6MTYxNDE3MDE5NCwiZXhwIjoxNjE0MTczNzk0LCJpc3MiOiJqdXN0LWFjY291bnRAdGVzdGFwaWFuZHNoZWV0cy5pYW0uZ3NlcnZpY2VhY2NvdW50LmNvbSJ9', b'd6aY-UftBz_9PepuVoXm1JF74Y7_NSztpaxV1-e2ZgC7_qHYpl5SYMjaRw2-kwSPHWZPstXfnMlUb2YKw11uFWZi-iwDZiXyZ31nWolXTKrQTPSst9BTCMw61Jd0cZRkoq6RnKXMChIuktpBqdHlADznmxBprzKmAkM0ZPEw6DdFRnL_iQjw-D6-f1jdI1PnLHkz-5_9I8Z0_hZR_Z_DlWzZSfmhQ9LwAbZbt7-L8bzRiz4BRvBCggTh5vIP6BaTgj4Zq8MA4_hNCL23E_Ut09MRAp5TyFXqE9rzpYhGfnlofWy5I_ULZcW2uWmrEjVtlg23i1CxyxJ1g2pBhPpLbQ']
INFO:oauth2client.client:Refreshing access_token
DEBUG:googleapiclient.discovery:URL being requested: GET https://www.googleapis.com/drive/v3/files/12xpxsV0IhJT0mPqxdO9dzsMjONwI7EcW?alt=media
WARNING:googleapiclient.discovery_cache:file_cache is unavailable when using oauth2client >= 4.0.0 or google-auth
Traceback (most recent call last):
  File "C:\Users\79069\AppData\Local\Programs\Python\Python39\lib\site-packages\googleapiclient\discovery_cache\file_cache.py", line 33, in <module>
    from oauth2client.contrib.locked_file import LockedFile
ModuleNotFoundError: No module named 'oauth2client.contrib.locked_file'

During handling of the above exception, another exception occurred:

Traceback (most recent call last):
  File "C:\Users\79069\AppData\Local\Programs\Python\Python39\lib\site-packages\googleapiclient\discovery_cache\file_cache.py", line 37, in <module>
    from oauth2client.locked_file import LockedFile
ModuleNotFoundError: No module named 'oauth2client.locked_file'

During handling of the above exception, another exception occurred:

Traceback (most recent call last):
  File "C:\Users\79069\AppData\Local\Programs\Python\Python39\lib\site-packages\googleapiclient\discovery_cache\__init__.py", line 44, in autodetect
    from . import file_cache
  File "C:\Users\79069\AppData\Local\Programs\Python\Python39\lib\site-packages\googleapiclient\discovery_cache\file_cache.py", line 40, in <module>
    raise ImportError(
ImportError: file_cache is unavailable when using oauth2client >= 4.0.0 or google-auth
DEBUG:googleapiclient.discovery:URL being requested: GET https://www.googleapis.com/discovery/v1/apis/drive/v3/rest
INFO:oauth2client.transport:Attempting refresh to obtain initial access_token
DEBUG:oauth2client.crypt:[b'eyJ0eXAiOiJKV1QiLCJhbGciOiJSUzI1NiIsImtpZCI6IjZiYzEzYmFjOTE0ZGZkNzliN2ZhOWQyODYxMzk5YzljZmY4OWFjNjcifQ', b'eyJhdWQiOiJodHRwczovL29hdXRoMi5nb29nbGVhcGlzLmNvbS90b2tlbiIsInNjb3BlIjoiaHR0cHM6Ly93d3cuZ29vZ2xlYXBpcy5jb20vYXV0aC9kcml2ZSIsImlhdCI6MTYxNDE3MDIwMSwiZXhwIjoxNjE0MTczODAxLCJpc3MiOiJqdXN0LWFjY291bnRAdGVzdGFwaWFuZHNoZWV0cy5pYW0uZ3NlcnZpY2VhY2NvdW50LmNvbSJ9', b'aUhlwLoqzwksUY2CO-OUZwLioCnQNub8AGAUB5eJMN6JXTfxPCwQoI12XgFbU8Y2cA2bWctNJ-1uyfZQBEQVt_DEsvbUjqBfnXNoLFuXyCCSJm3yKBnn_ql9a5lhNynNVp_ejyzA6wuRDdEpAvxG1sxW63HxZbMLMqaHcsB3bitT8kcs964UIF3P2Dcmv_2if1T-ElVx7G9YzjkwJtGY8L5nsY8W3vSK-ylqlD-ZC2j87w5e301h5YH3dGi6UY-a-qGZ5HwXQVU_YzTasI7Q1Vw908ZRAVN6jCFHiWKIqpoipPDdoqre8gJZFWg_GGhGh2vwieDDmiWxMEF900QcKQ']
INFO:oauth2client.client:Refreshing access_token
DEBUG:googleapiclient.discovery:URL being requested: POST https://www.googleapis.com/upload/drive/v3/files?fields=id&alt=json&uploadType=multipart
WARNING:googleapiclient.discovery_cache:file_cache is unavailable when using oauth2client >= 4.0.0 or google-auth
Traceback (most recent call last):
  File "C:\Users\79069\AppData\Local\Programs\Python\Python39\lib\site-packages\googleapiclient\discovery_cache\file_cache.py", line 33, in <module>
    from oauth2client.contrib.locked_file import LockedFile
ModuleNotFoundError: No module named 'oauth2client.contrib.locked_file'

During handling of the above exception, another exception occurred:

Traceback (most recent call last):
  File "C:\Users\79069\AppData\Local\Programs\Python\Python39\lib\site-packages\googleapiclient\discovery_cache\file_cache.py", line 37, in <module>
    from oauth2client.locked_file import LockedFile
ModuleNotFoundError: No module named 'oauth2client.locked_file'

During handling of the above exception, another exception occurred:

Traceback (most recent call last):
  File "C:\Users\79069\AppData\Local\Programs\Python\Python39\lib\site-packages\googleapiclient\discovery_cache\__init__.py", line 44, in autodetect
    from . import file_cache
  File "C:\Users\79069\AppData\Local\Programs\Python\Python39\lib\site-packages\googleapiclient\discovery_cache\file_cache.py", line 40, in <module>
    raise ImportError(
ImportError: file_cache is unavailable when using oauth2client >= 4.0.0 or google-auth
DEBUG:googleapiclient.discovery:URL being requested: GET https://www.googleapis.com/discovery/v1/apis/drive/v3/rest
INFO:oauth2client.transport:Attempting refresh to obtain initial access_token
DEBUG:oauth2client.crypt:[b'eyJ0eXAiOiJKV1QiLCJhbGciOiJSUzI1NiIsImtpZCI6IjZiYzEzYmFjOTE0ZGZkNzliN2ZhOWQyODYxMzk5YzljZmY4OWFjNjcifQ', b'eyJhdWQiOiJodHRwczovL29hdXRoMi5nb29nbGVhcGlzLmNvbS90b2tlbiIsInNjb3BlIjoiaHR0cHM6Ly93d3cuZ29vZ2xlYXBpcy5jb20vYXV0aC9kcml2ZSIsImlhdCI6MTYxNDE3MDQ4MSwiZXhwIjoxNjE0MTc0MDgxLCJpc3MiOiJqdXN0LWFjY291bnRAdGVzdGFwaWFuZHNoZWV0cy5pYW0uZ3NlcnZpY2VhY2NvdW50LmNvbSJ9', b'2-vcsFyHLlcTITkDufHv7e2DO_tTaR0Q3OrxGxH_J116HWfS8Hz9JEykHr1519ojS9omO0n7Wpf1aJ_WYmBT1DmO5vLkCdXd8q2Txlhgbga111cq02W1GL2o1pca9a2EAZKHJpDyyauarXQA6uvQRYkTaKYu0KhmyjDYLtr3bH7s0_U5K2onrlCOg2PlpYzfFKM1A788o8SYwjJOEnUr202zm7TI0sYFbRscSrsHXVXI9XjU-uMxw6WHEPgOZtDCBdvIFB-zEV3Op5jdoaMie74kzLbJSQkgO8-kud57pr5ZTGIFkwAT7tlwwDZRKW3wh_aRS9DhhfGd3lPAFWIDQg']
INFO:oauth2client.client:Refreshing access_token
DEBUG:googleapiclient.discovery:URL being requested: GET https://www.googleapis.com/drive/v3/files/1-GLrj8pJ11Y72fqamsqbb1I3X7t680Wb?alt=media
WARNING:googleapiclient.discovery_cache:file_cache is unavailable when using oauth2client >= 4.0.0 or google-auth
Traceback (most recent call last):
  File "C:\Users\79069\AppData\Local\Programs\Python\Python39\lib\site-packages\googleapiclient\discovery_cache\file_cache.py", line 33, in <module>
    from oauth2client.contrib.locked_file import LockedFile
ModuleNotFoundError: No module named 'oauth2client.contrib.locked_file'

During handling of the above exception, another exception occurred:

Traceback (most recent call last):
  File "C:\Users\79069\AppData\Local\Programs\Python\Python39\lib\site-packages\googleapiclient\discovery_cache\file_cache.py", line 37, in <module>
    from oauth2client.locked_file import LockedFile
ModuleNotFoundError: No module named 'oauth2client.locked_file'

During handling of the above exception, another exception occurred:

Traceback (most recent call last):
  File "C:\Users\79069\AppData\Local\Programs\Python\Python39\lib\site-packages\googleapiclient\discovery_cache\__init__.py", line 44, in autodetect
    from . import file_cache
  File "C:\Users\79069\AppData\Local\Programs\Python\Python39\lib\site-packages\googleapiclient\discovery_cache\file_cache.py", line 40, in <module>
    raise ImportError(
ImportError: file_cache is unavailable when using oauth2client >= 4.0.0 or google-auth
DEBUG:googleapiclient.discovery:URL being requested: GET https://www.googleapis.com/discovery/v1/apis/drive/v3/rest
INFO:oauth2client.transport:Attempting refresh to obtain initial access_token
DEBUG:oauth2client.crypt:[b'eyJ0eXAiOiJKV1QiLCJhbGciOiJSUzI1NiIsImtpZCI6IjZiYzEzYmFjOTE0ZGZkNzliN2ZhOWQyODYxMzk5YzljZmY4OWFjNjcifQ', b'eyJhdWQiOiJodHRwczovL29hdXRoMi5nb29nbGVhcGlzLmNvbS90b2tlbiIsInNjb3BlIjoiaHR0cHM6Ly93d3cuZ29vZ2xlYXBpcy5jb20vYXV0aC9kcml2ZSIsImlhdCI6MTYxNDE3MDQ4OCwiZXhwIjoxNjE0MTc0MDg4LCJpc3MiOiJqdXN0LWFjY291bnRAdGVzdGFwaWFuZHNoZWV0cy5pYW0uZ3NlcnZpY2VhY2NvdW50LmNvbSJ9', b'nIyY3jkctZR2sioj4RUCKDs6kDiUmyX6mpx0LPlwxiuZ2H1phj4IENcncauKHh1kWP6xnfZ0mCU58a9fmwUj2zFOhwxePEuP6UsUkFKvwsUpHxKClU6W1iwHtmdCKfUIdo_-YLnIj8E2zjpD5Fr_bWFTpvusENWTZNa5QUa2KMG52WhJV98C4sXVk9RBjq9bQ7lw5LHLBlxCvdTaJeeA6vVgPHOICf3RgxdepsKxoDBuT_eNp2-ViPqAM0wMXiWsPcM2-6B40RbuCu08AYT6PZeaDmrTgvmanCNuSR-IGJSUGbxjSVUGeHUUeIw4ruxsaPzNgkMcqajAuPSIN1WwIw']
INFO:oauth2client.client:Refreshing access_token
DEBUG:googleapiclient.discovery:URL being requested: POST https://www.googleapis.com/upload/drive/v3/files?fields=id&alt=json&uploadType=multipart
WARNING:googleapiclient.discovery_cache:file_cache is unavailable when using oauth2client >= 4.0.0 or google-auth
Traceback (most recent call last):
  File "C:\Users\79069\AppData\Local\Programs\Python\Python39\lib\site-packages\googleapiclient\discovery_cache\file_cache.py", line 33, in <module>
    from oauth2client.contrib.locked_file import LockedFile
ModuleNotFoundError: No module named 'oauth2client.contrib.locked_file'

During handling of the above exception, another exception occurred:

Traceback (most recent call last):
  File "C:\Users\79069\AppData\Local\Programs\Python\Python39\lib\site-packages\googleapiclient\discovery_cache\file_cache.py", line 37, in <module>
    from oauth2client.locked_file import LockedFile
ModuleNotFoundError: No module named 'oauth2client.locked_file'

During handling of the above exception, another exception occurred:

Traceback (most recent call last):
  File "C:\Users\79069\AppData\Local\Programs\Python\Python39\lib\site-packages\googleapiclient\discovery_cache\__init__.py", line 44, in autodetect
    from . import file_cache
  File "C:\Users\79069\AppData\Local\Programs\Python\Python39\lib\site-packages\googleapiclient\discovery_cache\file_cache.py", line 40, in <module>
    raise ImportError(
ImportError: file_cache is unavailable when using oauth2client >= 4.0.0 or google-auth
DEBUG:googleapiclient.discovery:URL being requested: GET https://www.googleapis.com/discovery/v1/apis/drive/v3/rest
INFO:oauth2client.transport:Attempting refresh to obtain initial access_token
DEBUG:oauth2client.crypt:[b'eyJ0eXAiOiJKV1QiLCJhbGciOiJSUzI1NiIsImtpZCI6IjZiYzEzYmFjOTE0ZGZkNzliN2ZhOWQyODYxMzk5YzljZmY4OWFjNjcifQ', b'eyJhdWQiOiJodHRwczovL29hdXRoMi5nb29nbGVhcGlzLmNvbS90b2tlbiIsInNjb3BlIjoiaHR0cHM6Ly93d3cuZ29vZ2xlYXBpcy5jb20vYXV0aC9kcml2ZSIsImlhdCI6MTYxNDE3MDU0MywiZXhwIjoxNjE0MTc0MTQzLCJpc3MiOiJqdXN0LWFjY291bnRAdGVzdGFwaWFuZHNoZWV0cy5pYW0uZ3NlcnZpY2VhY2NvdW50LmNvbSJ9', b'NCBrJyaA2k2SwJ3DQvZyrfygYXRoUtAlSF0cYkM6fFl-6gOSEZnnJulCSMkiK1kgpD0gm9InwENJsLZGPz8pGzOjkvIuY8WYw951wZugWpDj78I16JQ7DD_d-yPZGiaeJEkRBBmuO1Xu4YXerilSJ5mJhaW7t01G475V06YiJI8qgKwvlyEhdQT-8LO-z_acQNVtn-M6Aw78A8p8eWs6lrdK9iIxJukhYWuju900kVWFvg4lgj88Rcm98uXojMthKRDL-ryPeE4ficMR_agOuqGGCT3zkqRsMzRvoh93g2sS4YQoU7tVCsaYAKNYG3IgZjZ2owjsTVfDX1MSiODW2Q']
INFO:oauth2client.client:Refreshing access_token
DEBUG:googleapiclient.discovery:URL being requested: GET https://www.googleapis.com/drive/v3/files/12xpxsV0IhJT0mPqxdO9dzsMjONwI7EcW?alt=media
WARNING:googleapiclient.discovery_cache:file_cache is unavailable when using oauth2client >= 4.0.0 or google-auth
Traceback (most recent call last):
  File "C:\Users\79069\AppData\Local\Programs\Python\Python39\lib\site-packages\googleapiclient\discovery_cache\file_cache.py", line 33, in <module>
    from oauth2client.contrib.locked_file import LockedFile
ModuleNotFoundError: No module named 'oauth2client.contrib.locked_file'

During handling of the above exception, another exception occurred:

Traceback (most recent call last):
  File "C:\Users\79069\AppData\Local\Programs\Python\Python39\lib\site-packages\googleapiclient\discovery_cache\file_cache.py", line 37, in <module>
    from oauth2client.locked_file import LockedFile
ModuleNotFoundError: No module named 'oauth2client.locked_file'

During handling of the above exception, another exception occurred:

Traceback (most recent call last):
  File "C:\Users\79069\AppData\Local\Programs\Python\Python39\lib\site-packages\googleapiclient\discovery_cache\__init__.py", line 44, in autodetect
    from . import file_cache
  File "C:\Users\79069\AppData\Local\Programs\Python\Python39\lib\site-packages\googleapiclient\discovery_cache\file_cache.py", line 40, in <module>
    raise ImportError(
ImportError: file_cache is unavailable when using oauth2client >= 4.0.0 or google-auth
DEBUG:googleapiclient.discovery:URL being requested: GET https://www.googleapis.com/discovery/v1/apis/drive/v3/rest
INFO:oauth2client.transport:Attempting refresh to obtain initial access_token
DEBUG:oauth2client.crypt:[b'eyJ0eXAiOiJKV1QiLCJhbGciOiJSUzI1NiIsImtpZCI6IjZiYzEzYmFjOTE0ZGZkNzliN2ZhOWQyODYxMzk5YzljZmY4OWFjNjcifQ', b'eyJhdWQiOiJodHRwczovL29hdXRoMi5nb29nbGVhcGlzLmNvbS90b2tlbiIsInNjb3BlIjoiaHR0cHM6Ly93d3cuZ29vZ2xlYXBpcy5jb20vYXV0aC9kcml2ZSIsImlhdCI6MTYxNDE3MDU1MSwiZXhwIjoxNjE0MTc0MTUxLCJpc3MiOiJqdXN0LWFjY291bnRAdGVzdGFwaWFuZHNoZWV0cy5pYW0uZ3NlcnZpY2VhY2NvdW50LmNvbSJ9', b'6KR9QILDXfX-Kc_09-hGUE5RrU5Z9jrPjOPOw1q0699Ze7UP8qPFdoKI3rLnED15xcWkwO9Xfa8CUJRNZjlZCrIlXU7sppHL472r4zRvxvUZByj4SXct9an4bRwcjtfAkQXHLwEM6saJuCTKak00cbTxD6A68yMjeNamQX9gi_iViNmHmL8hU2-64g3REUZxI2Nx_BMgbWyDzqOlcVaOoNgUK4dQSlJeOk_DIyyyaL6rn7k2nzyMD-pz-hn2SxWdoA3VuAKm2AVdZXnAFiE3T3ecFxgLxY_zMdfSiHWCuuVGqLJodz1RPAiJqGI5W2gsu77JSz2o7iBF9F4crfr1XQ']
INFO:oauth2client.client:Refreshing access_token
DEBUG:googleapiclient.discovery:URL being requested: POST https://www.googleapis.com/upload/drive/v3/files?fields=id&alt=json&uploadType=multipart
WARNING:googleapiclient.discovery_cache:file_cache is unavailable when using oauth2client >= 4.0.0 or google-auth
Traceback (most recent call last):
  File "C:\Users\79069\AppData\Local\Programs\Python\Python39\lib\site-packages\googleapiclient\discovery_cache\file_cache.py", line 33, in <module>
    from oauth2client.contrib.locked_file import LockedFile
ModuleNotFoundError: No module named 'oauth2client.contrib.locked_file'

During handling of the above exception, another exception occurred:

Traceback (most recent call last):
  File "C:\Users\79069\AppData\Local\Programs\Python\Python39\lib\site-packages\googleapiclient\discovery_cache\file_cache.py", line 37, in <module>
    from oauth2client.locked_file import LockedFile
ModuleNotFoundError: No module named 'oauth2client.locked_file'

During handling of the above exception, another exception occurred:

Traceback (most recent call last):
  File "C:\Users\79069\AppData\Local\Programs\Python\Python39\lib\site-packages\googleapiclient\discovery_cache\__init__.py", line 44, in autodetect
    from . import file_cache
  File "C:\Users\79069\AppData\Local\Programs\Python\Python39\lib\site-packages\googleapiclient\discovery_cache\file_cache.py", line 40, in <module>
    raise ImportError(
ImportError: file_cache is unavailable when using oauth2client >= 4.0.0 or google-auth
DEBUG:googleapiclient.discovery:URL being requested: GET https://www.googleapis.com/discovery/v1/apis/drive/v3/rest
INFO:oauth2client.transport:Attempting refresh to obtain initial access_token
DEBUG:oauth2client.crypt:[b'eyJ0eXAiOiJKV1QiLCJhbGciOiJSUzI1NiIsImtpZCI6IjZiYzEzYmFjOTE0ZGZkNzliN2ZhOWQyODYxMzk5YzljZmY4OWFjNjcifQ', b'eyJhdWQiOiJodHRwczovL29hdXRoMi5nb29nbGVhcGlzLmNvbS90b2tlbiIsInNjb3BlIjoiaHR0cHM6Ly93d3cuZ29vZ2xlYXBpcy5jb20vYXV0aC9kcml2ZSIsImlhdCI6MTYxNDE3MDYzNCwiZXhwIjoxNjE0MTc0MjM0LCJpc3MiOiJqdXN0LWFjY291bnRAdGVzdGFwaWFuZHNoZWV0cy5pYW0uZ3NlcnZpY2VhY2NvdW50LmNvbSJ9', b't0VNMbSsIYnPvd3SVF-SVE2LnW2YzjhiXLXn7JfquGupu8sn85Oa6pmQRTyR-L8S-5aJgmCgPwQKjAFvJ9O-i0M5wvSDdX7MO_GL1k0vR_od7YSc8fUuPA2ka0_NWM80gRvuUyvTKN0wdtSenh6n8gibXL2kk507FmB2GN7rcFHXxbi5qUeQm6v041pAwS6SgXR8SNv01HPybkxkPfvt6WjPmArxg5C6jH7S8CeACoAJtsQe4YwCXNKbB8K2e1vy5icItoOvq-b0fzOrfsOkGF9MeqKqwTGGo3zjaYPeyMHxx4xYA8ikT8yDQ8WHik9VddtMtgSrBgOFgYIQ7UdaVQ']
INFO:oauth2client.client:Refreshing access_token
DEBUG:googleapiclient.discovery:URL being requested: GET https://www.googleapis.com/drive/v3/files/12xpxsV0IhJT0mPqxdO9dzsMjONwI7EcW?alt=media
WARNING:googleapiclient.discovery_cache:file_cache is unavailable when using oauth2client >= 4.0.0 or google-auth
Traceback (most recent call last):
  File "C:\Users\79069\AppData\Local\Programs\Python\Python39\lib\site-packages\googleapiclient\discovery_cache\file_cache.py", line 33, in <module>
    from oauth2client.contrib.locked_file import LockedFile
ModuleNotFoundError: No module named 'oauth2client.contrib.locked_file'

During handling of the above exception, another exception occurred:

Traceback (most recent call last):
  File "C:\Users\79069\AppData\Local\Programs\Python\Python39\lib\site-packages\googleapiclient\discovery_cache\file_cache.py", line 37, in <module>
    from oauth2client.locked_file import LockedFile
ModuleNotFoundError: No module named 'oauth2client.locked_file'

During handling of the above exception, another exception occurred:

Traceback (most recent call last):
  File "C:\Users\79069\AppData\Local\Programs\Python\Python39\lib\site-packages\googleapiclient\discovery_cache\__init__.py", line 44, in autodetect
    from . import file_cache
  File "C:\Users\79069\AppData\Local\Programs\Python\Python39\lib\site-packages\googleapiclient\discovery_cache\file_cache.py", line 40, in <module>
    raise ImportError(
ImportError: file_cache is unavailable when using oauth2client >= 4.0.0 or google-auth
DEBUG:googleapiclient.discovery:URL being requested: GET https://www.googleapis.com/discovery/v1/apis/drive/v3/rest
INFO:oauth2client.transport:Attempting refresh to obtain initial access_token
DEBUG:oauth2client.crypt:[b'eyJ0eXAiOiJKV1QiLCJhbGciOiJSUzI1NiIsImtpZCI6IjZiYzEzYmFjOTE0ZGZkNzliN2ZhOWQyODYxMzk5YzljZmY4OWFjNjcifQ', b'eyJhdWQiOiJodHRwczovL29hdXRoMi5nb29nbGVhcGlzLmNvbS90b2tlbiIsInNjb3BlIjoiaHR0cHM6Ly93d3cuZ29vZ2xlYXBpcy5jb20vYXV0aC9kcml2ZSIsImlhdCI6MTYxNDE3MDY0MywiZXhwIjoxNjE0MTc0MjQzLCJpc3MiOiJqdXN0LWFjY291bnRAdGVzdGFwaWFuZHNoZWV0cy5pYW0uZ3NlcnZpY2VhY2NvdW50LmNvbSJ9', b'WS-kFyYWF2ui4wem5WSo20oV-UsHMMEw6CO36TFo1HPlCgPcS1RqXSZ34E36LXqTX45Jc-Q9dm8aZeRWQbrlsoff6Lcmm7aY7ucLoQsLunilbbbAdfHcvPn2fC3gjevvPVQl2GTmjrEQOeuLmNBBADrIM2vAusA2JIKtEa4JyU2UKrBieSdQ3Ac5OTxzcEo7qF9Yklm3yakXMnNI1HW0JT5H01_IBvZyAmGsn9tZfZbYe4IAMOc1pgYgZ73etza_67NT3E8pd-_trI9gY13pGYlMNd019yjwlx40ZxVPeAfcTss9m0jfr77qG_nxVnwwQtkchgOaKbm0qd26KXl3Cw']
INFO:oauth2client.client:Refreshing access_token
DEBUG:googleapiclient.discovery:URL being requested: POST https://www.googleapis.com/upload/drive/v3/files?fields=id&alt=json&uploadType=multipart
WARNING:googleapiclient.discovery_cache:file_cache is unavailable when using oauth2client >= 4.0.0 or google-auth
Traceback (most recent call last):
  File "C:\Users\79069\AppData\Local\Programs\Python\Python39\lib\site-packages\googleapiclient\discovery_cache\file_cache.py", line 33, in <module>
    from oauth2client.contrib.locked_file import LockedFile
ModuleNotFoundError: No module named 'oauth2client.contrib.locked_file'

During handling of the above exception, another exception occurred:

Traceback (most recent call last):
  File "C:\Users\79069\AppData\Local\Programs\Python\Python39\lib\site-packages\googleapiclient\discovery_cache\file_cache.py", line 37, in <module>
    from oauth2client.locked_file import LockedFile
ModuleNotFoundError: No module named 'oauth2client.locked_file'

During handling of the above exception, another exception occurred:

Traceback (most recent call last):
  File "C:\Users\79069\AppData\Local\Programs\Python\Python39\lib\site-packages\googleapiclient\discovery_cache\__init__.py", line 44, in autodetect
    from . import file_cache
  File "C:\Users\79069\AppData\Local\Programs\Python\Python39\lib\site-packages\googleapiclient\discovery_cache\file_cache.py", line 40, in <module>
    raise ImportError(
ImportError: file_cache is unavailable when using oauth2client >= 4.0.0 or google-auth
DEBUG:googleapiclient.discovery:URL being requested: GET https://www.googleapis.com/discovery/v1/apis/drive/v3/rest
INFO:oauth2client.transport:Attempting refresh to obtain initial access_token
DEBUG:oauth2client.crypt:[b'eyJ0eXAiOiJKV1QiLCJhbGciOiJSUzI1NiIsImtpZCI6IjZiYzEzYmFjOTE0ZGZkNzliN2ZhOWQyODYxMzk5YzljZmY4OWFjNjcifQ', b'eyJhdWQiOiJodHRwczovL29hdXRoMi5nb29nbGVhcGlzLmNvbS90b2tlbiIsInNjb3BlIjoiaHR0cHM6Ly93d3cuZ29vZ2xlYXBpcy5jb20vYXV0aC9kcml2ZSIsImlhdCI6MTYxNDE3MDY2MiwiZXhwIjoxNjE0MTc0MjYyLCJpc3MiOiJqdXN0LWFjY291bnRAdGVzdGFwaWFuZHNoZWV0cy5pYW0uZ3NlcnZpY2VhY2NvdW50LmNvbSJ9', b'uZgh02ihaNRBm5THziauZPtP-vU-w4Xg4URLFyGhEVOgNxJCgkYpP4O2ZTfmFKDufUggQKBL-NcCztjU0nnP2-_HCfp6J9aolQjRx5sXI8CzAw7leDgrUgAlFjUtq5gFqk9WEfbXs_6UOKeI1P8jxxtSx62uU8krlReFKPFvKslXBsy4yO5jE75Q3oBRkyrYk9FprhPlu71QQinASbl7Jr461jG-Ib_RFEuiSzLYrDYuNn95Av7hRQd43TlxpT9hzWCAIRzXv5W6Qm7i8rSlgBZYni8OklfZkAsARoHOkMOxdlGDAmP6tKHALPdnbV8ZEqrkMA0CBtkSJCFANkKJDQ']
INFO:oauth2client.client:Refreshing access_token
DEBUG:googleapiclient.discovery:URL being requested: GET https://www.googleapis.com/drive/v3/files/1-GLrj8pJ11Y72fqamsqbb1I3X7t680Wb?alt=media
WARNING:googleapiclient.discovery_cache:file_cache is unavailable when using oauth2client >= 4.0.0 or google-auth
Traceback (most recent call last):
  File "C:\Users\79069\AppData\Local\Programs\Python\Python39\lib\site-packages\googleapiclient\discovery_cache\file_cache.py", line 33, in <module>
    from oauth2client.contrib.locked_file import LockedFile
ModuleNotFoundError: No module named 'oauth2client.contrib.locked_file'

During handling of the above exception, another exception occurred:

Traceback (most recent call last):
  File "C:\Users\79069\AppData\Local\Programs\Python\Python39\lib\site-packages\googleapiclient\discovery_cache\file_cache.py", line 37, in <module>
    from oauth2client.locked_file import LockedFile
ModuleNotFoundError: No module named 'oauth2client.locked_file'

During handling of the above exception, another exception occurred:

Traceback (most recent call last):
  File "C:\Users\79069\AppData\Local\Programs\Python\Python39\lib\site-packages\googleapiclient\discovery_cache\__init__.py", line 44, in autodetect
    from . import file_cache
  File "C:\Users\79069\AppData\Local\Programs\Python\Python39\lib\site-packages\googleapiclient\discovery_cache\file_cache.py", line 40, in <module>
    raise ImportError(
ImportError: file_cache is unavailable when using oauth2client >= 4.0.0 or google-auth
DEBUG:googleapiclient.discovery:URL being requested: GET https://www.googleapis.com/discovery/v1/apis/drive/v3/rest
INFO:oauth2client.transport:Attempting refresh to obtain initial access_token
DEBUG:oauth2client.crypt:[b'eyJ0eXAiOiJKV1QiLCJhbGciOiJSUzI1NiIsImtpZCI6IjZiYzEzYmFjOTE0ZGZkNzliN2ZhOWQyODYxMzk5YzljZmY4OWFjNjcifQ', b'eyJhdWQiOiJodHRwczovL29hdXRoMi5nb29nbGVhcGlzLmNvbS90b2tlbiIsInNjb3BlIjoiaHR0cHM6Ly93d3cuZ29vZ2xlYXBpcy5jb20vYXV0aC9kcml2ZSIsImlhdCI6MTYxNDE3MDY2OCwiZXhwIjoxNjE0MTc0MjY4LCJpc3MiOiJqdXN0LWFjY291bnRAdGVzdGFwaWFuZHNoZWV0cy5pYW0uZ3NlcnZpY2VhY2NvdW50LmNvbSJ9', b'VbC6JT81AX-jTrDqv-YOHqN53Fb0bvZwbE5U44uzyoHlIAAkagmYo3wG9Wa6diM3PUFG0CRaCsdxJRNR1HP4t56pikrhJ56zv5XyCFtpvHzSwjL8zHoWtIbgr21bkuf_CMtk2c-vXNjRuUE09YmV2OAgyAR4A-9F6vppx-g557ctxSkzGOTmYqGctsVIRIRtck0i7Uuak1NGuWE5D2_qosq3oNYwp7TfBbxluUCwQE_2JziAiyvXvZToc0TPzfFeFZTHrG3XgN_u_Cab5ek9vtJl1taDJEqwAkp-8BNjbleZONFq4XJ8R8LgdlqqmVVcBbocnKfIklVqtIo9T30Klw']
INFO:oauth2client.client:Refreshing access_token
DEBUG:googleapiclient.discovery:URL being requested: POST https://www.googleapis.com/upload/drive/v3/files?fields=id&alt=json&uploadType=multipart
WARNING:googleapiclient.discovery_cache:file_cache is unavailable when using oauth2client >= 4.0.0 or google-auth
Traceback (most recent call last):
  File "C:\Users\79069\AppData\Local\Programs\Python\Python39\lib\site-packages\googleapiclient\discovery_cache\file_cache.py", line 33, in <module>
    from oauth2client.contrib.locked_file import LockedFile
ModuleNotFoundError: No module named 'oauth2client.contrib.locked_file'

During handling of the above exception, another exception occurred:

Traceback (most recent call last):
  File "C:\Users\79069\AppData\Local\Programs\Python\Python39\lib\site-packages\googleapiclient\discovery_cache\file_cache.py", line 37, in <module>
    from oauth2client.locked_file import LockedFile
ModuleNotFoundError: No module named 'oauth2client.locked_file'

During handling of the above exception, another exception occurred:

Traceback (most recent call last):
  File "C:\Users\79069\AppData\Local\Programs\Python\Python39\lib\site-packages\googleapiclient\discovery_cache\__init__.py", line 44, in autodetect
    from . import file_cache
  File "C:\Users\79069\AppData\Local\Programs\Python\Python39\lib\site-packages\googleapiclient\discovery_cache\file_cache.py", line 40, in <module>
    raise ImportError(
ImportError: file_cache is unavailable when using oauth2client >= 4.0.0 or google-auth
DEBUG:googleapiclient.discovery:URL being requested: GET https://www.googleapis.com/discovery/v1/apis/drive/v3/rest
INFO:oauth2client.transport:Attempting refresh to obtain initial access_token
DEBUG:oauth2client.crypt:[b'eyJ0eXAiOiJKV1QiLCJhbGciOiJSUzI1NiIsImtpZCI6IjZiYzEzYmFjOTE0ZGZkNzliN2ZhOWQyODYxMzk5YzljZmY4OWFjNjcifQ', b'eyJhdWQiOiJodHRwczovL29hdXRoMi5nb29nbGVhcGlzLmNvbS90b2tlbiIsInNjb3BlIjoiaHR0cHM6Ly93d3cuZ29vZ2xlYXBpcy5jb20vYXV0aC9kcml2ZSIsImlhdCI6MTYxNDE3MDc1MCwiZXhwIjoxNjE0MTc0MzUwLCJpc3MiOiJqdXN0LWFjY291bnRAdGVzdGFwaWFuZHNoZWV0cy5pYW0uZ3NlcnZpY2VhY2NvdW50LmNvbSJ9', b'Tr2LXilpOqzZoLwkF8H1nF8r30qxxNLa7ne2YHI3XFr8ZpyD1y1Nfrk-BKebIHgDTBuQtiroj1If160dwgjJJpg-ofzEMtiT8dCL-aOGUMSgFeFLLxoPCiJvy5nGtrMORWf90YMbqxcKDZFh3AB8KpOIoUHgWntYfflZU-UQ-t4NEJL7UGucQN4v__BPWgJ5QNjks5t3dhVpAUJCravL04--O3Ef-vYDtqdECQYhOo6MDgtDZksB0Zx-RJC4O8iZpwU0pJNusWijoezB7ARZg1_s-T9FPfbzgT1uS2GtaVmPc5mgT5CD2B_zy-kQ4uwWF-tx02eOp5lbqF44i8ygSA']
INFO:oauth2client.client:Refreshing access_token
DEBUG:googleapiclient.discovery:URL being requested: GET https://www.googleapis.com/drive/v3/files/1-GLrj8pJ11Y72fqamsqbb1I3X7t680Wb?alt=media
WARNING:googleapiclient.discovery_cache:file_cache is unavailable when using oauth2client >= 4.0.0 or google-auth
Traceback (most recent call last):
  File "C:\Users\79069\AppData\Local\Programs\Python\Python39\lib\site-packages\googleapiclient\discovery_cache\file_cache.py", line 33, in <module>
    from oauth2client.contrib.locked_file import LockedFile
ModuleNotFoundError: No module named 'oauth2client.contrib.locked_file'

During handling of the above exception, another exception occurred:

Traceback (most recent call last):
  File "C:\Users\79069\AppData\Local\Programs\Python\Python39\lib\site-packages\googleapiclient\discovery_cache\file_cache.py", line 37, in <module>
    from oauth2client.locked_file import LockedFile
ModuleNotFoundError: No module named 'oauth2client.locked_file'

During handling of the above exception, another exception occurred:

Traceback (most recent call last):
  File "C:\Users\79069\AppData\Local\Programs\Python\Python39\lib\site-packages\googleapiclient\discovery_cache\__init__.py", line 44, in autodetect
    from . import file_cache
  File "C:\Users\79069\AppData\Local\Programs\Python\Python39\lib\site-packages\googleapiclient\discovery_cache\file_cache.py", line 40, in <module>
    raise ImportError(
ImportError: file_cache is unavailable when using oauth2client >= 4.0.0 or google-auth
DEBUG:googleapiclient.discovery:URL being requested: GET https://www.googleapis.com/discovery/v1/apis/drive/v3/rest
INFO:oauth2client.transport:Attempting refresh to obtain initial access_token
DEBUG:oauth2client.crypt:[b'eyJ0eXAiOiJKV1QiLCJhbGciOiJSUzI1NiIsImtpZCI6IjZiYzEzYmFjOTE0ZGZkNzliN2ZhOWQyODYxMzk5YzljZmY4OWFjNjcifQ', b'eyJhdWQiOiJodHRwczovL29hdXRoMi5nb29nbGVhcGlzLmNvbS90b2tlbiIsInNjb3BlIjoiaHR0cHM6Ly93d3cuZ29vZ2xlYXBpcy5jb20vYXV0aC9kcml2ZSIsImlhdCI6MTYxNDE3MDc4MywiZXhwIjoxNjE0MTc0MzgzLCJpc3MiOiJqdXN0LWFjY291bnRAdGVzdGFwaWFuZHNoZWV0cy5pYW0uZ3NlcnZpY2VhY2NvdW50LmNvbSJ9', b'boncCpSrMojkZ6LSwcXhzETBW02s5Thk2_BM0K2z9Ch0vbpuvVVVatefs1AOlNv0GcugvMKq-HlgumiUkLnodAsJjNJhXo6E8sXtN7k6s6BGTqHAmm-miIk8MNn3lXmTZlYDCf_Dd0QQD__WBp5KkD6iQWLj-iQDIKsGSRvGFagMwsNZV2Ci7sKZwCBV4HV0VgK3sMpEE8MAT2ATTh4eXv2VFzBKZmS1ADw_kajCcBaHfWI_r7c6hxWPdGf_S_HMozUPct75HSuGo5ezszESr1bIuLbEUfaDlWpZXsBdBrqfCXFnhN8L-HgFUr4b2sBJsDyUfCcAxnomSpmQDaWSUg']
INFO:oauth2client.client:Refreshing access_token
DEBUG:googleapiclient.discovery:URL being requested: GET https://www.googleapis.com/drive/v3/files/1-GLrj8pJ11Y72fqamsqbb1I3X7t680Wb?alt=media
WARNING:googleapiclient.discovery_cache:file_cache is unavailable when using oauth2client >= 4.0.0 or google-auth
Traceback (most recent call last):
  File "C:\Users\79069\AppData\Local\Programs\Python\Python39\lib\site-packages\googleapiclient\discovery_cache\file_cache.py", line 33, in <module>
    from oauth2client.contrib.locked_file import LockedFile
ModuleNotFoundError: No module named 'oauth2client.contrib.locked_file'

During handling of the above exception, another exception occurred:

Traceback (most recent call last):
  File "C:\Users\79069\AppData\Local\Programs\Python\Python39\lib\site-packages\googleapiclient\discovery_cache\file_cache.py", line 37, in <module>
    from oauth2client.locked_file import LockedFile
ModuleNotFoundError: No module named 'oauth2client.locked_file'

During handling of the above exception, another exception occurred:

Traceback (most recent call last):
  File "C:\Users\79069\AppData\Local\Programs\Python\Python39\lib\site-packages\googleapiclient\discovery_cache\__init__.py", line 44, in autodetect
    from . import file_cache
  File "C:\Users\79069\AppData\Local\Programs\Python\Python39\lib\site-packages\googleapiclient\discovery_cache\file_cache.py", line 40, in <module>
    raise ImportError(
ImportError: file_cache is unavailable when using oauth2client >= 4.0.0 or google-auth
DEBUG:googleapiclient.discovery:URL being requested: GET https://www.googleapis.com/discovery/v1/apis/drive/v3/rest
INFO:oauth2client.transport:Attempting refresh to obtain initial access_token
DEBUG:oauth2client.crypt:[b'eyJ0eXAiOiJKV1QiLCJhbGciOiJSUzI1NiIsImtpZCI6IjZiYzEzYmFjOTE0ZGZkNzliN2ZhOWQyODYxMzk5YzljZmY4OWFjNjcifQ', b'eyJhdWQiOiJodHRwczovL29hdXRoMi5nb29nbGVhcGlzLmNvbS90b2tlbiIsInNjb3BlIjoiaHR0cHM6Ly93d3cuZ29vZ2xlYXBpcy5jb20vYXV0aC9kcml2ZSIsImlhdCI6MTYxNDE3MDgxMCwiZXhwIjoxNjE0MTc0NDEwLCJpc3MiOiJqdXN0LWFjY291bnRAdGVzdGFwaWFuZHNoZWV0cy5pYW0uZ3NlcnZpY2VhY2NvdW50LmNvbSJ9', b'Kot_buvRc4-dzkjRlViH1FfxNG9B7z_Mhn1CaJSHSAGHOQ8B4FBpTT5T39U0Yx0shDAFYJDlBmXWzAV5tI7DdVN47j0gdO5J3vkigRZb3YDQQvDu1yCwVUux_1hYALvjzBOXhRc2OJpRArI-wR8pKiwINH6OrNRgjUeMHNtwWkzIH-AvO5_XpyQ49ZbL67KFgXXslY0dsD-PVj90nQvqyHyU9owkQIN4Aj3_E0m7AAa2asC0NltdnneQz0SdFrMtKWWWSzPqmEPTWKNgOuTg2iOC1mg42O9s7ij3ELeAy4O11K3gYSUfx7dpBKj7FqsQr-5s8QeXh-H-7-ZtFohbtQ']
INFO:oauth2client.client:Refreshing access_token
DEBUG:googleapiclient.discovery:URL being requested: GET https://www.googleapis.com/drive/v3/files/1-GLrj8pJ11Y72fqamsqbb1I3X7t680Wb?alt=media
WARNING:googleapiclient.discovery_cache:file_cache is unavailable when using oauth2client >= 4.0.0 or google-auth
Traceback (most recent call last):
  File "C:\Users\79069\AppData\Local\Programs\Python\Python39\lib\site-packages\googleapiclient\discovery_cache\file_cache.py", line 33, in <module>
    from oauth2client.contrib.locked_file import LockedFile
ModuleNotFoundError: No module named 'oauth2client.contrib.locked_file'

During handling of the above exception, another exception occurred:

Traceback (most recent call last):
  File "C:\Users\79069\AppData\Local\Programs\Python\Python39\lib\site-packages\googleapiclient\discovery_cache\file_cache.py", line 37, in <module>
    from oauth2client.locked_file import LockedFile
ModuleNotFoundError: No module named 'oauth2client.locked_file'

During handling of the above exception, another exception occurred:

Traceback (most recent call last):
  File "C:\Users\79069\AppData\Local\Programs\Python\Python39\lib\site-packages\googleapiclient\discovery_cache\__init__.py", line 44, in autodetect
    from . import file_cache
  File "C:\Users\79069\AppData\Local\Programs\Python\Python39\lib\site-packages\googleapiclient\discovery_cache\file_cache.py", line 40, in <module>
    raise ImportError(
ImportError: file_cache is unavailable when using oauth2client >= 4.0.0 or google-auth
DEBUG:googleapiclient.discovery:URL being requested: GET https://www.googleapis.com/discovery/v1/apis/drive/v3/rest
INFO:oauth2client.transport:Attempting refresh to obtain initial access_token
DEBUG:oauth2client.crypt:[b'eyJ0eXAiOiJKV1QiLCJhbGciOiJSUzI1NiIsImtpZCI6IjZiYzEzYmFjOTE0ZGZkNzliN2ZhOWQyODYxMzk5YzljZmY4OWFjNjcifQ', b'eyJhdWQiOiJodHRwczovL29hdXRoMi5nb29nbGVhcGlzLmNvbS90b2tlbiIsInNjb3BlIjoiaHR0cHM6Ly93d3cuZ29vZ2xlYXBpcy5jb20vYXV0aC9kcml2ZSIsImlhdCI6MTYxNDE3MDgxNiwiZXhwIjoxNjE0MTc0NDE2LCJpc3MiOiJqdXN0LWFjY291bnRAdGVzdGFwaWFuZHNoZWV0cy5pYW0uZ3NlcnZpY2VhY2NvdW50LmNvbSJ9', b'ebLzuJs_hUzLh46HDCX1Vhc2oObcQL9EeFat8-SMX5kIawX8ToIGgwefsiy0fwIQRGGPB0gkLgs4rw0X9hG5muop6hYG60y_wr7nFLz0VnlV5DlN00ix5pAmI46vMZMFJ-GFCWHjlBB4Rbm3u4wmFEP8m4cbgYLdWFe3rYkWIaKafVz7oVcBhRcsujB5p-pf4YqRU3-wbyZIcqEBaGz5www-cMyMMX2a9yqY3T0Y3O-1XNdh1i3nw9tuQ7oMDshbICWV7SpBRNgCaXOvFPSRTMEx26p9nNYOx1Be1WdLdeSN5gbRh4H_tn9Nqmy79RtnU3PiBngE9tsOOwyD9B73NA']
INFO:oauth2client.client:Refreshing access_token
DEBUG:googleapiclient.discovery:URL being requested: POST https://www.googleapis.com/upload/drive/v3/files?fields=id&alt=json&uploadType=multipart
WARNING:googleapiclient.discovery_cache:file_cache is unavailable when using oauth2client >= 4.0.0 or google-auth
Traceback (most recent call last):
  File "C:\Users\79069\AppData\Local\Programs\Python\Python39\lib\site-packages\googleapiclient\discovery_cache\file_cache.py", line 33, in <module>
    from oauth2client.contrib.locked_file import LockedFile
ModuleNotFoundError: No module named 'oauth2client.contrib.locked_file'

During handling of the above exception, another exception occurred:

Traceback (most recent call last):
  File "C:\Users\79069\AppData\Local\Programs\Python\Python39\lib\site-packages\googleapiclient\discovery_cache\file_cache.py", line 37, in <module>
    from oauth2client.locked_file import LockedFile
ModuleNotFoundError: No module named 'oauth2client.locked_file'

During handling of the above exception, another exception occurred:

Traceback (most recent call last):
  File "C:\Users\79069\AppData\Local\Programs\Python\Python39\lib\site-packages\googleapiclient\discovery_cache\__init__.py", line 44, in autodetect
    from . import file_cache
  File "C:\Users\79069\AppData\Local\Programs\Python\Python39\lib\site-packages\googleapiclient\discovery_cache\file_cache.py", line 40, in <module>
    raise ImportError(
ImportError: file_cache is unavailable when using oauth2client >= 4.0.0 or google-auth
DEBUG:googleapiclient.discovery:URL being requested: GET https://www.googleapis.com/discovery/v1/apis/drive/v3/rest
INFO:oauth2client.transport:Attempting refresh to obtain initial access_token
DEBUG:oauth2client.crypt:[b'eyJ0eXAiOiJKV1QiLCJhbGciOiJSUzI1NiIsImtpZCI6IjZiYzEzYmFjOTE0ZGZkNzliN2ZhOWQyODYxMzk5YzljZmY4OWFjNjcifQ', b'eyJhdWQiOiJodHRwczovL29hdXRoMi5nb29nbGVhcGlzLmNvbS90b2tlbiIsInNjb3BlIjoiaHR0cHM6Ly93d3cuZ29vZ2xlYXBpcy5jb20vYXV0aC9kcml2ZSIsImlhdCI6MTYxNDE3MDkwNiwiZXhwIjoxNjE0MTc0NTA2LCJpc3MiOiJqdXN0LWFjY291bnRAdGVzdGFwaWFuZHNoZWV0cy5pYW0uZ3NlcnZpY2VhY2NvdW50LmNvbSJ9', b'wqqi9sS6ga79u9IISrLeLOkfqJG2aGNWQI08XSilToo8BxoZ9LNELNZdZPPujN1q0RRcLCudr6lWBUAUbAVPvzOHws_SR2Yhlabnn-cQUa8KIir2nYS_Uy7-nqUthCT-0RuGa_NwwQ7akcphHGACidEVAw3F_N8GugnY3iVZbA3AfLh7nKSu7ey7svTuzeVGCThwn9ibI-EDxiHKkupjui-77aXOW7rdkJRytyg-0l_f2pZKR3XNB-SxGpgZK-Ed9KEH0P-f_XD0vQh5zP0z_ogYybLo0BfblHRVqHE35BjwqPiJ3cVR23I_WX6vZngpZmxLF79DNwNRc0g8KnNyDA']
INFO:oauth2client.client:Refreshing access_token
DEBUG:googleapiclient.discovery:URL being requested: GET https://www.googleapis.com/drive/v3/files/12xpxsV0IhJT0mPqxdO9dzsMjONwI7EcW?alt=media
WARNING:googleapiclient.discovery_cache:file_cache is unavailable when using oauth2client >= 4.0.0 or google-auth
Traceback (most recent call last):
  File "C:\Users\79069\AppData\Local\Programs\Python\Python39\lib\site-packages\googleapiclient\discovery_cache\file_cache.py", line 33, in <module>
    from oauth2client.contrib.locked_file import LockedFile
ModuleNotFoundError: No module named 'oauth2client.contrib.locked_file'

During handling of the above exception, another exception occurred:

Traceback (most recent call last):
  File "C:\Users\79069\AppData\Local\Programs\Python\Python39\lib\site-packages\googleapiclient\discovery_cache\file_cache.py", line 37, in <module>
    from oauth2client.locked_file import LockedFile
ModuleNotFoundError: No module named 'oauth2client.locked_file'

During handling of the above exception, another exception occurred:

Traceback (most recent call last):
  File "C:\Users\79069\AppData\Local\Programs\Python\Python39\lib\site-packages\googleapiclient\discovery_cache\__init__.py", line 44, in autodetect
    from . import file_cache
  File "C:\Users\79069\AppData\Local\Programs\Python\Python39\lib\site-packages\googleapiclient\discovery_cache\file_cache.py", line 40, in <module>
    raise ImportError(
ImportError: file_cache is unavailable when using oauth2client >= 4.0.0 or google-auth
DEBUG:googleapiclient.discovery:URL being requested: GET https://www.googleapis.com/discovery/v1/apis/drive/v3/rest
INFO:oauth2client.transport:Attempting refresh to obtain initial access_token
DEBUG:oauth2client.crypt:[b'eyJ0eXAiOiJKV1QiLCJhbGciOiJSUzI1NiIsImtpZCI6IjZiYzEzYmFjOTE0ZGZkNzliN2ZhOWQyODYxMzk5YzljZmY4OWFjNjcifQ', b'eyJhdWQiOiJodHRwczovL29hdXRoMi5nb29nbGVhcGlzLmNvbS90b2tlbiIsInNjb3BlIjoiaHR0cHM6Ly93d3cuZ29vZ2xlYXBpcy5jb20vYXV0aC9kcml2ZSIsImlhdCI6MTYxNDE3MDk5NCwiZXhwIjoxNjE0MTc0NTk0LCJpc3MiOiJqdXN0LWFjY291bnRAdGVzdGFwaWFuZHNoZWV0cy5pYW0uZ3NlcnZpY2VhY2NvdW50LmNvbSJ9', b'i3FM4c3rr3dJ9wBAxcrb5_MkRK_FtptllRCOsHzpuOW-lNqoZjn7Ut7DYeApXNhrfLQz3EgxABrtIPLIQbWHwpt2aVKTbnd5y34oVXd3sWopyzMWfxn3uT3CA_xXMjJPeQI7bMf-DnJK9ZkaPYzshfEaEijhXqV08CP61elVuhrX6LEHB3BR9Iash5FX0APTlnxxqW0pykRj0Oc9Mk_xaxOx5lCc8a4WccdAQ8YzSysS_75mPzVc555gOnB4tIcbetN7mMy5osy9Au03q_ewaNKE3HxsieRL2fXU76-PrOf4GTas7lZwHRY0AoQ1eZafCgO9c9sfqnQKuuMU9YHi3g']
INFO:oauth2client.client:Refreshing access_token
DEBUG:googleapiclient.discovery:URL being requested: GET https://www.googleapis.com/drive/v3/files/12xpxsV0IhJT0mPqxdO9dzsMjONwI7EcW?alt=media
WARNING:googleapiclient.discovery_cache:file_cache is unavailable when using oauth2client >= 4.0.0 or google-auth
Traceback (most recent call last):
  File "C:\Users\79069\AppData\Local\Programs\Python\Python39\lib\site-packages\googleapiclient\discovery_cache\file_cache.py", line 33, in <module>
    from oauth2client.contrib.locked_file import LockedFile
ModuleNotFoundError: No module named 'oauth2client.contrib.locked_file'

During handling of the above exception, another exception occurred:

Traceback (most recent call last):
  File "C:\Users\79069\AppData\Local\Programs\Python\Python39\lib\site-packages\googleapiclient\discovery_cache\file_cache.py", line 37, in <module>
    from oauth2client.locked_file import LockedFile
ModuleNotFoundError: No module named 'oauth2client.locked_file'

During handling of the above exception, another exception occurred:

Traceback (most recent call last):
  File "C:\Users\79069\AppData\Local\Programs\Python\Python39\lib\site-packages\googleapiclient\discovery_cache\__init__.py", line 44, in autodetect
    from . import file_cache
  File "C:\Users\79069\AppData\Local\Programs\Python\Python39\lib\site-packages\googleapiclient\discovery_cache\file_cache.py", line 40, in <module>
    raise ImportError(
ImportError: file_cache is unavailable when using oauth2client >= 4.0.0 or google-auth
DEBUG:googleapiclient.discovery:URL being requested: GET https://www.googleapis.com/discovery/v1/apis/drive/v3/rest
INFO:oauth2client.transport:Attempting refresh to obtain initial access_token
DEBUG:oauth2client.crypt:[b'eyJ0eXAiOiJKV1QiLCJhbGciOiJSUzI1NiIsImtpZCI6IjZiYzEzYmFjOTE0ZGZkNzliN2ZhOWQyODYxMzk5YzljZmY4OWFjNjcifQ', b'eyJhdWQiOiJodHRwczovL29hdXRoMi5nb29nbGVhcGlzLmNvbS90b2tlbiIsInNjb3BlIjoiaHR0cHM6Ly93d3cuZ29vZ2xlYXBpcy5jb20vYXV0aC9kcml2ZSIsImlhdCI6MTYxNDE3MTAxOCwiZXhwIjoxNjE0MTc0NjE4LCJpc3MiOiJqdXN0LWFjY291bnRAdGVzdGFwaWFuZHNoZWV0cy5pYW0uZ3NlcnZpY2VhY2NvdW50LmNvbSJ9', b'ojst5ETOwNR5rA5dbudUCCmydmgE-au3wsi0Lnz71PSWYVtofZW5ngWLezpJgsjgxS8CsLJ7VkCoxMmMmA9GK1jxQIx2MQOsGux_9j7WWOiLVxG6a9fNSyNo48pPDRlscdCUZvNXqaN3c1CxuJHJNs29n9XTbfqQJgq95WRC2opCHi7HoHC6A5nnLeRjbZ6j8kP82aiBmcT3iJIoV8Eb68uZ9bUWBUWfcB3iDsSmiLqmGp7X6zz06T01z7MkajBiZ_-g4o-57tlOXIyUDO3Q42XGrvPutAyricxn8r4nuGHvIqRJ6y1dmxlsGACqh65vnM5WFsEpzMf3mSgBKwiPXA']
INFO:oauth2client.client:Refreshing access_token
DEBUG:googleapiclient.discovery:URL being requested: GET https://www.googleapis.com/drive/v3/files/12xpxsV0IhJT0mPqxdO9dzsMjONwI7EcW?alt=media
ERROR:root:'Show_Test_Controller' object has no attribute 'task_object'
WARNING:googleapiclient.discovery_cache:file_cache is unavailable when using oauth2client >= 4.0.0 or google-auth
Traceback (most recent call last):
  File "C:\Users\79069\AppData\Local\Programs\Python\Python39\lib\site-packages\googleapiclient\discovery_cache\file_cache.py", line 33, in <module>
    from oauth2client.contrib.locked_file import LockedFile
ModuleNotFoundError: No module named 'oauth2client.contrib.locked_file'

During handling of the above exception, another exception occurred:

Traceback (most recent call last):
  File "C:\Users\79069\AppData\Local\Programs\Python\Python39\lib\site-packages\googleapiclient\discovery_cache\file_cache.py", line 37, in <module>
    from oauth2client.locked_file import LockedFile
ModuleNotFoundError: No module named 'oauth2client.locked_file'

During handling of the above exception, another exception occurred:

Traceback (most recent call last):
  File "C:\Users\79069\AppData\Local\Programs\Python\Python39\lib\site-packages\googleapiclient\discovery_cache\__init__.py", line 44, in autodetect
    from . import file_cache
  File "C:\Users\79069\AppData\Local\Programs\Python\Python39\lib\site-packages\googleapiclient\discovery_cache\file_cache.py", line 40, in <module>
    raise ImportError(
ImportError: file_cache is unavailable when using oauth2client >= 4.0.0 or google-auth
DEBUG:googleapiclient.discovery:URL being requested: GET https://www.googleapis.com/discovery/v1/apis/drive/v3/rest
INFO:oauth2client.transport:Attempting refresh to obtain initial access_token
DEBUG:oauth2client.crypt:[b'eyJ0eXAiOiJKV1QiLCJhbGciOiJSUzI1NiIsImtpZCI6IjZiYzEzYmFjOTE0ZGZkNzliN2ZhOWQyODYxMzk5YzljZmY4OWFjNjcifQ', b'eyJhdWQiOiJodHRwczovL29hdXRoMi5nb29nbGVhcGlzLmNvbS90b2tlbiIsInNjb3BlIjoiaHR0cHM6Ly93d3cuZ29vZ2xlYXBpcy5jb20vYXV0aC9kcml2ZSIsImlhdCI6MTYxNDE3MTEwOSwiZXhwIjoxNjE0MTc0NzA5LCJpc3MiOiJqdXN0LWFjY291bnRAdGVzdGFwaWFuZHNoZWV0cy5pYW0uZ3NlcnZpY2VhY2NvdW50LmNvbSJ9', b'YDH6BuH4OPfNvwM98trbNOBozLvRN-ZKVRrgA5xhPGuDzdqswZ8BSlnEYEqHIed8DIaSBpOkv73vxfM33b4gVJBbcFVML41OglS9As_veHoykmslgnS2D56Zd2mT03Hk4Hv1u6supGpWE2bekbQD1BALeDFnHl808RMLlYjNiODtnLJwxELK99T-AMZ8ZIjorM9yK70mO13TjlPrMk7ybuAILCo9vEZiYFBkFvq4BdFCXMHy3mqr66M2a10qFulVZoPmCKDdOzIkUvmAkuOtPO01TBueMGYN3UJELxotNpgn0x0Q6MiAEPtGbg4ugx7zXmxQMY33qpA3zAO5C-__cg']
INFO:oauth2client.client:Refreshing access_token
DEBUG:googleapiclient.discovery:URL being requested: GET https://www.googleapis.com/drive/v3/files/12xpxsV0IhJT0mPqxdO9dzsMjONwI7EcW?alt=media
WARNING:googleapiclient.discovery_cache:file_cache is unavailable when using oauth2client >= 4.0.0 or google-auth
Traceback (most recent call last):
  File "C:\Users\79069\AppData\Local\Programs\Python\Python39\lib\site-packages\googleapiclient\discovery_cache\file_cache.py", line 33, in <module>
    from oauth2client.contrib.locked_file import LockedFile
ModuleNotFoundError: No module named 'oauth2client.contrib.locked_file'

During handling of the above exception, another exception occurred:

Traceback (most recent call last):
  File "C:\Users\79069\AppData\Local\Programs\Python\Python39\lib\site-packages\googleapiclient\discovery_cache\file_cache.py", line 37, in <module>
    from oauth2client.locked_file import LockedFile
ModuleNotFoundError: No module named 'oauth2client.locked_file'

During handling of the above exception, another exception occurred:

Traceback (most recent call last):
  File "C:\Users\79069\AppData\Local\Programs\Python\Python39\lib\site-packages\googleapiclient\discovery_cache\__init__.py", line 44, in autodetect
    from . import file_cache
  File "C:\Users\79069\AppData\Local\Programs\Python\Python39\lib\site-packages\googleapiclient\discovery_cache\file_cache.py", line 40, in <module>
    raise ImportError(
ImportError: file_cache is unavailable when using oauth2client >= 4.0.0 or google-auth
DEBUG:googleapiclient.discovery:URL being requested: GET https://www.googleapis.com/discovery/v1/apis/drive/v3/rest
INFO:oauth2client.transport:Attempting refresh to obtain initial access_token
DEBUG:oauth2client.crypt:[b'eyJ0eXAiOiJKV1QiLCJhbGciOiJSUzI1NiIsImtpZCI6IjZiYzEzYmFjOTE0ZGZkNzliN2ZhOWQyODYxMzk5YzljZmY4OWFjNjcifQ', b'eyJhdWQiOiJodHRwczovL29hdXRoMi5nb29nbGVhcGlzLmNvbS90b2tlbiIsInNjb3BlIjoiaHR0cHM6Ly93d3cuZ29vZ2xlYXBpcy5jb20vYXV0aC9kcml2ZSIsImlhdCI6MTYxNDE3MTEzOCwiZXhwIjoxNjE0MTc0NzM4LCJpc3MiOiJqdXN0LWFjY291bnRAdGVzdGFwaWFuZHNoZWV0cy5pYW0uZ3NlcnZpY2VhY2NvdW50LmNvbSJ9', b'HQX_txKWXh7msB8_aPpiP-wm8slcgbRwdezNuxycbpPXyCjhcJcInkxTAI7-8WdYaIDzrgtOAxIq-0KAU2gi3kzvlR9oVzvXtqy8Yhxfp3R_IQaPws6HYZlTq_rFCfjaJ7mz27Ol9Cz-Y3AHzNI0f4Vc1zwYEfWZTTQpNYL6-dsuYHUatWgydndf1AmmfZWtEWTuAu0kFZ-oj5vEiYKrQH7x52KVwd8oQXynCC_1T9fGPkQc5TcMcdyTyFBmetk-u20pMA2i3KYdIp7sUa0mbeIipH5f05CBM-NKuNDnP3jGPcYAOGZXzXDMCwUcRczdsMQHKsdaZ_c4WVDzv11tHw']
INFO:oauth2client.client:Refreshing access_token
DEBUG:googleapiclient.discovery:URL being requested: GET https://www.googleapis.com/drive/v3/files/12xpxsV0IhJT0mPqxdO9dzsMjONwI7EcW?alt=media
WARNING:googleapiclient.discovery_cache:file_cache is unavailable when using oauth2client >= 4.0.0 or google-auth
Traceback (most recent call last):
  File "C:\Users\79069\AppData\Local\Programs\Python\Python39\lib\site-packages\googleapiclient\discovery_cache\file_cache.py", line 33, in <module>
    from oauth2client.contrib.locked_file import LockedFile
ModuleNotFoundError: No module named 'oauth2client.contrib.locked_file'

During handling of the above exception, another exception occurred:

Traceback (most recent call last):
  File "C:\Users\79069\AppData\Local\Programs\Python\Python39\lib\site-packages\googleapiclient\discovery_cache\file_cache.py", line 37, in <module>
    from oauth2client.locked_file import LockedFile
ModuleNotFoundError: No module named 'oauth2client.locked_file'

During handling of the above exception, another exception occurred:

Traceback (most recent call last):
  File "C:\Users\79069\AppData\Local\Programs\Python\Python39\lib\site-packages\googleapiclient\discovery_cache\__init__.py", line 44, in autodetect
    from . import file_cache
  File "C:\Users\79069\AppData\Local\Programs\Python\Python39\lib\site-packages\googleapiclient\discovery_cache\file_cache.py", line 40, in <module>
    raise ImportError(
ImportError: file_cache is unavailable when using oauth2client >= 4.0.0 or google-auth
DEBUG:googleapiclient.discovery:URL being requested: GET https://www.googleapis.com/discovery/v1/apis/drive/v3/rest
INFO:oauth2client.transport:Attempting refresh to obtain initial access_token
DEBUG:oauth2client.crypt:[b'eyJ0eXAiOiJKV1QiLCJhbGciOiJSUzI1NiIsImtpZCI6IjZiYzEzYmFjOTE0ZGZkNzliN2ZhOWQyODYxMzk5YzljZmY4OWFjNjcifQ', b'eyJhdWQiOiJodHRwczovL29hdXRoMi5nb29nbGVhcGlzLmNvbS90b2tlbiIsInNjb3BlIjoiaHR0cHM6Ly93d3cuZ29vZ2xlYXBpcy5jb20vYXV0aC9kcml2ZSIsImlhdCI6MTYxNDE3MTE2MSwiZXhwIjoxNjE0MTc0NzYxLCJpc3MiOiJqdXN0LWFjY291bnRAdGVzdGFwaWFuZHNoZWV0cy5pYW0uZ3NlcnZpY2VhY2NvdW50LmNvbSJ9', b'502nqLyQKBy5LS7JRZdLq2X_AQXiruN3y__D9DkGmwPU5VMhqptSRHS81OqZvS53RYL_XH4TigAglDqduT5hqQLFc4m_tL7KH8RYwVcKeBCfLBJJnhfsRYELudR_KwKWBPhJiZV8grQvSjJKIxzRl2uNkuhGWe1lFfwrXVCCocARFaSV6PAd-URmBOMS1ihN84paTb0aEibiVGxXqlNPQVbNb2NlrgMVxSvwFqqNciLKddjpV_b6-0BqcEv4duQvZDaJ8356kyU2gOyLKmPZwjRrC-L-zIxlJ4ViObu1Fo0bztrJ9j_m4xXg9zrrRtSZwc3mGjV6djGSftaTseIvag']
INFO:oauth2client.client:Refreshing access_token
DEBUG:googleapiclient.discovery:URL being requested: GET https://www.googleapis.com/drive/v3/files/12xpxsV0IhJT0mPqxdO9dzsMjONwI7EcW?alt=media
WARNING:googleapiclient.discovery_cache:file_cache is unavailable when using oauth2client >= 4.0.0 or google-auth
Traceback (most recent call last):
  File "C:\Users\79069\AppData\Local\Programs\Python\Python39\lib\site-packages\googleapiclient\discovery_cache\file_cache.py", line 33, in <module>
    from oauth2client.contrib.locked_file import LockedFile
ModuleNotFoundError: No module named 'oauth2client.contrib.locked_file'

During handling of the above exception, another exception occurred:

Traceback (most recent call last):
  File "C:\Users\79069\AppData\Local\Programs\Python\Python39\lib\site-packages\googleapiclient\discovery_cache\file_cache.py", line 37, in <module>
    from oauth2client.locked_file import LockedFile
ModuleNotFoundError: No module named 'oauth2client.locked_file'

During handling of the above exception, another exception occurred:

Traceback (most recent call last):
  File "C:\Users\79069\AppData\Local\Programs\Python\Python39\lib\site-packages\googleapiclient\discovery_cache\__init__.py", line 44, in autodetect
    from . import file_cache
  File "C:\Users\79069\AppData\Local\Programs\Python\Python39\lib\site-packages\googleapiclient\discovery_cache\file_cache.py", line 40, in <module>
    raise ImportError(
ImportError: file_cache is unavailable when using oauth2client >= 4.0.0 or google-auth
DEBUG:googleapiclient.discovery:URL being requested: GET https://www.googleapis.com/discovery/v1/apis/drive/v3/rest
INFO:oauth2client.transport:Attempting refresh to obtain initial access_token
DEBUG:oauth2client.crypt:[b'eyJ0eXAiOiJKV1QiLCJhbGciOiJSUzI1NiIsImtpZCI6IjZiYzEzYmFjOTE0ZGZkNzliN2ZhOWQyODYxMzk5YzljZmY4OWFjNjcifQ', b'eyJhdWQiOiJodHRwczovL29hdXRoMi5nb29nbGVhcGlzLmNvbS90b2tlbiIsInNjb3BlIjoiaHR0cHM6Ly93d3cuZ29vZ2xlYXBpcy5jb20vYXV0aC9kcml2ZSIsImlhdCI6MTYxNDE3MTE4OCwiZXhwIjoxNjE0MTc0Nzg4LCJpc3MiOiJqdXN0LWFjY291bnRAdGVzdGFwaWFuZHNoZWV0cy5pYW0uZ3NlcnZpY2VhY2NvdW50LmNvbSJ9', b'h1SOuw3_bbqhat5jxNBRXD_88DzD1vS70fXZ9jqmZ53IiYs6IAwL9dgloEvd9TSarM5u_Mz-DmJjWBbQIkyGVTnNpSiIWn-Fp97pIQum8ejmgYg1Rz9mDVJ-iMM0vNQ9bi2Mi4aJRSqe29wFOhuXKSUSl3yOaMhUfW2gSIVCWdbdF0-e1OKOeCViGfRKSTjP5Zbztxl_sxY7q2YXOrD3vdXpW4GWq2lIYIgkK_wNiOAPOJO__xHPqrS2XRpQXJAHV0a43C5yCGwYQ0l4mtxxYEWMJHCiXRWtUGjupDIt2fvY4PrvTXzvn_tMJQzDxdY2JYPC2HTr7GImxZJM1RWQ8Q']
INFO:oauth2client.client:Refreshing access_token
DEBUG:googleapiclient.discovery:URL being requested: GET https://www.googleapis.com/drive/v3/files/12xpxsV0IhJT0mPqxdO9dzsMjONwI7EcW?alt=media
ERROR:root:'Show_Test_Controller' object has no attribute 'task_object'
WARNING:googleapiclient.discovery_cache:file_cache is unavailable when using oauth2client >= 4.0.0 or google-auth
Traceback (most recent call last):
  File "C:\Users\79069\AppData\Local\Programs\Python\Python39\lib\site-packages\googleapiclient\discovery_cache\file_cache.py", line 33, in <module>
    from oauth2client.contrib.locked_file import LockedFile
ModuleNotFoundError: No module named 'oauth2client.contrib.locked_file'

During handling of the above exception, another exception occurred:

Traceback (most recent call last):
  File "C:\Users\79069\AppData\Local\Programs\Python\Python39\lib\site-packages\googleapiclient\discovery_cache\file_cache.py", line 37, in <module>
    from oauth2client.locked_file import LockedFile
ModuleNotFoundError: No module named 'oauth2client.locked_file'

During handling of the above exception, another exception occurred:

Traceback (most recent call last):
  File "C:\Users\79069\AppData\Local\Programs\Python\Python39\lib\site-packages\googleapiclient\discovery_cache\__init__.py", line 44, in autodetect
    from . import file_cache
  File "C:\Users\79069\AppData\Local\Programs\Python\Python39\lib\site-packages\googleapiclient\discovery_cache\file_cache.py", line 40, in <module>
    raise ImportError(
ImportError: file_cache is unavailable when using oauth2client >= 4.0.0 or google-auth
DEBUG:googleapiclient.discovery:URL being requested: GET https://www.googleapis.com/discovery/v1/apis/drive/v3/rest
INFO:oauth2client.transport:Attempting refresh to obtain initial access_token
DEBUG:oauth2client.crypt:[b'eyJ0eXAiOiJKV1QiLCJhbGciOiJSUzI1NiIsImtpZCI6IjZiYzEzYmFjOTE0ZGZkNzliN2ZhOWQyODYxMzk5YzljZmY4OWFjNjcifQ', b'eyJhdWQiOiJodHRwczovL29hdXRoMi5nb29nbGVhcGlzLmNvbS90b2tlbiIsInNjb3BlIjoiaHR0cHM6Ly93d3cuZ29vZ2xlYXBpcy5jb20vYXV0aC9kcml2ZSIsImlhdCI6MTYxNDE3MTI0OSwiZXhwIjoxNjE0MTc0ODQ5LCJpc3MiOiJqdXN0LWFjY291bnRAdGVzdGFwaWFuZHNoZWV0cy5pYW0uZ3NlcnZpY2VhY2NvdW50LmNvbSJ9', b'jxnxhipIUsP8lh5pO1tJCSQ-u5B2Qk49PKw4TyK_FHQE-0fTDn5YfyLEdoLPAV-9Ig4Z45HMRFYqnhfYRakwaO0pf__L4n70Hfe_14UWueCThxWRpXsTYifavNPZd5VWYHsvWW50BmhZIO5dtBFAq5Ddl8BQLR0wWGxXQ8W2H0w03Vuj9OArxxFDvdO533dPbtDW_ypocZoW0dyqx2CdySLftEhohlRWw9-BEv759EWMUJ-iFg9iM-80CspRw4Bh_DbNRx6e2SoPKNNvowaLoViYyEyxkUAzTv34vjkDW5yXbIT07gQB7PZiRzxGuonTaa55ZADzWwisgh0ABiI81A']
INFO:oauth2client.client:Refreshing access_token
DEBUG:googleapiclient.discovery:URL being requested: GET https://www.googleapis.com/drive/v3/files/12xpxsV0IhJT0mPqxdO9dzsMjONwI7EcW?alt=media
ERROR:root:'Show_Test_Controller' object has no attribute 'task_object'
WARNING:googleapiclient.discovery_cache:file_cache is unavailable when using oauth2client >= 4.0.0 or google-auth
Traceback (most recent call last):
  File "C:\Users\79069\AppData\Local\Programs\Python\Python39\lib\site-packages\googleapiclient\discovery_cache\file_cache.py", line 33, in <module>
    from oauth2client.contrib.locked_file import LockedFile
ModuleNotFoundError: No module named 'oauth2client.contrib.locked_file'

During handling of the above exception, another exception occurred:

Traceback (most recent call last):
  File "C:\Users\79069\AppData\Local\Programs\Python\Python39\lib\site-packages\googleapiclient\discovery_cache\file_cache.py", line 37, in <module>
    from oauth2client.locked_file import LockedFile
ModuleNotFoundError: No module named 'oauth2client.locked_file'

During handling of the above exception, another exception occurred:

Traceback (most recent call last):
  File "C:\Users\79069\AppData\Local\Programs\Python\Python39\lib\site-packages\googleapiclient\discovery_cache\__init__.py", line 44, in autodetect
    from . import file_cache
  File "C:\Users\79069\AppData\Local\Programs\Python\Python39\lib\site-packages\googleapiclient\discovery_cache\file_cache.py", line 40, in <module>
    raise ImportError(
ImportError: file_cache is unavailable when using oauth2client >= 4.0.0 or google-auth
DEBUG:googleapiclient.discovery:URL being requested: GET https://www.googleapis.com/discovery/v1/apis/drive/v3/rest
INFO:oauth2client.transport:Attempting refresh to obtain initial access_token
DEBUG:oauth2client.crypt:[b'eyJ0eXAiOiJKV1QiLCJhbGciOiJSUzI1NiIsImtpZCI6IjZiYzEzYmFjOTE0ZGZkNzliN2ZhOWQyODYxMzk5YzljZmY4OWFjNjcifQ', b'eyJhdWQiOiJodHRwczovL29hdXRoMi5nb29nbGVhcGlzLmNvbS90b2tlbiIsInNjb3BlIjoiaHR0cHM6Ly93d3cuZ29vZ2xlYXBpcy5jb20vYXV0aC9kcml2ZSIsImlhdCI6MTYxNDE3MTI3NiwiZXhwIjoxNjE0MTc0ODc2LCJpc3MiOiJqdXN0LWFjY291bnRAdGVzdGFwaWFuZHNoZWV0cy5pYW0uZ3NlcnZpY2VhY2NvdW50LmNvbSJ9', b'f69OKlAXW0Su_sttSqvWj5EZEzi1CrRaQajQ0EY0OS3IdQdRni9ig1aBy5L-PR2JkF07QQFWAh5RWLBdJrx5R4hbjJfg_0LXvBnykfctGgsWmLAiF46cFHj-Ci3EoHMiKVsCeTny5LhoYsM-JcMTAaCWnlbS29OVHjv3Pz9MbH3Q0piJdkHHqAE3XRrdOWuOP6ToCgypV7P5ObMiQHxJjz9cqdf7G90VyIrNfYmxsqJ4xcnZ8GQa9EpuSz5qf4dbvWOJOCgwIUb9GXA6M0cLNg9oZsMs1U4bcfkEVrqK-5y3H3hKBqIW-MPFx3HXJsWeDSPxnmpOCUCDEu1ZjB_gcg']
INFO:oauth2client.client:Refreshing access_token
DEBUG:googleapiclient.discovery:URL being requested: GET https://www.googleapis.com/drive/v3/files/12xpxsV0IhJT0mPqxdO9dzsMjONwI7EcW?alt=media
WARNING:googleapiclient.discovery_cache:file_cache is unavailable when using oauth2client >= 4.0.0 or google-auth
Traceback (most recent call last):
  File "C:\Users\79069\AppData\Local\Programs\Python\Python39\lib\site-packages\googleapiclient\discovery_cache\file_cache.py", line 33, in <module>
    from oauth2client.contrib.locked_file import LockedFile
ModuleNotFoundError: No module named 'oauth2client.contrib.locked_file'

During handling of the above exception, another exception occurred:

Traceback (most recent call last):
  File "C:\Users\79069\AppData\Local\Programs\Python\Python39\lib\site-packages\googleapiclient\discovery_cache\file_cache.py", line 37, in <module>
    from oauth2client.locked_file import LockedFile
ModuleNotFoundError: No module named 'oauth2client.locked_file'

During handling of the above exception, another exception occurred:

Traceback (most recent call last):
  File "C:\Users\79069\AppData\Local\Programs\Python\Python39\lib\site-packages\googleapiclient\discovery_cache\__init__.py", line 44, in autodetect
    from . import file_cache
  File "C:\Users\79069\AppData\Local\Programs\Python\Python39\lib\site-packages\googleapiclient\discovery_cache\file_cache.py", line 40, in <module>
    raise ImportError(
ImportError: file_cache is unavailable when using oauth2client >= 4.0.0 or google-auth
DEBUG:googleapiclient.discovery:URL being requested: GET https://www.googleapis.com/discovery/v1/apis/drive/v3/rest
INFO:oauth2client.transport:Attempting refresh to obtain initial access_token
DEBUG:oauth2client.crypt:[b'eyJ0eXAiOiJKV1QiLCJhbGciOiJSUzI1NiIsImtpZCI6IjZiYzEzYmFjOTE0ZGZkNzliN2ZhOWQyODYxMzk5YzljZmY4OWFjNjcifQ', b'eyJhdWQiOiJodHRwczovL29hdXRoMi5nb29nbGVhcGlzLmNvbS90b2tlbiIsInNjb3BlIjoiaHR0cHM6Ly93d3cuZ29vZ2xlYXBpcy5jb20vYXV0aC9kcml2ZSIsImlhdCI6MTYxNDE3MTMzOCwiZXhwIjoxNjE0MTc0OTM4LCJpc3MiOiJqdXN0LWFjY291bnRAdGVzdGFwaWFuZHNoZWV0cy5pYW0uZ3NlcnZpY2VhY2NvdW50LmNvbSJ9', b'IiE5mpw1pGpgUNVPe-Q-efh3ItizVvyu4cBUdSxGMGwpwny8WnInmQHast2Hi9vNDO6u9k2YAfnvrKy7DTWt6Q4Nte4GTgEiId5MSvl73IpmMsHM1ReRYxJDxtRh4fDJmBy0T6_zJSLG2aQkLIYvlPGws8skUfA4H5CCMh4LAgKOy3H1gf0bK0_athotFTGhZyxN5gZHAlmOSEN1oZZoTBobffY5zk_hjxjrlLGdYwrdscOauq0xxffoxy9AOOGJnq-xVbGOjQrMWxBjm8GjuDgBU_axEvFdDVYNtEVkG6aiiRb0Ohw2Gam2c3_zJwxJlzPxHp8x5a3LLjVzY_4oiw']
INFO:oauth2client.client:Refreshing access_token
DEBUG:googleapiclient.discovery:URL being requested: GET https://www.googleapis.com/drive/v3/files/12xpxsV0IhJT0mPqxdO9dzsMjONwI7EcW?alt=media
WARNING:googleapiclient.discovery_cache:file_cache is unavailable when using oauth2client >= 4.0.0 or google-auth
Traceback (most recent call last):
  File "C:\Users\79069\AppData\Local\Programs\Python\Python39\lib\site-packages\googleapiclient\discovery_cache\file_cache.py", line 33, in <module>
    from oauth2client.contrib.locked_file import LockedFile
ModuleNotFoundError: No module named 'oauth2client.contrib.locked_file'

During handling of the above exception, another exception occurred:

Traceback (most recent call last):
  File "C:\Users\79069\AppData\Local\Programs\Python\Python39\lib\site-packages\googleapiclient\discovery_cache\file_cache.py", line 37, in <module>
    from oauth2client.locked_file import LockedFile
ModuleNotFoundError: No module named 'oauth2client.locked_file'

During handling of the above exception, another exception occurred:

Traceback (most recent call last):
  File "C:\Users\79069\AppData\Local\Programs\Python\Python39\lib\site-packages\googleapiclient\discovery_cache\__init__.py", line 44, in autodetect
    from . import file_cache
  File "C:\Users\79069\AppData\Local\Programs\Python\Python39\lib\site-packages\googleapiclient\discovery_cache\file_cache.py", line 40, in <module>
    raise ImportError(
ImportError: file_cache is unavailable when using oauth2client >= 4.0.0 or google-auth
DEBUG:googleapiclient.discovery:URL being requested: GET https://www.googleapis.com/discovery/v1/apis/drive/v3/rest
INFO:oauth2client.transport:Attempting refresh to obtain initial access_token
DEBUG:oauth2client.crypt:[b'eyJ0eXAiOiJKV1QiLCJhbGciOiJSUzI1NiIsImtpZCI6IjZiYzEzYmFjOTE0ZGZkNzliN2ZhOWQyODYxMzk5YzljZmY4OWFjNjcifQ', b'eyJhdWQiOiJodHRwczovL29hdXRoMi5nb29nbGVhcGlzLmNvbS90b2tlbiIsInNjb3BlIjoiaHR0cHM6Ly93d3cuZ29vZ2xlYXBpcy5jb20vYXV0aC9kcml2ZSIsImlhdCI6MTYxNDE3MTM0NSwiZXhwIjoxNjE0MTc0OTQ1LCJpc3MiOiJqdXN0LWFjY291bnRAdGVzdGFwaWFuZHNoZWV0cy5pYW0uZ3NlcnZpY2VhY2NvdW50LmNvbSJ9', b'agQKvhnBo0PkPmwYaEwcmyoyjOUJakK-6FxCQUAYJAYDgYnmfDSOufFYOc5vZuJHeYj0lBf_1cDKzo7yvK-iNfUoGxsLPuzVaDJWfhv5TT-sbTw-I_D0WbAKv4vkQsYzM0ySKDYlU-fM2aoKGNubpmvcaho2tDluC8IFcWbk1sJWQoUXbIP2S3jvQMJ1kOWV_uxem-Hym6Zt2QvLmp-oltpDJUdN4tvW57GtxB2Sw4DKggl7w5mSCT9O8ve0InCql1kg3qrnrVpvvOyxMYlupbvkhDaWKrJIAkhwJ7qLZhQDXWrt8YYbZFFLUIs2T0lr2bfCXebdedfHLLZI-Inzjg']
INFO:oauth2client.client:Refreshing access_token
DEBUG:googleapiclient.discovery:URL being requested: POST https://www.googleapis.com/upload/drive/v3/files?fields=id&alt=json&uploadType=multipart
WARNING:googleapiclient.discovery_cache:file_cache is unavailable when using oauth2client >= 4.0.0 or google-auth
Traceback (most recent call last):
  File "C:\Users\79069\AppData\Local\Programs\Python\Python39\lib\site-packages\googleapiclient\discovery_cache\file_cache.py", line 33, in <module>
    from oauth2client.contrib.locked_file import LockedFile
ModuleNotFoundError: No module named 'oauth2client.contrib.locked_file'

During handling of the above exception, another exception occurred:

Traceback (most recent call last):
  File "C:\Users\79069\AppData\Local\Programs\Python\Python39\lib\site-packages\googleapiclient\discovery_cache\file_cache.py", line 37, in <module>
    from oauth2client.locked_file import LockedFile
ModuleNotFoundError: No module named 'oauth2client.locked_file'

During handling of the above exception, another exception occurred:

Traceback (most recent call last):
  File "C:\Users\79069\AppData\Local\Programs\Python\Python39\lib\site-packages\googleapiclient\discovery_cache\__init__.py", line 44, in autodetect
    from . import file_cache
  File "C:\Users\79069\AppData\Local\Programs\Python\Python39\lib\site-packages\googleapiclient\discovery_cache\file_cache.py", line 40, in <module>
    raise ImportError(
ImportError: file_cache is unavailable when using oauth2client >= 4.0.0 or google-auth
DEBUG:googleapiclient.discovery:URL being requested: GET https://www.googleapis.com/discovery/v1/apis/drive/v3/rest
INFO:oauth2client.transport:Attempting refresh to obtain initial access_token
DEBUG:oauth2client.crypt:[b'eyJ0eXAiOiJKV1QiLCJhbGciOiJSUzI1NiIsImtpZCI6IjZiYzEzYmFjOTE0ZGZkNzliN2ZhOWQyODYxMzk5YzljZmY4OWFjNjcifQ', b'eyJhdWQiOiJodHRwczovL29hdXRoMi5nb29nbGVhcGlzLmNvbS90b2tlbiIsInNjb3BlIjoiaHR0cHM6Ly93d3cuZ29vZ2xlYXBpcy5jb20vYXV0aC9kcml2ZSIsImlhdCI6MTYxNDE3MTU3NCwiZXhwIjoxNjE0MTc1MTc0LCJpc3MiOiJqdXN0LWFjY291bnRAdGVzdGFwaWFuZHNoZWV0cy5pYW0uZ3NlcnZpY2VhY2NvdW50LmNvbSJ9', b'VvA13nJ0kqRXZQOeoK8IHOUuOPDs8qnSYJ8dWly2bn0ZOBuYVVncsk_4QMZxlHnyGcf3XRAMHX_Phr_U0IXtOKKDJqi53LLb-G4R9T6K6lW4AUXV7wTA79T7Hq-TMb2jtLlMmSx-qSr3-hMIeHZEstDsOvvzvgXv8S7uqz0A6na2xD5veV142tquToj95EX7UJW4P3OUMYF1Q6DBswz-bgfrU3z5P2EVqVrznbWWm4uqeIv__XyZVPDe3NnylFE0J12B6aDih8kb-wImXYCkpxkzrDRbNziBKzbhb-epHQPkF1lsL3JCcKrXtqztS6xGGycPcnlb6s2AddkcDgluKg']
INFO:oauth2client.client:Refreshing access_token
DEBUG:googleapiclient.discovery:URL being requested: GET https://www.googleapis.com/drive/v3/files/1-GLrj8pJ11Y72fqamsqbb1I3X7t680Wb?alt=media
WARNING:googleapiclient.discovery_cache:file_cache is unavailable when using oauth2client >= 4.0.0 or google-auth
Traceback (most recent call last):
  File "C:\Users\79069\AppData\Local\Programs\Python\Python39\lib\site-packages\googleapiclient\discovery_cache\file_cache.py", line 33, in <module>
    from oauth2client.contrib.locked_file import LockedFile
ModuleNotFoundError: No module named 'oauth2client.contrib.locked_file'

During handling of the above exception, another exception occurred:

Traceback (most recent call last):
  File "C:\Users\79069\AppData\Local\Programs\Python\Python39\lib\site-packages\googleapiclient\discovery_cache\file_cache.py", line 37, in <module>
    from oauth2client.locked_file import LockedFile
ModuleNotFoundError: No module named 'oauth2client.locked_file'

During handling of the above exception, another exception occurred:

Traceback (most recent call last):
  File "C:\Users\79069\AppData\Local\Programs\Python\Python39\lib\site-packages\googleapiclient\discovery_cache\__init__.py", line 44, in autodetect
    from . import file_cache
  File "C:\Users\79069\AppData\Local\Programs\Python\Python39\lib\site-packages\googleapiclient\discovery_cache\file_cache.py", line 40, in <module>
    raise ImportError(
ImportError: file_cache is unavailable when using oauth2client >= 4.0.0 or google-auth
DEBUG:googleapiclient.discovery:URL being requested: GET https://www.googleapis.com/discovery/v1/apis/drive/v3/rest
INFO:oauth2client.transport:Attempting refresh to obtain initial access_token
DEBUG:oauth2client.crypt:[b'eyJ0eXAiOiJKV1QiLCJhbGciOiJSUzI1NiIsImtpZCI6IjZiYzEzYmFjOTE0ZGZkNzliN2ZhOWQyODYxMzk5YzljZmY4OWFjNjcifQ', b'eyJhdWQiOiJodHRwczovL29hdXRoMi5nb29nbGVhcGlzLmNvbS90b2tlbiIsInNjb3BlIjoiaHR0cHM6Ly93d3cuZ29vZ2xlYXBpcy5jb20vYXV0aC9kcml2ZSIsImlhdCI6MTYxNDE3MTU4MSwiZXhwIjoxNjE0MTc1MTgxLCJpc3MiOiJqdXN0LWFjY291bnRAdGVzdGFwaWFuZHNoZWV0cy5pYW0uZ3NlcnZpY2VhY2NvdW50LmNvbSJ9', b'AeuzdFTb3SCiojz9F1uNEXJKaA5s5VYLZ5WAkBeGMhwEinYIiWhcqKRjPApFcqG6oEUdlc9ZEeQz3HofYQPEW_4dkPY2BUtZrjvIljizJja23L7Y-0Dd6bJfCkj7hk-zyN5eklFqkfxfcXIG_arl-1TX1AVAgTxH0CisdlT1GMEBF3gkEtrmfkquyLTUfDJK5aD71smRoGHGNojjmIL3PyZ4pi6ZQ_vYBvN7pHOb1V0t4mNC736OcPIy3yJi6IsGh_i_cNlamRAGkfRRyDU6Y4rdVoTXNUhfQLQYChFiGCeF2_UyZVtTU_A3kxynWjsAx-KiNGAU_h-f_o4d5OPfvg']
INFO:oauth2client.client:Refreshing access_token
DEBUG:googleapiclient.discovery:URL being requested: POST https://www.googleapis.com/upload/drive/v3/files?fields=id&alt=json&uploadType=multipart
WARNING:googleapiclient.discovery_cache:file_cache is unavailable when using oauth2client >= 4.0.0 or google-auth
Traceback (most recent call last):
  File "C:\Users\79069\AppData\Local\Programs\Python\Python39\lib\site-packages\googleapiclient\discovery_cache\file_cache.py", line 33, in <module>
    from oauth2client.contrib.locked_file import LockedFile
ModuleNotFoundError: No module named 'oauth2client.contrib.locked_file'

During handling of the above exception, another exception occurred:

Traceback (most recent call last):
  File "C:\Users\79069\AppData\Local\Programs\Python\Python39\lib\site-packages\googleapiclient\discovery_cache\file_cache.py", line 37, in <module>
    from oauth2client.locked_file import LockedFile
ModuleNotFoundError: No module named 'oauth2client.locked_file'

During handling of the above exception, another exception occurred:

Traceback (most recent call last):
  File "C:\Users\79069\AppData\Local\Programs\Python\Python39\lib\site-packages\googleapiclient\discovery_cache\__init__.py", line 44, in autodetect
    from . import file_cache
  File "C:\Users\79069\AppData\Local\Programs\Python\Python39\lib\site-packages\googleapiclient\discovery_cache\file_cache.py", line 40, in <module>
    raise ImportError(
ImportError: file_cache is unavailable when using oauth2client >= 4.0.0 or google-auth
DEBUG:googleapiclient.discovery:URL being requested: GET https://www.googleapis.com/discovery/v1/apis/drive/v3/rest
INFO:oauth2client.transport:Attempting refresh to obtain initial access_token
DEBUG:oauth2client.crypt:[b'eyJ0eXAiOiJKV1QiLCJhbGciOiJSUzI1NiIsImtpZCI6IjZiYzEzYmFjOTE0ZGZkNzliN2ZhOWQyODYxMzk5YzljZmY4OWFjNjcifQ', b'eyJhdWQiOiJodHRwczovL29hdXRoMi5nb29nbGVhcGlzLmNvbS90b2tlbiIsInNjb3BlIjoiaHR0cHM6Ly93d3cuZ29vZ2xlYXBpcy5jb20vYXV0aC9kcml2ZSIsImlhdCI6MTYxNDE3MTYwMCwiZXhwIjoxNjE0MTc1MjAwLCJpc3MiOiJqdXN0LWFjY291bnRAdGVzdGFwaWFuZHNoZWV0cy5pYW0uZ3NlcnZpY2VhY2NvdW50LmNvbSJ9', b'cbsbNq3uQM9sY-mEK46q17zDqA0CNnXaILmDrfDjOxZqUdKMqCjYX172vTDNnKIKKRu_GtpQajqXp1Z_qVGICVYS6l7jNVfGPH0CFRMj5HqB75CGGd2YRMQB-eG0V8pdI_DlxsfTk6LQeUNV53a_GbmYBH77RGf3IpINmwCsw_S6DIj9n6Uy6zs55a2oHrKS2qRe9WonGX4lJOE9vDBPKDR2cwqra0KTokiEMl7XX1pL2xeAU6p9mVigvd3egL4gMoPRRX1EEC9QbiGuK4uZN1JeoPQezBQkfUSuqMQ_q3NbHGr4KW-rvmxMLEUoQa03UgO37oev3xN9uFuikjKbeA']
INFO:oauth2client.client:Refreshing access_token
DEBUG:googleapiclient.discovery:URL being requested: GET https://www.googleapis.com/drive/v3/files/1-GLrj8pJ11Y72fqamsqbb1I3X7t680Wb?alt=media
WARNING:googleapiclient.discovery_cache:file_cache is unavailable when using oauth2client >= 4.0.0 or google-auth
Traceback (most recent call last):
  File "C:\Users\79069\AppData\Local\Programs\Python\Python39\lib\site-packages\googleapiclient\discovery_cache\file_cache.py", line 33, in <module>
    from oauth2client.contrib.locked_file import LockedFile
ModuleNotFoundError: No module named 'oauth2client.contrib.locked_file'

During handling of the above exception, another exception occurred:

Traceback (most recent call last):
  File "C:\Users\79069\AppData\Local\Programs\Python\Python39\lib\site-packages\googleapiclient\discovery_cache\file_cache.py", line 37, in <module>
    from oauth2client.locked_file import LockedFile
ModuleNotFoundError: No module named 'oauth2client.locked_file'

During handling of the above exception, another exception occurred:

Traceback (most recent call last):
  File "C:\Users\79069\AppData\Local\Programs\Python\Python39\lib\site-packages\googleapiclient\discovery_cache\__init__.py", line 44, in autodetect
    from . import file_cache
  File "C:\Users\79069\AppData\Local\Programs\Python\Python39\lib\site-packages\googleapiclient\discovery_cache\file_cache.py", line 40, in <module>
    raise ImportError(
ImportError: file_cache is unavailable when using oauth2client >= 4.0.0 or google-auth
DEBUG:googleapiclient.discovery:URL being requested: GET https://www.googleapis.com/discovery/v1/apis/drive/v3/rest
INFO:oauth2client.transport:Attempting refresh to obtain initial access_token
DEBUG:oauth2client.crypt:[b'eyJ0eXAiOiJKV1QiLCJhbGciOiJSUzI1NiIsImtpZCI6IjZiYzEzYmFjOTE0ZGZkNzliN2ZhOWQyODYxMzk5YzljZmY4OWFjNjcifQ', b'eyJhdWQiOiJodHRwczovL29hdXRoMi5nb29nbGVhcGlzLmNvbS90b2tlbiIsInNjb3BlIjoiaHR0cHM6Ly93d3cuZ29vZ2xlYXBpcy5jb20vYXV0aC9kcml2ZSIsImlhdCI6MTYxNDE3MTYwNiwiZXhwIjoxNjE0MTc1MjA2LCJpc3MiOiJqdXN0LWFjY291bnRAdGVzdGFwaWFuZHNoZWV0cy5pYW0uZ3NlcnZpY2VhY2NvdW50LmNvbSJ9', b'y-DYKp5PvlyPu1Air1o-zTmSy1o4vQvKnoDQFDzYN1GHNgpCZoAwvpE7kn-bhsuSSReOa_hjVJw3bBtqlqYdUjNAYhiUY5W-5jsLI2qqknGnIsLm-CldopJOnMY7aDvMHo1qRq5ulC1yLCcaMPKfsw5EtOFJEjPgWz7YI0xywtju4Hp0eXspBjiZ7AuDLQj4rMIP_MAW2qx7u-n1KJEhx6Cnis6stp-Lkn58aieeF98hx63pGRKQbvN1F64UBGNe_i4xO1lsR4DWMERM8RBXt8tkfo0M98W7R2osJNF2zIs7x4qH_jxpG7gX9LMov4XbwZ8z9UFgnb42Cp5RLBnp-A']
INFO:oauth2client.client:Refreshing access_token
DEBUG:googleapiclient.discovery:URL being requested: POST https://www.googleapis.com/upload/drive/v3/files?fields=id&alt=json&uploadType=multipart
WARNING:googleapiclient.discovery_cache:file_cache is unavailable when using oauth2client >= 4.0.0 or google-auth
Traceback (most recent call last):
  File "C:\Users\79069\AppData\Local\Programs\Python\Python39\lib\site-packages\googleapiclient\discovery_cache\file_cache.py", line 33, in <module>
    from oauth2client.contrib.locked_file import LockedFile
ModuleNotFoundError: No module named 'oauth2client.contrib.locked_file'

During handling of the above exception, another exception occurred:

Traceback (most recent call last):
  File "C:\Users\79069\AppData\Local\Programs\Python\Python39\lib\site-packages\googleapiclient\discovery_cache\file_cache.py", line 37, in <module>
    from oauth2client.locked_file import LockedFile
ModuleNotFoundError: No module named 'oauth2client.locked_file'

During handling of the above exception, another exception occurred:

Traceback (most recent call last):
  File "C:\Users\79069\AppData\Local\Programs\Python\Python39\lib\site-packages\googleapiclient\discovery_cache\__init__.py", line 44, in autodetect
    from . import file_cache
  File "C:\Users\79069\AppData\Local\Programs\Python\Python39\lib\site-packages\googleapiclient\discovery_cache\file_cache.py", line 40, in <module>
    raise ImportError(
ImportError: file_cache is unavailable when using oauth2client >= 4.0.0 or google-auth
DEBUG:googleapiclient.discovery:URL being requested: GET https://www.googleapis.com/discovery/v1/apis/drive/v3/rest
INFO:oauth2client.transport:Attempting refresh to obtain initial access_token
DEBUG:oauth2client.crypt:[b'eyJ0eXAiOiJKV1QiLCJhbGciOiJSUzI1NiIsImtpZCI6IjZiYzEzYmFjOTE0ZGZkNzliN2ZhOWQyODYxMzk5YzljZmY4OWFjNjcifQ', b'eyJhdWQiOiJodHRwczovL29hdXRoMi5nb29nbGVhcGlzLmNvbS90b2tlbiIsInNjb3BlIjoiaHR0cHM6Ly93d3cuZ29vZ2xlYXBpcy5jb20vYXV0aC9kcml2ZSIsImlhdCI6MTYxNDE3MTY1NywiZXhwIjoxNjE0MTc1MjU3LCJpc3MiOiJqdXN0LWFjY291bnRAdGVzdGFwaWFuZHNoZWV0cy5pYW0uZ3NlcnZpY2VhY2NvdW50LmNvbSJ9', b'gfu1Uok1HqBCsiLfQgSWexm0-JOHGIrSaBx2xrA1PYpoahOl5kcGvpjxt6_FY4IrksgYpv8v1INrtMC2CCqNi4YpODn2IU1nTp35Ts7INWVzgERfR1P4PaBMDe0m4UCRFgWK_KlAAdBOSuXwxGgZdmk2emH46zLzVAfvjcOE7-m9s224HIeQV9Kya9G4P3T5XNyRsD9J_XRDM1PGxS4N6h_epHv5nbXM67QnvSLrCvf6j_Am9RYCEHlVn0ML5DUgY3uaRwYXsfbYkjayuKvYdrfohExBAIeHgY1nAYCwiwTRwVx7iTCxdSQmaI7Fh60fXjOmdWcPO3X6FXGtUKvyxA']
INFO:oauth2client.client:Refreshing access_token
DEBUG:googleapiclient.discovery:URL being requested: GET https://www.googleapis.com/drive/v3/files/1-GLrj8pJ11Y72fqamsqbb1I3X7t680Wb?alt=media
WARNING:googleapiclient.discovery_cache:file_cache is unavailable when using oauth2client >= 4.0.0 or google-auth
Traceback (most recent call last):
  File "C:\Users\79069\AppData\Local\Programs\Python\Python39\lib\site-packages\googleapiclient\discovery_cache\file_cache.py", line 33, in <module>
    from oauth2client.contrib.locked_file import LockedFile
ModuleNotFoundError: No module named 'oauth2client.contrib.locked_file'

During handling of the above exception, another exception occurred:

Traceback (most recent call last):
  File "C:\Users\79069\AppData\Local\Programs\Python\Python39\lib\site-packages\googleapiclient\discovery_cache\file_cache.py", line 37, in <module>
    from oauth2client.locked_file import LockedFile
ModuleNotFoundError: No module named 'oauth2client.locked_file'

During handling of the above exception, another exception occurred:

Traceback (most recent call last):
  File "C:\Users\79069\AppData\Local\Programs\Python\Python39\lib\site-packages\googleapiclient\discovery_cache\__init__.py", line 44, in autodetect
    from . import file_cache
  File "C:\Users\79069\AppData\Local\Programs\Python\Python39\lib\site-packages\googleapiclient\discovery_cache\file_cache.py", line 40, in <module>
    raise ImportError(
ImportError: file_cache is unavailable when using oauth2client >= 4.0.0 or google-auth
DEBUG:googleapiclient.discovery:URL being requested: GET https://www.googleapis.com/discovery/v1/apis/drive/v3/rest
INFO:oauth2client.transport:Attempting refresh to obtain initial access_token
DEBUG:oauth2client.crypt:[b'eyJ0eXAiOiJKV1QiLCJhbGciOiJSUzI1NiIsImtpZCI6IjZiYzEzYmFjOTE0ZGZkNzliN2ZhOWQyODYxMzk5YzljZmY4OWFjNjcifQ', b'eyJhdWQiOiJodHRwczovL29hdXRoMi5nb29nbGVhcGlzLmNvbS90b2tlbiIsInNjb3BlIjoiaHR0cHM6Ly93d3cuZ29vZ2xlYXBpcy5jb20vYXV0aC9kcml2ZSIsImlhdCI6MTYxNDE3MTY2MywiZXhwIjoxNjE0MTc1MjYzLCJpc3MiOiJqdXN0LWFjY291bnRAdGVzdGFwaWFuZHNoZWV0cy5pYW0uZ3NlcnZpY2VhY2NvdW50LmNvbSJ9', b'SQf2MtxojC6SMJopr4V18rk2syuDKRaFvgGPJ-F7dL6wkccLFGfV6DfVhefL2wXioUCyNMzT2jhv15XSpHSjPTSuzSusIAbU42HDUGtKZuQAqQuz24wDw1_IbcNwnZoRtbuGCnrbpDeZShtmGMVeRWba5-_XliS5iabK3HssstFpiqyNewHPD-aqxI9E80sN_eJBAPwfKBRS_mX5_FVuyh0BvS1NAQDvoFAT3qPpOHsIxnsUuSbtnVyoJ45qe-Qr9-5WIw_lSOnBfp2bJ0_eIshR2jzwrKmFqQoPdOZS34p-5HdKGYxAoDO9InxIsGhbgEry77Dd0ETl9KBxTgDs1A']
INFO:oauth2client.client:Refreshing access_token
DEBUG:googleapiclient.discovery:URL being requested: POST https://www.googleapis.com/upload/drive/v3/files?fields=id&alt=json&uploadType=multipart
WARNING:googleapiclient.discovery_cache:file_cache is unavailable when using oauth2client >= 4.0.0 or google-auth
Traceback (most recent call last):
  File "C:\Users\79069\AppData\Local\Programs\Python\Python39\lib\site-packages\googleapiclient\discovery_cache\file_cache.py", line 33, in <module>
    from oauth2client.contrib.locked_file import LockedFile
ModuleNotFoundError: No module named 'oauth2client.contrib.locked_file'

During handling of the above exception, another exception occurred:

Traceback (most recent call last):
  File "C:\Users\79069\AppData\Local\Programs\Python\Python39\lib\site-packages\googleapiclient\discovery_cache\file_cache.py", line 37, in <module>
    from oauth2client.locked_file import LockedFile
ModuleNotFoundError: No module named 'oauth2client.locked_file'

During handling of the above exception, another exception occurred:

Traceback (most recent call last):
  File "C:\Users\79069\AppData\Local\Programs\Python\Python39\lib\site-packages\googleapiclient\discovery_cache\__init__.py", line 44, in autodetect
    from . import file_cache
  File "C:\Users\79069\AppData\Local\Programs\Python\Python39\lib\site-packages\googleapiclient\discovery_cache\file_cache.py", line 40, in <module>
    raise ImportError(
ImportError: file_cache is unavailable when using oauth2client >= 4.0.0 or google-auth
DEBUG:googleapiclient.discovery:URL being requested: GET https://www.googleapis.com/discovery/v1/apis/drive/v3/rest
INFO:oauth2client.transport:Attempting refresh to obtain initial access_token
DEBUG:oauth2client.crypt:[b'eyJ0eXAiOiJKV1QiLCJhbGciOiJSUzI1NiIsImtpZCI6IjZiYzEzYmFjOTE0ZGZkNzliN2ZhOWQyODYxMzk5YzljZmY4OWFjNjcifQ', b'eyJhdWQiOiJodHRwczovL29hdXRoMi5nb29nbGVhcGlzLmNvbS90b2tlbiIsInNjb3BlIjoiaHR0cHM6Ly93d3cuZ29vZ2xlYXBpcy5jb20vYXV0aC9kcml2ZSIsImlhdCI6MTYxNDIyMjE2NiwiZXhwIjoxNjE0MjI1NzY2LCJpc3MiOiJqdXN0LWFjY291bnRAdGVzdGFwaWFuZHNoZWV0cy5pYW0uZ3NlcnZpY2VhY2NvdW50LmNvbSJ9', b'JAl2djQ6uZk357iyLb8Z0hE1pRefT_xnTjDa-ECAs3sRakLtsb9Kl7FWmIT8GnJWOmV9cqJPefpaTiuq6cWz6WJd4ADNIrZYbsIQMKljqglrQWunz49UyA_S4UYbVrsrTtNswCNvN8J-4YsVgyPqqWS5cN4bTuSoDCzlLkjLtT_p_nR3SuL0jBzqgd3zx5gbikZ5Q4i_BAbq6wdaaAHHvrzveAYo4--EnWUeT00wsPBsbF53jN1FuFSYFkmIi02To1n5iwA5tVwQ8EnPItD41j_hRtGmnd874E-YiZctkyV1CSwDsUg4M7yPg5lbe73ATqvA0_sLVGHMESrsideOcg']
INFO:oauth2client.client:Refreshing access_token
DEBUG:googleapiclient.discovery:URL being requested: GET https://www.googleapis.com/drive/v3/files/12xpxsV0IhJT0mPqxdO9dzsMjONwI7EcW?alt=media
WARNING:googleapiclient.discovery_cache:file_cache is unavailable when using oauth2client >= 4.0.0 or google-auth
Traceback (most recent call last):
  File "C:\Users\79069\AppData\Local\Programs\Python\Python39\lib\site-packages\googleapiclient\discovery_cache\file_cache.py", line 33, in <module>
    from oauth2client.contrib.locked_file import LockedFile
ModuleNotFoundError: No module named 'oauth2client.contrib.locked_file'

During handling of the above exception, another exception occurred:

Traceback (most recent call last):
  File "C:\Users\79069\AppData\Local\Programs\Python\Python39\lib\site-packages\googleapiclient\discovery_cache\file_cache.py", line 37, in <module>
    from oauth2client.locked_file import LockedFile
ModuleNotFoundError: No module named 'oauth2client.locked_file'

During handling of the above exception, another exception occurred:

Traceback (most recent call last):
  File "C:\Users\79069\AppData\Local\Programs\Python\Python39\lib\site-packages\googleapiclient\discovery_cache\__init__.py", line 44, in autodetect
    from . import file_cache
  File "C:\Users\79069\AppData\Local\Programs\Python\Python39\lib\site-packages\googleapiclient\discovery_cache\file_cache.py", line 40, in <module>
    raise ImportError(
ImportError: file_cache is unavailable when using oauth2client >= 4.0.0 or google-auth
DEBUG:googleapiclient.discovery:URL being requested: GET https://www.googleapis.com/discovery/v1/apis/drive/v3/rest
INFO:oauth2client.transport:Attempting refresh to obtain initial access_token
DEBUG:oauth2client.crypt:[b'eyJ0eXAiOiJKV1QiLCJhbGciOiJSUzI1NiIsImtpZCI6IjZiYzEzYmFjOTE0ZGZkNzliN2ZhOWQyODYxMzk5YzljZmY4OWFjNjcifQ', b'eyJhdWQiOiJodHRwczovL29hdXRoMi5nb29nbGVhcGlzLmNvbS90b2tlbiIsInNjb3BlIjoiaHR0cHM6Ly93d3cuZ29vZ2xlYXBpcy5jb20vYXV0aC9kcml2ZSIsImlhdCI6MTYxNDIyMjIyNiwiZXhwIjoxNjE0MjI1ODI2LCJpc3MiOiJqdXN0LWFjY291bnRAdGVzdGFwaWFuZHNoZWV0cy5pYW0uZ3NlcnZpY2VhY2NvdW50LmNvbSJ9', b'uA1lrU_Kcbqx6yE2SDO0Mu6m4PECtfOzLNrMsgJeJqV9j392ve5y9cq9w3sE7F96EjvpYi-AcPbO8EI51IkeFEb7Dhh2b02fj8jMokloa7gIjntRbqaA8Hv22LWzPrD54gd-E9DoqV8pjlWDxEo_zsFLsZrJyD_Q-0_aEvXK7Vu2aZ6Erpf2REe2n_tw4QSLu5_be1cuRnSgfGbjPsK5kxlwDFXwaA5LYTjYlOUqeTrE7pYkRJ_aOYzzY8rITwh4oEv5deVn5c-Rv2OT_7vJdA3m_vEFZrKLMZOFUnPP23AyHNwF7KU7vEO_wr_IAoFCJvzVol2ZV5DoP771OJHlIg']
INFO:oauth2client.client:Refreshing access_token
DEBUG:googleapiclient.discovery:URL being requested: GET https://www.googleapis.com/drive/v3/files/12xpxsV0IhJT0mPqxdO9dzsMjONwI7EcW?alt=media
WARNING:googleapiclient.discovery_cache:file_cache is unavailable when using oauth2client >= 4.0.0 or google-auth
Traceback (most recent call last):
  File "C:\Users\79069\AppData\Local\Programs\Python\Python39\lib\site-packages\googleapiclient\discovery_cache\file_cache.py", line 33, in <module>
    from oauth2client.contrib.locked_file import LockedFile
ModuleNotFoundError: No module named 'oauth2client.contrib.locked_file'

During handling of the above exception, another exception occurred:

Traceback (most recent call last):
  File "C:\Users\79069\AppData\Local\Programs\Python\Python39\lib\site-packages\googleapiclient\discovery_cache\file_cache.py", line 37, in <module>
    from oauth2client.locked_file import LockedFile
ModuleNotFoundError: No module named 'oauth2client.locked_file'

During handling of the above exception, another exception occurred:

Traceback (most recent call last):
  File "C:\Users\79069\AppData\Local\Programs\Python\Python39\lib\site-packages\googleapiclient\discovery_cache\__init__.py", line 44, in autodetect
    from . import file_cache
  File "C:\Users\79069\AppData\Local\Programs\Python\Python39\lib\site-packages\googleapiclient\discovery_cache\file_cache.py", line 40, in <module>
    raise ImportError(
ImportError: file_cache is unavailable when using oauth2client >= 4.0.0 or google-auth
DEBUG:googleapiclient.discovery:URL being requested: GET https://www.googleapis.com/discovery/v1/apis/drive/v3/rest
INFO:oauth2client.transport:Attempting refresh to obtain initial access_token
DEBUG:oauth2client.crypt:[b'eyJ0eXAiOiJKV1QiLCJhbGciOiJSUzI1NiIsImtpZCI6IjZiYzEzYmFjOTE0ZGZkNzliN2ZhOWQyODYxMzk5YzljZmY4OWFjNjcifQ', b'eyJhdWQiOiJodHRwczovL29hdXRoMi5nb29nbGVhcGlzLmNvbS90b2tlbiIsInNjb3BlIjoiaHR0cHM6Ly93d3cuZ29vZ2xlYXBpcy5jb20vYXV0aC9kcml2ZSIsImlhdCI6MTYxNDIyMjg3NiwiZXhwIjoxNjE0MjI2NDc2LCJpc3MiOiJqdXN0LWFjY291bnRAdGVzdGFwaWFuZHNoZWV0cy5pYW0uZ3NlcnZpY2VhY2NvdW50LmNvbSJ9', b'7BBJtNzW9X0otY5Kez7Xx4P26EXaWaS1rfwZy92jQ6Get0sFfYirFvkN7YMGk4cj3Xzmy8YwxLwKX12eW-Vh0H3tZjP1nfsmzVPDRg88JSG2ZuYZNHK5QuJ_xRBK9BrIzgYG-pxoKtC8iN1_tYyS1BaN6N-5Yr0yrNTSSRRZyhaN7Ka3-FkmcVxZ80xZCYDEC7PaMjenpir5voErbPrIkIMeLsoJdoxztFcjQvyFGzmtr2Trq38MSsoEu7Q4SaN7BH3F-AcKHuPAgf5S-IZbybx9Rl4DGv8466WMtny_Quu7jS-4pSuEa2Mpx9E0QIaGLyRqVz2NMGunR_rI7wg_vg']
INFO:oauth2client.client:Refreshing access_token
DEBUG:googleapiclient.discovery:URL being requested: GET https://www.googleapis.com/drive/v3/files/12xpxsV0IhJT0mPqxdO9dzsMjONwI7EcW?alt=media
WARNING:googleapiclient.discovery_cache:file_cache is unavailable when using oauth2client >= 4.0.0 or google-auth
Traceback (most recent call last):
  File "C:\Users\79069\AppData\Local\Programs\Python\Python39\lib\site-packages\googleapiclient\discovery_cache\file_cache.py", line 33, in <module>
    from oauth2client.contrib.locked_file import LockedFile
ModuleNotFoundError: No module named 'oauth2client.contrib.locked_file'

During handling of the above exception, another exception occurred:

Traceback (most recent call last):
  File "C:\Users\79069\AppData\Local\Programs\Python\Python39\lib\site-packages\googleapiclient\discovery_cache\file_cache.py", line 37, in <module>
    from oauth2client.locked_file import LockedFile
ModuleNotFoundError: No module named 'oauth2client.locked_file'

During handling of the above exception, another exception occurred:

Traceback (most recent call last):
  File "C:\Users\79069\AppData\Local\Programs\Python\Python39\lib\site-packages\googleapiclient\discovery_cache\__init__.py", line 44, in autodetect
    from . import file_cache
  File "C:\Users\79069\AppData\Local\Programs\Python\Python39\lib\site-packages\googleapiclient\discovery_cache\file_cache.py", line 40, in <module>
    raise ImportError(
ImportError: file_cache is unavailable when using oauth2client >= 4.0.0 or google-auth
DEBUG:googleapiclient.discovery:URL being requested: GET https://www.googleapis.com/discovery/v1/apis/drive/v3/rest
INFO:oauth2client.transport:Attempting refresh to obtain initial access_token
DEBUG:oauth2client.crypt:[b'eyJ0eXAiOiJKV1QiLCJhbGciOiJSUzI1NiIsImtpZCI6IjZiYzEzYmFjOTE0ZGZkNzliN2ZhOWQyODYxMzk5YzljZmY4OWFjNjcifQ', b'eyJhdWQiOiJodHRwczovL29hdXRoMi5nb29nbGVhcGlzLmNvbS90b2tlbiIsInNjb3BlIjoiaHR0cHM6Ly93d3cuZ29vZ2xlYXBpcy5jb20vYXV0aC9kcml2ZSIsImlhdCI6MTYxNDIyMjg5NywiZXhwIjoxNjE0MjI2NDk3LCJpc3MiOiJqdXN0LWFjY291bnRAdGVzdGFwaWFuZHNoZWV0cy5pYW0uZ3NlcnZpY2VhY2NvdW50LmNvbSJ9', b'C6AStdyDgEo3AiciyoSHoeELcy6HoevdDCcY2U3bPZqcIF864UBy7tAUwJMMrgDfgKktMvmQE8Q4HioLZmaA6pnWD3NHHUMh8nk_Npas3FKTfkHKiOaygUxPMq6HL6tcJsEVSRvsSW9RzLvy6YD73TYC-8vRek-kn5vxRGOB7Wxb1a9NOpmFpZHgPRRsrR_Fvj7D_R4JtZBYLW7bfSaerdkD2MjnEVTDBxfpZ89TYJwGlm753rHWsf2wpBvDcx68VRkEI0rH1DQ9rk5leWha9uMCPpk2KXFL9uA2MhmkavUcYRYJBAoBsGMindaKdRkq0sO3U6tsrdneuG2S7qTTSw']
INFO:oauth2client.client:Refreshing access_token
DEBUG:googleapiclient.discovery:URL being requested: GET https://www.googleapis.com/drive/v3/files/12xpxsV0IhJT0mPqxdO9dzsMjONwI7EcW?alt=media
WARNING:googleapiclient.discovery_cache:file_cache is unavailable when using oauth2client >= 4.0.0 or google-auth
Traceback (most recent call last):
  File "C:\Users\79069\AppData\Local\Programs\Python\Python39\lib\site-packages\googleapiclient\discovery_cache\file_cache.py", line 33, in <module>
    from oauth2client.contrib.locked_file import LockedFile
ModuleNotFoundError: No module named 'oauth2client.contrib.locked_file'

During handling of the above exception, another exception occurred:

Traceback (most recent call last):
  File "C:\Users\79069\AppData\Local\Programs\Python\Python39\lib\site-packages\googleapiclient\discovery_cache\file_cache.py", line 37, in <module>
    from oauth2client.locked_file import LockedFile
ModuleNotFoundError: No module named 'oauth2client.locked_file'

During handling of the above exception, another exception occurred:

Traceback (most recent call last):
  File "C:\Users\79069\AppData\Local\Programs\Python\Python39\lib\site-packages\googleapiclient\discovery_cache\__init__.py", line 44, in autodetect
    from . import file_cache
  File "C:\Users\79069\AppData\Local\Programs\Python\Python39\lib\site-packages\googleapiclient\discovery_cache\file_cache.py", line 40, in <module>
    raise ImportError(
ImportError: file_cache is unavailable when using oauth2client >= 4.0.0 or google-auth
DEBUG:googleapiclient.discovery:URL being requested: GET https://www.googleapis.com/discovery/v1/apis/drive/v3/rest
INFO:oauth2client.transport:Attempting refresh to obtain initial access_token
DEBUG:oauth2client.crypt:[b'eyJ0eXAiOiJKV1QiLCJhbGciOiJSUzI1NiIsImtpZCI6IjZiYzEzYmFjOTE0ZGZkNzliN2ZhOWQyODYxMzk5YzljZmY4OWFjNjcifQ', b'eyJhdWQiOiJodHRwczovL29hdXRoMi5nb29nbGVhcGlzLmNvbS90b2tlbiIsInNjb3BlIjoiaHR0cHM6Ly93d3cuZ29vZ2xlYXBpcy5jb20vYXV0aC9kcml2ZSIsImlhdCI6MTYxNDIyMjk0OCwiZXhwIjoxNjE0MjI2NTQ4LCJpc3MiOiJqdXN0LWFjY291bnRAdGVzdGFwaWFuZHNoZWV0cy5pYW0uZ3NlcnZpY2VhY2NvdW50LmNvbSJ9', b'vbqWnaqLPmgrLlsKrX_Xd_Bh2-Ez3nS27jsfnMRZWsuqLsOl0djYqREOWdhdkXomVyTEwxjYBaXlSpd3lcnK3B0gkHbvv1TH7Haem5Gf1Ck6fYE3h_jZsh2a5ClE8GPr_d_1KAkwjWtvipsJbhCKP6YQt-u9Rov2sQArcsZiuYVdvZETEJgHxkjUps-8MvFWeV8d-SkUNi1hQC6BWJSysN4xiIA86NZUcCCTj_crSt1RImJG4u7seNpLv91LT8h56ODmaFuPdWxJCau7sWdQkC02mjxre1CDuzP4wAAyW7yODUIJZYB2E80B-dx-69QpH3g_Kx0imkY3sgCFe3Ge8g']
INFO:oauth2client.client:Refreshing access_token
DEBUG:googleapiclient.discovery:URL being requested: GET https://www.googleapis.com/drive/v3/files/12xpxsV0IhJT0mPqxdO9dzsMjONwI7EcW?alt=media
WARNING:googleapiclient.discovery_cache:file_cache is unavailable when using oauth2client >= 4.0.0 or google-auth
Traceback (most recent call last):
  File "C:\Users\79069\AppData\Local\Programs\Python\Python39\lib\site-packages\googleapiclient\discovery_cache\file_cache.py", line 33, in <module>
    from oauth2client.contrib.locked_file import LockedFile
ModuleNotFoundError: No module named 'oauth2client.contrib.locked_file'

During handling of the above exception, another exception occurred:

Traceback (most recent call last):
  File "C:\Users\79069\AppData\Local\Programs\Python\Python39\lib\site-packages\googleapiclient\discovery_cache\file_cache.py", line 37, in <module>
    from oauth2client.locked_file import LockedFile
ModuleNotFoundError: No module named 'oauth2client.locked_file'

During handling of the above exception, another exception occurred:

Traceback (most recent call last):
  File "C:\Users\79069\AppData\Local\Programs\Python\Python39\lib\site-packages\googleapiclient\discovery_cache\__init__.py", line 44, in autodetect
    from . import file_cache
  File "C:\Users\79069\AppData\Local\Programs\Python\Python39\lib\site-packages\googleapiclient\discovery_cache\file_cache.py", line 40, in <module>
    raise ImportError(
ImportError: file_cache is unavailable when using oauth2client >= 4.0.0 or google-auth
DEBUG:googleapiclient.discovery:URL being requested: GET https://www.googleapis.com/discovery/v1/apis/drive/v3/rest
INFO:oauth2client.transport:Attempting refresh to obtain initial access_token
DEBUG:oauth2client.crypt:[b'eyJ0eXAiOiJKV1QiLCJhbGciOiJSUzI1NiIsImtpZCI6IjZiYzEzYmFjOTE0ZGZkNzliN2ZhOWQyODYxMzk5YzljZmY4OWFjNjcifQ', b'eyJhdWQiOiJodHRwczovL29hdXRoMi5nb29nbGVhcGlzLmNvbS90b2tlbiIsInNjb3BlIjoiaHR0cHM6Ly93d3cuZ29vZ2xlYXBpcy5jb20vYXV0aC9kcml2ZSIsImlhdCI6MTYxNDIyMjk1NSwiZXhwIjoxNjE0MjI2NTU1LCJpc3MiOiJqdXN0LWFjY291bnRAdGVzdGFwaWFuZHNoZWV0cy5pYW0uZ3NlcnZpY2VhY2NvdW50LmNvbSJ9', b'Mn_yixu3DsF6FjoY00-Bzqjbsx6S1GXfvVZZP_zEA6-9KutkfnDN2Tmg_-_c5EX-atMQitPQ9iq8Wiv4pnX3Z9wEBw7FS61XGwhd_GZTMcpEK5ONCnkrMogyoDVBnG2RHYRLgSZ__1z8qRXIfUGt15m9A3sqwftHy0jjYL40tO3XLCOVy4t6G1j2Z1-8_tbNVdQ4dt8s4eAnBp-VAf2vCsETwXXl1ygJ5XRk-_68b72whwNdAPadmOSkkO2NKzMVXXPvzUsIDzoNpbvN6nxQMAtqiqDEE67kESr2_slobwZgPGdJKPcsluguYkDt55B8KlWWV7lsWIgO5akQ9gHOzQ']
INFO:oauth2client.client:Refreshing access_token
DEBUG:googleapiclient.discovery:URL being requested: POST https://www.googleapis.com/upload/drive/v3/files?fields=id&alt=json&uploadType=multipart
WARNING:googleapiclient.discovery_cache:file_cache is unavailable when using oauth2client >= 4.0.0 or google-auth
Traceback (most recent call last):
  File "C:\Users\79069\AppData\Local\Programs\Python\Python39\lib\site-packages\googleapiclient\discovery_cache\file_cache.py", line 33, in <module>
    from oauth2client.contrib.locked_file import LockedFile
ModuleNotFoundError: No module named 'oauth2client.contrib.locked_file'

During handling of the above exception, another exception occurred:

Traceback (most recent call last):
  File "C:\Users\79069\AppData\Local\Programs\Python\Python39\lib\site-packages\googleapiclient\discovery_cache\file_cache.py", line 37, in <module>
    from oauth2client.locked_file import LockedFile
ModuleNotFoundError: No module named 'oauth2client.locked_file'

During handling of the above exception, another exception occurred:

Traceback (most recent call last):
  File "C:\Users\79069\AppData\Local\Programs\Python\Python39\lib\site-packages\googleapiclient\discovery_cache\__init__.py", line 44, in autodetect
    from . import file_cache
  File "C:\Users\79069\AppData\Local\Programs\Python\Python39\lib\site-packages\googleapiclient\discovery_cache\file_cache.py", line 40, in <module>
    raise ImportError(
ImportError: file_cache is unavailable when using oauth2client >= 4.0.0 or google-auth
DEBUG:googleapiclient.discovery:URL being requested: GET https://www.googleapis.com/discovery/v1/apis/drive/v3/rest
INFO:oauth2client.transport:Attempting refresh to obtain initial access_token
DEBUG:oauth2client.crypt:[b'eyJ0eXAiOiJKV1QiLCJhbGciOiJSUzI1NiIsImtpZCI6IjZiYzEzYmFjOTE0ZGZkNzliN2ZhOWQyODYxMzk5YzljZmY4OWFjNjcifQ', b'eyJhdWQiOiJodHRwczovL29hdXRoMi5nb29nbGVhcGlzLmNvbS90b2tlbiIsInNjb3BlIjoiaHR0cHM6Ly93d3cuZ29vZ2xlYXBpcy5jb20vYXV0aC9kcml2ZSIsImlhdCI6MTYxNDIzMzEwNywiZXhwIjoxNjE0MjM2NzA3LCJpc3MiOiJqdXN0LWFjY291bnRAdGVzdGFwaWFuZHNoZWV0cy5pYW0uZ3NlcnZpY2VhY2NvdW50LmNvbSJ9', b'EbtFtV64eB6qPJajOuQuHrbihvEHhRTW7udmclrP5WCg1xCNO9J1qsP2hdNg-5YF3b7arkD1dm7wzy4O5y_nSQTAU9ex7pvN-if9qc0HVdcp-XaCw662CARyOPP2_nR43rmPmYfTiTT8a79mtXL7zReImMz08uTF1icrXpg7TBey4GQugoOOqGMzLjjG4ZABalozyxoOQMRWCAkAfRKLhZkZIPlOZOYyAw_okg1s_nOiBJNDzarbFr8D3rnqwClnWdIgDmQd6BD7y0jclh24JFAthPxVFto1X6qAR6lK2bw01lGse8SC87pZBzRuE_nUxaLXpqmWlYFAELHQAsdYyw']
INFO:oauth2client.client:Refreshing access_token
DEBUG:googleapiclient.discovery:URL being requested: GET https://www.googleapis.com/drive/v3/files/12xpxsV0IhJT0mPqxdO9dzsMjONwI7EcW?alt=media
WARNING:googleapiclient.discovery_cache:file_cache is unavailable when using oauth2client >= 4.0.0 or google-auth
Traceback (most recent call last):
  File "C:\Users\79069\AppData\Local\Programs\Python\Python39\lib\site-packages\googleapiclient\discovery_cache\file_cache.py", line 33, in <module>
    from oauth2client.contrib.locked_file import LockedFile
ModuleNotFoundError: No module named 'oauth2client.contrib.locked_file'

During handling of the above exception, another exception occurred:

Traceback (most recent call last):
  File "C:\Users\79069\AppData\Local\Programs\Python\Python39\lib\site-packages\googleapiclient\discovery_cache\file_cache.py", line 37, in <module>
    from oauth2client.locked_file import LockedFile
ModuleNotFoundError: No module named 'oauth2client.locked_file'

During handling of the above exception, another exception occurred:

Traceback (most recent call last):
  File "C:\Users\79069\AppData\Local\Programs\Python\Python39\lib\site-packages\googleapiclient\discovery_cache\__init__.py", line 44, in autodetect
    from . import file_cache
  File "C:\Users\79069\AppData\Local\Programs\Python\Python39\lib\site-packages\googleapiclient\discovery_cache\file_cache.py", line 40, in <module>
    raise ImportError(
ImportError: file_cache is unavailable when using oauth2client >= 4.0.0 or google-auth
DEBUG:googleapiclient.discovery:URL being requested: GET https://www.googleapis.com/discovery/v1/apis/drive/v3/rest
INFO:oauth2client.transport:Attempting refresh to obtain initial access_token
DEBUG:oauth2client.crypt:[b'eyJ0eXAiOiJKV1QiLCJhbGciOiJSUzI1NiIsImtpZCI6IjZiYzEzYmFjOTE0ZGZkNzliN2ZhOWQyODYxMzk5YzljZmY4OWFjNjcifQ', b'eyJhdWQiOiJodHRwczovL29hdXRoMi5nb29nbGVhcGlzLmNvbS90b2tlbiIsInNjb3BlIjoiaHR0cHM6Ly93d3cuZ29vZ2xlYXBpcy5jb20vYXV0aC9kcml2ZSIsImlhdCI6MTYxNDIzMzIxMywiZXhwIjoxNjE0MjM2ODEzLCJpc3MiOiJqdXN0LWFjY291bnRAdGVzdGFwaWFuZHNoZWV0cy5pYW0uZ3NlcnZpY2VhY2NvdW50LmNvbSJ9', b'09Cdp-4cAUcuAUQFXrLJQG3eVMV92G5Tu-fS4BDqRMla63Do3aYl4WCobIuDbW8jl7UURZ_9jiDj-TgywhqG86cRa012Ko9ZRWWHSaEORjCgXrXAAgqdv9pyBiOTnWm5qtnpKoTd5yh3mCEhe0ldLEttZoW78UZz1EPkYPu2HJkGQ1YL7cG-RHMOXa1-uDhj1hLbSDLlbsz2CJXDr7YpfKUUbOiHnGtPY822E0K3C31VR7Aylbr_tmJh3n2WzwQpcy5KtuRRLElLTTGT-5wz9wHlNo7tzzRuAM59N0Ot6kGL_sY2fL9fezzne5r0M33pNFgZYYBFEPvborBaqPYcSg']
INFO:oauth2client.client:Refreshing access_token
DEBUG:googleapiclient.discovery:URL being requested: GET https://www.googleapis.com/drive/v3/files/12xpxsV0IhJT0mPqxdO9dzsMjONwI7EcW?alt=media
WARNING:googleapiclient.discovery_cache:file_cache is unavailable when using oauth2client >= 4.0.0 or google-auth
Traceback (most recent call last):
  File "C:\Users\79069\AppData\Local\Programs\Python\Python39\lib\site-packages\googleapiclient\discovery_cache\file_cache.py", line 33, in <module>
    from oauth2client.contrib.locked_file import LockedFile
ModuleNotFoundError: No module named 'oauth2client.contrib.locked_file'

During handling of the above exception, another exception occurred:

Traceback (most recent call last):
  File "C:\Users\79069\AppData\Local\Programs\Python\Python39\lib\site-packages\googleapiclient\discovery_cache\file_cache.py", line 37, in <module>
    from oauth2client.locked_file import LockedFile
ModuleNotFoundError: No module named 'oauth2client.locked_file'

During handling of the above exception, another exception occurred:

Traceback (most recent call last):
  File "C:\Users\79069\AppData\Local\Programs\Python\Python39\lib\site-packages\googleapiclient\discovery_cache\__init__.py", line 44, in autodetect
    from . import file_cache
  File "C:\Users\79069\AppData\Local\Programs\Python\Python39\lib\site-packages\googleapiclient\discovery_cache\file_cache.py", line 40, in <module>
    raise ImportError(
ImportError: file_cache is unavailable when using oauth2client >= 4.0.0 or google-auth
DEBUG:googleapiclient.discovery:URL being requested: GET https://www.googleapis.com/discovery/v1/apis/drive/v3/rest
INFO:oauth2client.transport:Attempting refresh to obtain initial access_token
DEBUG:oauth2client.crypt:[b'eyJ0eXAiOiJKV1QiLCJhbGciOiJSUzI1NiIsImtpZCI6IjZiYzEzYmFjOTE0ZGZkNzliN2ZhOWQyODYxMzk5YzljZmY4OWFjNjcifQ', b'eyJhdWQiOiJodHRwczovL29hdXRoMi5nb29nbGVhcGlzLmNvbS90b2tlbiIsInNjb3BlIjoiaHR0cHM6Ly93d3cuZ29vZ2xlYXBpcy5jb20vYXV0aC9kcml2ZSIsImlhdCI6MTYxNDIzMzMzMSwiZXhwIjoxNjE0MjM2OTMxLCJpc3MiOiJqdXN0LWFjY291bnRAdGVzdGFwaWFuZHNoZWV0cy5pYW0uZ3NlcnZpY2VhY2NvdW50LmNvbSJ9', b'3aqUBmJJA9BOrZNozutyEaDMSkDNyrIQPi9h-GYh-Ci6AUO5jJ85UYJwrfZm7UOJlpgPRBktYquea8RrCE8X27GlhI-Qs3ma0W7FqGYB7ldMZnf-DYEgLy85Vy-PnqRSinWk4PSPsdrRg3q2b_ZjGcxmUGwZkD7501BoynvsqbgafpNXaOTQ6LCPuDVTx_j9Ci0cKeYcyGYcWhPv1ZkOvPRHUkJyhBR_fkV7UnUJwT4j8hqbIdmpH06K8O209A6CBxWS8js0Ltwu2EhmJBA-1NhNfSpXOHhQ84nOTn8TNZvM9R6tt_G643tt92TVyNs-hU9PxF3BctxCSW6oFdGiXQ']
INFO:oauth2client.client:Refreshing access_token
DEBUG:googleapiclient.discovery:URL being requested: GET https://www.googleapis.com/drive/v3/files/12xpxsV0IhJT0mPqxdO9dzsMjONwI7EcW?alt=media
ERROR:root:name 'logging' is not defined
ERROR:root:name 'logging' is not defined
ERROR:root:name 'logging' is not defined
ERROR:root:name 'logging' is not defined
ERROR:root:name 'logging' is not defined
INFO:root:Connection to PostgreSQL DB successful
INFO:root:Query executed successfully
INFO:root:Connection to PostgreSQL DB successful
INFO:root:Query executed successfully
INFO:root:Query executed successfully
INFO:root:You are logged in!
INFO:root:Connection to PostgreSQL DB successful
INFO:root:Query executed successfully
INFO:root:Connection to PostgreSQL DB successful
INFO:root:Query executed successfully
INFO:root:Connection to PostgreSQL DB successful
INFO:root:Query executed successfully
INFO:root:Connection to PostgreSQL DB successful
INFO:root:Query executed successfully
INFO:root:Connection to PostgreSQL DB successful
INFO:root:Query executed successfully
INFO:root:Connection to PostgreSQL DB successful
INFO:root:Query executed successfully
INFO:root:Connection to PostgreSQL DB successful
INFO:root:Query executed successfully
INFO:root:Connection to PostgreSQL DB successful
INFO:root:Query executed successfully
INFO:root:Connection to PostgreSQL DB successful
INFO:root:Connection to PostgreSQL DB successful
INFO:root:Query executed successfully
INFO:root:Connection to PostgreSQL DB successful
INFO:root:Query executed successfully
INFO:root:Connection to PostgreSQL DB successful
INFO:root:Connection to PostgreSQL DB successful
INFO:root:Query executed successfully
INFO:root:Connection to PostgreSQL DB successful
INFO:root:Query executed successfully
